Workbook

Sheet Scoring Matrix
A1: Category | B1: Metric | C1: Weight (%) | D1: 0 | E1: 1 | F1: 2 | G1: 3 (Contributor) | H1: 4 (High) | I1: 5 (STAR)
A2: Sales | B2: Sales vs Budget (%) | C2: 5 | D2: <90% | E2: 90-94.9% | F2: 95–98.9% | G2: 99–101.9% | H2: 102–104.9% | I2: >105% | J2: 5.9 | K2: 6
A3: Sales | B3: Sales vs Prior Year (%) | C3: 5 | D3: <-5% | E3: -5-0% | F3: 0.1-4.9% | G3: 5-7.4% | H3: 7.5-14.9% | I3: ≥15% | J3: 5.9 | K3: 6
A4: EBITDA | B4: EBITDA vs Budget (%) | C4: 15 | D4: <75% | E4: 75-84.9% | F4: 85–94.9% | G4: 95–100.9% | H4: 101–104.9% | I4: ≥105%
A5: Prime Cost | B5: Labor vs Budget Variance (pts) | C5: 12.5 | D5: ≥+3.0 | E5: +2.0–2.99 | F5: +1.0–1.99 | G5: 0.0–0.99 | H5: -0.5– -0.99 | I5: ≤-1.0 | J5: 14.7 | K5: 14.5 | L5: /** * Automatically triggers whenever a cell is edited in the spreadsheet. */ function onEdit(e) { // If the edit is not valid, stop here if (!e) return; // Only run if the edit happened on the Scorecards sheet const activeSheetName = e.source.getActiveSheet().getName(); if (activeSheetName === "Weekly Store Scorecards ") { syncCrossSheetColors(); } } function syncCrossSheetColors() { const ss = SpreadsheetApp.getActiveSpreadsheet(); const sourceSheet = ss.getSheetByName("Weekly Store Scorecards "); const targetSheet = ss.getSheetByName("Weekly Area Leader Dashboard"); if (!sourceSheet || !targetSheet) return; // 1. Force Google to finish the formula calculation SpreadsheetApp.flush(); // 2. Add a tiny delay (200ms) to let the Color Scale "paint" itself Utilities.sleep(200); const startRowSource = 3; const startRowTarget = 2; const numRows = 6; const mapping = [ [3, 4], [6, 5], [12, 6], [15, 7], [18, 8], [21, 10], [24, 11], [27, 9]]; mapping.forEach(pair => { try { const sourceCol = pair[0]; const targetCol = pair[1]; // Grab the NEW colors from Column C (Source) const colors = sourceSheet.getRange(startRowSource, sourceCol, numRows).getBackgrounds(); // Update the "Input" column on the same scorecard sheet (SourceCol - 1) sourceSheet.getRange(startRowSource, sourceCol - 1, numRows).setBackgrounds(colors); // Syncing the Dashboard targetSheet.getRange(startRowTarget, targetCol, numRows).setBackgrounds(colors); } catch (err) { Logger.log("Error: " + err.message); } }); }
A6: Prime Cost | B6: COGS vs Budget Variance (pts) | C6: 12.5 | D6: ≥+3.0 | E6: +2.0–2.99 | F6: +1.0–1.99 | G6: 0.0–0.99 | H6: -0.5–-0.99 | I6: ≤-1.0 | J6: 14.7 | K6: 14.5
A7: Operational | B7: Google Rating | C7: 17.5 | D7: <3.8 | E7: <4.0 | F7: 4.0–4.29 | G7: 4.3–4.49 | H7: 4.5–4.69 | I7: ≥4.7 | J7: 20.6 | K7: 20.5
A8: Operational | B8: Yelp Rating | C8: 7.5 | D8: <3.8 | E8: <4.0 | F8: 4.0–4.29 | G8: 4.3–4.49 | H8: 4.5–4.69 | I8: ≥4.7 | J8: 8.8 | K8: 8.5
A9: Operational | B9: 3P Error Rate (%) | C9: 10 | D9: >6% | E9: 4.01–6% | F9: 2.01–4% | G9: 1.51–2% | H9: 1.01–1.5% | I9: ≤1% | J9: 11.8 | K9: 12
A10: Operational | B10: Avoidable Wait (mins) | C10: 7.5 | D10: >8 | E10: >5–8 | F10: >2–5 | G10: ≤2 & >1.5 | H10: ≤1.5 & >1 | I10: ≤1 | J10: 8.8 | K10: 9
A11: Operational | B11: 3P Rating | C11: 7.5 | D11: <3.8 | E11: <4.0 | F11: 4.0–4.29 | G11: 4.3–4.49 | H11: 4.5–4.69 | I11: ≥4.7 | J11: 8.8 | K11: 9
A12: Operational | B12: Full Audit Score | C12: 12.5 | D12: <70 | E12: 70–74 | F12: 75–82 | G12: 83–88 | H12: 89–93 | I12: ≥94
A13: Operational | B13: Culinary Audit Score | C13: 6.25 | D13: <70 | E13: 70–74 | F13: 75–82 | G13: 83–88 | H13: 89–93 | I13: ≥94
A14: Eligibility | B14: Training Completion % (Gate) | C14: 0 | E14: <87% | G14: ≥87%
A18: RASA · Store Scoring Matrix - Weekly | K18: Performance Rating Key
A19: Category | B19: Metric | C19: Weight (%) | D19: 0 | E19: 1 | F19: 2 | G19: 3 (Contributor) | H19: 4 (High) | I19: 5 (STAR) | K19: Performance | L19: Score | M19: Colour
A20: Sales | B20: Sales vs Budget (%) | C20: 0.06 | D20: <90% | E20: 90–94.9% | F20: 95–98.9% | G20: 99–101.9% | H20: 102–104.9% | I20: ≥105% | K20: STAR | L20: 4.7 - 5.0
B21: Interpolated score range | D21: — | E21: 1.0 – 1.9 | F21: 2.0 – 2.9 | G21: 3.0 – 3.9 | H21: 4.0 – 4.9 | I21: 5 | K21: HIGH | L21: 3.7 - 4.7
B22: Sales vs Prior Year (%) | C22: 0.06 | D22: <−5% | E22: −5% to 0% | F22: 0.1–4.9% | G22: 5–7.4% | H22: 7.5–14.9% | I22: ≥15% | K22: CONTRIBUTOR | L22: 2.7 - 3.7
B23: Interpolated score range | D23: — | E23: 1.0 – 1.9 | F23: 2.0 – 2.9 | G23: 3.0 – 3.9 | H23: 4.0 – 4.9 | I23: 5 | K23: LOW | L23: 1.7 - 2.7
A24: Prime Cost | B24: Labor vs Budget Variance (pts) | C24: 0.145 | D24: ≥+3.0 | E24: 2.0 to 2.99 | F24: 1.0 to +1.99 | G24: 0.01 to 0.99 | H24: 0.0 to -0.99 | I24: ≤−1.0 | K24: NON | L24: 0.0 - 1.7
B25: Interpolated score range | D25: — | E25: 1.0 – 1.9 | F25: 2.0 – 2.9 | G25: 3.0 – 3.9 | H25: 4.0 – 4.9 | I25: 5
B26: COGS vs Budget Variance (pts) | C26: 0.145 | D26: ≥+3.0 | E26: 2.0 to +2.99 | F26: 1.0 to +1.99 | G26: 0.01 to 0.99 | H26: 0.0 to -0.99 | I26: ≤−1.0
B27: Interpolated score range | D27: — | E27: 1.0 – 1.9 | F27: 2.0 – 2.9 | G27: 3.0 – 3.9 | H27: 4.0 – 4.9 | I27: 5
A28: Operational | B28: Google Rating | C28: 0.29 | D28: <3.8 | E28: 3.8–3.99 | F28: 4.0–4.29 | G28: 4.3–4.49 | H28: 4.5–4.69 | I28: ≥4.7
B29: Interpolated score range | D29: — | E29: 1.0 – 1.9 | F29: 2.0 – 2.9 | G29: 3.0 – 3.9 | H29: 4.0 – 4.9 | I29: 5
B30: 3P Error Rate (%) | C30: 0.12 | D30: >6% | E30: 4.01–6% | F30: 2.01–4% | G30: 1.51–2% | H30: 1.01–1.5% | I30: ≤1%
B31: Interpolated score range | D31: — | E31: 1.0 – 1.9 | F31: 2.0 – 2.9 | G31: 3.0 – 3.9 | H31: 4.0 – 4.9 | I31: 5
B32: Avoidable Wait (mins) | C32: 0.09 | D32: >8 | E32: >5 to 8 | F32: >2 to 5 | G32: >1.5 to 2 | H32: >1 to 1.5 | I32: ≤1
B33: Interpolated score range | D33: — | E33: 1.0 – 1.9 | F33: 2.0 – 2.9 | G33: 3.0 – 3.9 | H33: 4.0 – 4.9 | I33: 5
B34: 3P Rating | C34: 0.09 | D34: <3.8 | E34: 3.8–3.99 | F34: 4.0–4.29 | G34: 4.3–4.49 | H34: 4.5–4.69 | I34: ≥4.7
B35: Interpolated score range | D35: — | E35: 1.0 – 1.9 | F35: 2.0 – 2.9 | G35: 3.0 – 3.9 | H35: 4.0 – 4.9 | I35: 5
A36: Total Weight (scored metrics only) | C36: =SUM(C20:C34) -> 1
A40: RASA · Period Scoring Matrix
A41: Category | B41: Metric | C41: Weight (%) | D41: 0 | E41: 1 | F41: 2 | G41: 3 (Contributor) | H41: 4 (High) | I41: 5 (STAR)
A42: Sales | B42: Sales vs Budget (%) | C42: 0.04 | D42: <90% | E42: 90–94.9% | F42: 95–98.9% | G42: 99–101.9% | H42: 102–104.9% | I42: ≥105%
B43: Interpolated score range | D43: — | E43: 1.0 – 1.9 | F43: 2.0 – 2.9 | G43: 3.0 – 3.9 | H43: 4.0 – 4.9 | I43: 5
B44: Sales vs Prior Year (%) | C44: 0.04 | D44: <−5% | E44: −5% to 0% | F44: 0.1–4.9% | G44: 5–7.4% | H44: 7.5–14.9% | I44: ≥15%
B45: Interpolated score range | D45: — | E45: 1.0 – 1.9 | F45: 2.0 – 2.9 | G45: 3.0 – 3.9 | H45: 4.0 – 4.9 | I45: 5
A46: EBITDA | B46: EBITDA vs Budget (%) | C46: 0.125 | D46: <75% | E46: 75–84% | F46: 85–94% | G46: 95–100% | H46: 101–105% | I46: >105%
...

Sheet WEEKLY>>>

Sheet Weekly Store Scorecards 
A1: Location | B1: Sales vs Budget (%) | E1: Sales vs Prior Year (%) | K1: Labor vs Budget Variance (pts) | N1: COGS vs Budget Variance (pts) | Q1: In-Store Rating | T1: 3P Error Rate (%) | W1: Avoidable Wait (mins) | Z1: 3P Rating | AC1: Composite Score (0–5)
B2: Input | C2: Score | D2: Weighted | E2: Input | F2: Score | G2: Weighted | K2: Input | L2: Score | M2: Weighted | N2: Input | O2: Score | P2: Weighted | Q2: Input | R2: Score | S2: Weighted | T2: Input | U2: Score | V2: Weighted | W2: Input | X2: Score | Y2: Weighted | Z2: Input | AA2: Score | AB2: Weighted
A3: Mosaic | B3: =100%+'Weekly Tables'!I3 -> 0.94670671 | C3: =IFERROR(ROUND(ifs(B3="","",B3>=1.05,5,B3>=1.02,4+(B3-1.02)/0.03,B3>=0.99,3+(B3-0.99)/0.03,B3>=0.95,2+(B3-0.95)/0.04,B3>=0.9,1+(B3-0.9)/0.05,TRUE(),0),1),"") -> 1.9 | D3: =IF(C3="","",C3*C$8) -> 0.114 | E3: =100%+'Weekly Tables'!F3 -> 1.0965152 | F3: =IFERROR(ROUND(ifs(E3="","",E3>=1.15,5,E3>=1.075,4+(E3-1.075)/0.075,E3>=1.05,3+(E3-1.05)/0.025,E3>=1,2+(E3-1)/0.05,E3>=0.95,1+(E3-0.95)/0.05,TRUE(),0),1),"") -> 4.3 | G3: =IF(F3="","",F3*F$8) -> 0.258 | K3: ='Weekly Tables'!L3*100 -> -2.7 | L3: =IFERROR(ROUND(IFS(K3="","",K3>=3,0,K3>=2,1+(3-K3)/1,K3>=1,2+(2-K3)/1,K3>0,3+(1-K3)/1,K3>=-1,4+(0-K3)/1,TRUE,5),1),"") -> 5 | M3: =IF(L3="","",L3*L$8) -> 0.725 | N3: ='Weekly Tables'!O3*100 -> -3.4 | O3: =IFERROR(ROUND(IFS(N3="","",N3>=3,0,N3>=2,1+(3-N3)/1,N3>=1,2+(2-N3)/1,N3>0,3+(1-N3)/1,N3>=-1,4+(0-N3)/1,TRUE,5),1),"") -> 5 | P3: =IF(O3="","",O3*O$8) -> 0.725 | Q3: ='Weekly Tables'!E14 -> 3.33 | R3: =IFERROR(ROUND(ifs(Q3="","",Value(Q3)="NA","" ,Q3>=4.7,5,Q3>=4.5,4+(Q3-4.5)/0.2,Q3>=4.3,3+(Q3-4.3)/0.2,Q3>=4,2+(Q3-4)/0.3,Q3>=3.8,1+(Q3-3.8)/0.2,TRUE(),0),1),"") -> 0 | S3: =IF(R3="","",R3*R$8) -> 0 | T3: ='Weekly Tables'!N21 -> 0.0372 | U3: =IFERROR(ROUND(ifs(T3="","",T3<=0.01,5,T3<=0.015,4+(0.015-T3)/0.005,T3<=0.02,3+(0.02-T3)/0.005,T3<=0.04,2+(0.04-T3)/0.02,T3<=0.06,1+(0.06-T3)/0.02,TRUE(),0),1),"") -> 2.1 | V3: =IF(U3="","",U3*U$8) -> 0.252 | W3: {=XLOOKUP(A3,'Weekly Tables'!$B$30:$B$34,'Weekly Tables'!$H$30:$H$34)} -> 1.6 | X3: =IFERROR(ROUND(ifs(W3="","",W3<=1,5,W3<=1.5,4+(1.5-W3)/0.5,W3<=2,3+(2-W3)/0.5,W3<=5,2+(5-W3)/3,W3<=8,1+(8-W3)/3,TRUE(),0),1),"") -> 3.8 | Y3: =IF(X3="","",X3*X$8) -> 0.342 | Z3: ='Weekly Tables'!E21 -> 4.3 | AA3: =IFERROR(ROUND(ifs(Z3="","",Z3>=4.7,5,Z3>=4.5,4+(Z3-4.5)/0.2,Z3>=4.3,3+(Z3-4.3)/0.2,Z3>=4,2+(Z3-4)/0.3,Z3>=3.8,1+(Z3-3.8)/0.2,TRUE(),0),1),"") -> 3 | AB3: =IF(AA3="","",AA3*AA$8) -> 0.27 | AC3: =SUM(D3,G3,J3,M3,P3,S3,V3,Y3,AB3) -> 2.686
A4: MVT | B4: =100%+'Weekly Tables'!I4 -> 1.0190662 | C4: =IFERROR(ROUND(ifs(B4="","",B4>=1.05,5,B4>=1.02,4+(B4-1.02)/0.03,B4>=0.99,3+(B4-0.99)/0.03,B4>=0.95,2+(B4-0.95)/0.04,B4>=0.9,1+(B4-0.9)/0.05,TRUE(),0),1),"") -> 4 | D4: =IF(C4="","",C4*C$8) -> 0.24 | E4: =100%+'Weekly Tables'!F4 -> 1.3761061 | F4: =IFERROR(ROUND(ifs(E4="","",E4>=1.15,5,E4>=1.075,4+(E4-1.075)/0.075,E4>=1.05,3+(E4-1.05)/0.025,E4>=1,2+(E4-1)/0.05,E4>=0.95,1+(E4-0.95)/0.05,TRUE(),0),1),"") -> 5 | G4: =IF(F4="","",F4*F$8) -> 0.3 | K4: ='Weekly Tables'!L4*100 -> 2.4 | L4: =IFERROR(ROUND(IFS(K4="","",K4>=3,0,K4>=2,1+(3-K4)/1,K4>=1,2+(2-K4)/1,K4>0,3+(1-K4)/1,K4>=-1,4+(0-K4)/1,TRUE,5),1),"") -> 1.6 | M4: =IF(L4="","",L4*L$8) -> 0.232 | N4: ='Weekly Tables'!O4*100 -> 1.1 | O4: =IFERROR(ROUND(IFS(N4="","",N4>=3,0,N4>=2,1+(3-N4)/1,N4>=1,2+(2-N4)/1,N4>0,3+(1-N4)/1,N4>=-1,4+(0-N4)/1,TRUE,5),1),"") -> 2.9 | P4: =IF(O4="","",O4*O$8) -> 0.4205 | Q4: ='Weekly Tables'!E12 -> NA | R4: =IFERROR(ROUND(ifs(Q4="","",Value(Q4)="NA","" ,Q4>=4.7,5,Q4>=4.5,4+(Q4-4.5)/0.2,Q4>=4.3,3+(Q4-4.3)/0.2,Q4>=4,2+(Q4-4)/0.3,Q4>=3.8,1+(Q4-3.8)/0.2,TRUE(),0),1),"") | S4: =IF(R4="","",R4*R$8) | T4: ='Weekly Tables'!N19 -> 0.0209 | U4: =IFERROR(ROUND(ifs(T4="","",T4<=0.01,5,T4<=0.015,4+(0.015-T4)/0.005,T4<=0.02,3+(0.02-T4)/0.005,T4<=0.04,2+(0.04-T4)/0.02,T4<=0.06,1+(0.06-T4)/0.02,TRUE(),0),1),"") -> 3 | V4: =IF(U4="","",U4*U$8) -> 0.36 | W4: {=XLOOKUP(A4,'Weekly Tables'!$B$30:$B$34,'Weekly Tables'!$H$30:$H$34)} -> 1.02 | X4: =IFERROR(ROUND(ifs(W4="","",W4<=1,5,W4<=1.5,4+(1.5-W4)/0.5,W4<=2,3+(2-W4)/0.5,W4<=5,2+(5-W4)/3,W4<=8,1+(8-W4)/3,TRUE(),0),1),"") -> 5 | Y4: =IF(X4="","",X4*X$8) -> 0.45 | Z4: ='Weekly Tables'!E19 -> 4.5 | AA4: =IFERROR(ROUND(ifs(Z4="","",Z4>=4.7,5,Z4>=4.5,4+(Z4-4.5)/0.2,Z4>=4.3,3+(Z4-4.3)/0.2,Z4>=4,2+(Z4-4)/0.3,Z4>=3.8,1+(Z4-3.8)/0.2,TRUE(),0),1),"") -> 4 | AB4: =IF(AA4="","",AA4*AA$8) -> 0.36 | AC4: =SUM(D4,G4,J4,M4,P4,S4,V4,Y4,AB4) -> 2.3625
A5: National Landing | B5: =100%+'Weekly Tables'!I5 -> 1.2172449 | C5: =IFERROR(ROUND(ifs(B5="","",B5>=1.05,5,B5>=1.02,4+(B5-1.02)/0.03,B5>=0.99,3+(B5-0.99)/0.03,B5>=0.95,2+(B5-0.95)/0.04,B5>=0.9,1+(B5-0.9)/0.05,TRUE(),0),1),"") -> 5 | D5: =IF(C5="","",C5*C$8) -> 0.3 | E5: =100%+'Weekly Tables'!F5 -> 1.4285788 | F5: =IFERROR(ROUND(ifs(E5="","",E5>=1.15,5,E5>=1.075,4+(E5-1.075)/0.075,E5>=1.05,3+(E5-1.05)/0.025,E5>=1,2+(E5-1)/0.05,E5>=0.95,1+(E5-0.95)/0.05,TRUE(),0),1),"") -> 5 | G5: =IF(F5="","",F5*F$8) -> 0.3 | K5: ='Weekly Tables'!L5*100 -> -4.1 | L5: =IFERROR(ROUND(IFS(K5="","",K5>=3,0,K5>=2,1+(3-K5)/1,K5>=1,2+(2-K5)/1,K5>0,3+(1-K5)/1,K5>=-1,4+(0-K5)/1,TRUE,5),1),"") -> 5 | M5: =IF(L5="","",L5*L$8) -> 0.725 | N5: ='Weekly Tables'!O5*100 -> 0.2 | O5: =IFERROR(ROUND(IFS(N5="","",N5>=3,0,N5>=2,1+(3-N5)/1,N5>=1,2+(2-N5)/1,N5>0,3+(1-N5)/1,N5>=-1,4+(0-N5)/1,TRUE,5),1),"") -> 3.8 | P5: =IF(O5="","",O5*O$8) -> 0.551 | Q5: ='Weekly Tables'!E13 -> 4 | R5: =IFERROR(ROUND(ifs(Q5="","",Value(Q5)="NA","" ,Q5>=4.7,5,Q5>=4.5,4+(Q5-4.5)/0.2,Q5>=4.3,3+(Q5-4.3)/0.2,Q5>=4,2+(Q5-4)/0.3,Q5>=3.8,1+(Q5-3.8)/0.2,TRUE(),0),1),"") -> 2 | S5: =IF(R5="","",R5*R$8) -> 0.58 | T5: ='Weekly Tables'!N20 -> 0.0408 | U5: =IFERROR(ROUND(ifs(T5="","",T5<=0.01,5,T5<=0.015,4+(0.015-T5)/0.005,T5<=0.02,3+(0.02-T5)/0.005,T5<=0.04,2+(0.04-T5)/0.02,T5<=0.06,1+(0.06-T5)/0.02,TRUE(),0),1),"") -> 2 | V5: =IF(U5="","",U5*U$8) -> 0.24 | W5: {=XLOOKUP(A5,'Weekly Tables'!$B$30:$B$34,'Weekly Tables'!$H$30:$H$34)} -> 1.05 | X5: =IFERROR(ROUND(ifs(W5="","",W5<=1,5,W5<=1.5,4+(1.5-W5)/0.5,W5<=2,3+(2-W5)/0.5,W5<=5,2+(5-W5)/3,W5<=8,1+(8-W5)/3,TRUE(),0),1),"") -> 4.9 | Y5: =IF(X5="","",X5*X$8) -> 0.441 | Z5: ='Weekly Tables'!E20 -> 4.5 | AA5: =IFERROR(ROUND(ifs(Z5="","",Z5>=4.7,5,Z5>=4.5,4+(Z5-4.5)/0.2,Z5>=4.3,3+(Z5-4.3)/0.2,Z5>=4,2+(Z5-4)/0.3,Z5>=3.8,1+(Z5-3.8)/0.2,TRUE(),0),1),"") -> 4 | AB5: =IF(AA5="","",AA5*AA$8) -> 0.36 | AC5: =SUM(D5,G5,J5,M5,P5,S5,V5,Y5,AB5) -> 3.497
A6: Rockville | B6: =100%+'Weekly Tables'!I6 -> 0.87077313 | C6: =IFERROR(ROUND(ifs(B6="","",B6>=1.05,5,B6>=1.02,4+(B6-1.02)/0.03,B6>=0.99,3+(B6-0.99)/0.03,B6>=0.95,2+(B6-0.95)/0.04,B6>=0.9,1+(B6-0.9)/0.05,TRUE(),0),1),"") -> 0 | D6: =IF(C6="","",C6*C$8) -> 0 | E6: =100%+'Weekly Tables'!F6 -> 1.0890977 | F6: =IFERROR(ROUND(ifs(E6="","",E6>=1.15,5,E6>=1.075,4+(E6-1.075)/0.075,E6>=1.05,3+(E6-1.05)/0.025,E6>=1,2+(E6-1)/0.05,E6>=0.95,1+(E6-0.95)/0.05,TRUE(),0),1),"") -> 4.2 | G6: =IF(F6="","",F6*F$8) -> 0.252 | K6: ='Weekly Tables'!L6*100 -> -0.7 | L6: =IFERROR(ROUND(IFS(K6="","",K6>=3,0,K6>=2,1+(3-K6)/1,K6>=1,2+(2-K6)/1,K6>0,3+(1-K6)/1,K6>=-1,4+(0-K6)/1,TRUE,5),1),"") -> 4.7 | M6: =IF(L6="","",L6*L$8) -> 0.6815 | N6: ='Weekly Tables'!O6*100 -> 3.3 | O6: =IFERROR(ROUND(IFS(N6="","",N6>=3,0,N6>=2,1+(3-N6)/1,N6>=1,2+(2-N6)/1,N6>0,3+(1-N6)/1,N6>=-1,4+(0-N6)/1,TRUE,5),1),"") -> 0 | P6: =IF(O6="","",O6*O$8) -> 0 | Q6: ='Weekly Tables'!E15 -> 4.25 | R6: =IFERROR(ROUND(ifs(Q6="","",Value(Q6)="NA","" ,Q6>=4.7,5,Q6>=4.5,4+(Q6-4.5)/0.2,Q6>=4.3,3+(Q6-4.3)/0.2,Q6>=4,2+(Q6-4)/0.3,Q6>=3.8,1+(Q6-3.8)/0.2,TRUE(),0),1),"") -> 2.8 | S6: =IF(R6="","",R6*R$8) -> 0.812 | T6: ='Weekly Tables'!N22 -> 0.0294 | U6: =IFERROR(ROUND(ifs(T6="","",T6<=0.01,5,T6<=0.015,4+(0.015-T6)/0.005,T6<=0.02,3+(0.02-T6)/0.005,T6<=0.04,2+(0.04-T6)/0.02,T6<=0.06,1+(0.06-T6)/0.02,TRUE(),0),1),"") -> 2.5 | V6: =IF(U6="","",U6*U$8) -> 0.3 | W6: {=XLOOKUP(A6,'Weekly Tables'!$B$30:$B$34,'Weekly Tables'!$H$30:$H$34)} -> 1.43 | X6: =IFERROR(ROUND(ifs(W6="","",W6<=1,5,W6<=1.5,4+(1.5-W6)/0.5,W6<=2,3+(2-W6)/0.5,W6<=5,2+(5-W6)/3,W6<=8,1+(8-W6)/3,TRUE(),0),1),"") -> 4.1 | Y6: =IF(X6="","",X6*X$8) -> 0.369 | Z6: ='Weekly Tables'!E22 -> 4.2 | AA6: =IFERROR(ROUND(ifs(Z6="","",Z6>=4.7,5,Z6>=4.5,4+(Z6-4.5)/0.2,Z6>=4.3,3+(Z6-4.3)/0.2,Z6>=4,2+(Z6-4)/0.3,Z6>=3.8,1+(Z6-3.8)/0.2,TRUE(),0),1),"") -> 2.7 | AB6: =IF(AA6="","",AA6*AA$8) -> 0.243 | AC6: =SUM(D6,G6,J6,M6,P6,S6,V6,Y6,AB6) -> 2.6575
A7: All Stores | B7: =100%+'Weekly Tables'!I7 -> 0.85242532 | C7: =IFERROR(ROUND(ifs(B7="","",B7>=1.05,5,B7>=1.02,4+(B7-1.02)/0.03,B7>=0.99,3+(B7-0.99)/0.03,B7>=0.95,2+(B7-0.95)/0.04,B7>=0.9,1+(B7-0.9)/0.05,TRUE(),0),1),"") -> 0 | D7: =IF(C7="","",C7*C$8) -> 0 | E7: =100%+'Weekly Tables'!F7 -> 1.0642439 | F7: =IFERROR(ROUND(ifs(E7="","",E7>=1.15,5,E7>=1.075,4+(E7-1.075)/0.075,E7>=1.05,3+(E7-1.05)/0.025,E7>=1,2+(E7-1)/0.05,E7>=0.95,1+(E7-0.95)/0.05,TRUE(),0),1),"") -> 3.6 | G7: =IF(F7="","",F7*F$8) -> 0.216 | K7: ='Weekly Tables'!L7*100 -> -1.9 | L7: =IFERROR(ROUND(IFS(K7="","",K7>=3,0,K7>=2,1+(3-K7)/1,K7>=1,2+(2-K7)/1,K7>0,3+(1-K7)/1,K7>=-1,4+(0-K7)/1,TRUE,5),1),"") -> 5 | M7: =IF(L7="","",L7*L$8) -> 0.725 | N7: ='Weekly Tables'!O7*100 -> -0.1 | O7: =IFERROR(ROUND(IFS(N7="","",N7>=3,0,N7>=2,1+(3-N7)/1,N7>=1,2+(2-N7)/1,N7>0,3+(1-N7)/1,N7>=-1,4+(0-N7)/1,TRUE,5),1),"") -> 4.1 | P7: =IF(O7="","",O7*O$8) -> 0.5945 | Q7: ='Weekly Tables'!E16 -> 3.88 | R7: =IFERROR(ROUND(ifs(Q7="","",Value(Q7)="NA","" ,Q7>=4.7,5,Q7>=4.5,4+(Q7-4.5)/0.2,Q7>=4.3,3+(Q7-4.3)/0.2,Q7>=4,2+(Q7-4)/0.3,Q7>=3.8,1+(Q7-3.8)/0.2,TRUE(),0),1),"") -> 1.4 | S7: =IF(R7="","",R7*R$8) -> 0.406 | T7: ='Weekly Tables'!N23 -> 0.032075 | U7: =IFERROR(ROUND(ifs(T7="","",T7<=0.01,5,T7<=0.015,4+(0.015-T7)/0.005,T7<=0.02,3+(0.02-T7)/0.005,T7<=0.04,2+(0.04-T7)/0.02,T7<=0.06,1+(0.06-T7)/0.02,TRUE(),0),1),"") -> 2.4 | V7: =IF(U7="","",U7*U$8) -> 0.288 | W7: {=XLOOKUP(A7,'Weekly Tables'!$B$30:$B$35,'Weekly Tables'!$H$30:$H$35)} -> 1.2 | X7: =IFERROR(ROUND(ifs(W7="","",W7<=1,5,W7<=1.5,4+(1.5-W7)/0.5,W7<=2,3+(2-W7)/0.5,W7<=5,2+(5-W7)/3,W7<=8,1+(8-W7)/3,TRUE(),0),1),"") -> 4.6 | Y7: =IF(X7="","",X7*X$8) -> 0.414 | Z7: ='Weekly Tables'!E23 -> 4.375 | AA7: =IFERROR(ROUND(ifs(Z7="","",Z7>=4.7,5,Z7>=4.5,4+(Z7-4.5)/0.2,Z7>=4.3,3+(Z7-4.3)/0.2,Z7>=4,2+(Z7-4)/0.3,Z7>=3.8,1+(Z7-3.8)/0.2,TRUE(),0),1),"") -> 3.4 | AB7: =IF(AA7="","",AA7*AA$8) -> 0.306 | AC7: =SUM(D7,G7,J7,M7,P7,S7,V7,Y7,AB7) -> 2.9495
A8: Weight | C8: ='Scoring Matrix'!C20 -> 0.06 | F8: ='Scoring Matrix'!C22 -> 0.06 | L8: ='Scoring Matrix'!C24 -> 0.145 | O8: ='Scoring Matrix'!C26 -> 0.145 | R8: ='Scoring Matrix'!C28 -> 0.29 | U8: ='Scoring Matrix'!C30 -> 0.12 | X8: ='Scoring Matrix'!C32 -> 0.09 | AA8: ='Scoring Matrix'!C34 -> 0.09

Sheet Weekly Area Leader Dashboard
A1: Restaurant | B1: Composite Score | C1: Contributor Band | D1: Sales vs Budget (%) | E1: Sales vs Prior Year (%) | F1: Labor vs Budget Variance (pts) | G1: COGS vs Budget Variance (pts) | H1: In-Store Rating | I1: 3P Rating | J1: 3P Error % | K1: Avoidable Wait (mins)
A2: Mosaic | B2: ='Weekly Store Scorecards '!AC3 -> 2.686 | C2: =IFS(B2<1.7,"Non", B2<2.7,"Low", B2<3.7,"Contributor", B2<4.7,"High", TRUE,"STAR") -> Low | D2: ='Weekly Store Scorecards '!B3 -> 0.94670671 | E2: ='Weekly Store Scorecards '!E3 -> 1.0965152 | F2: ='Weekly Store Scorecards '!K3 -> -2.7 | G2: ='Weekly Store Scorecards '!N3 -> -3.4 | H2: ='Weekly Store Scorecards '!Q3 -> 3.33 | I2: ='Weekly Store Scorecards '!Z3 -> 4.3 | J2: ='Weekly Store Scorecards '!T3 -> 0.0372 | K2: ='Weekly Store Scorecards '!W3 -> 1.6
A3: MVT | B3: ='Weekly Store Scorecards '!AC4 -> 2.3625 | C3: =IFS(B3<1.7,"Non", B3<2.7,"Low", B3<3.7,"Contributor", B3<4.7,"High", TRUE,"STAR") -> Low | D3: ='Weekly Store Scorecards '!B4 -> 1.0190662 | E3: ='Weekly Store Scorecards '!E4 -> 1.3761061 | F3: ='Weekly Store Scorecards '!K4 -> 2.4 | G3: ='Weekly Store Scorecards '!N4 -> 1.1 | H3: ='Weekly Store Scorecards '!Q4 -> NA | I3: ='Weekly Store Scorecards '!Z4 -> 4.5 | J3: ='Weekly Store Scorecards '!T4 -> 0.0209 | K3: ='Weekly Store Scorecards '!W4 -> 1.02
A4: National Landing | B4: ='Weekly Store Scorecards '!AC5 -> 3.497 | C4: =IFS(B4<1.7,"Non", B4<2.7,"Low", B4<3.7,"Contributor", B4<4.7,"High", TRUE,"STAR") -> Contributor | D4: ='Weekly Store Scorecards '!B5 -> 1.2172449 | E4: ='Weekly Store Scorecards '!E5 -> 1.4285788 | F4: ='Weekly Store Scorecards '!K5 -> -4.1 | G4: ='Weekly Store Scorecards '!N5 -> 0.2 | H4: ='Weekly Store Scorecards '!Q5 -> 4 | I4: ='Weekly Store Scorecards '!Z5 -> 4.5 | J4: ='Weekly Store Scorecards '!T5 -> 0.0408 | K4: ='Weekly Store Scorecards '!W5 -> 1.05
A5: Rockville | B5: ='Weekly Store Scorecards '!AC6 -> 2.6575 | C5: =IFS(B5<1.7,"Non", B5<2.7,"Low", B5<3.7,"Contributor", B5<4.7,"High", TRUE,"STAR") -> Low | D5: ='Weekly Store Scorecards '!B6 -> 0.87077313 | E5: ='Weekly Store Scorecards '!E6 -> 1.0890977 | F5: ='Weekly Store Scorecards '!K6 -> -0.7 | G5: ='Weekly Store Scorecards '!N6 -> 3.3 | H5: ='Weekly Store Scorecards '!Q6 -> 4.25 | I5: ='Weekly Store Scorecards '!Z6 -> 4.2 | J5: ='Weekly Store Scorecards '!T6 -> 0.0294 | K5: ='Weekly Store Scorecards '!W6 -> 1.43
A6: All Stores | B6: ='Weekly Store Scorecards '!AC7 -> 2.9495 | D6: ='Weekly Store Scorecards '!B7 -> 0.85242532 | E6: ='Weekly Store Scorecards '!E7 -> 1.0642439 | F6: ='Weekly Store Scorecards '!K7 -> -1.9 | G6: ='Weekly Store Scorecards '!N7 -> -0.1 | H6: ='Weekly Store Scorecards '!Q7 -> 3.88 | I6: ='Weekly Store Scorecards '!Z7 -> 4.375 | J6: ='Weekly Store Scorecards '!T7 -> 0.032075 | K6: ='Weekly Store Scorecards '!W7 -> 1.2

Sheet Weekly Store Scorecards
A1: Restaurant | B1: Sales vs Budget (%) | C1: Score | D1: Weighted | E1: Sales vs Prior Year (%) | F1: Score | G1: Weighted | H1: EBITDA vs Budget (%) | I1: Score | J1: Weighted | K1: Labor Var (pts) | L1: Score | M1: Weighted | N1: COGS Var (pts) | O1: Score | P1: Weighted | Q1: Google Rating | R1: Score | S1: Weighted | T1: Yelp Rating | U1: Score | V1: Weighted | W1: 3P Error Rate (%) | X1: Score | Y1: Weighted | Z1: Avoidable Wait (mins) | AA1: Score | AB1: Weighted | AC1: 3P Rating | AD1: Score | AE1: Weighted | AF1: Full Audit Score | AG1: Score | AH1: Weighted | AI1: Culinary Audit Score | AJ1: Score | AK1: Weighted | AL1: Focus Audit Score | AM1: Score | AN1: Weighted | AO1: Training % (Gate) | AP1: Composite Score (0-5)
A2: Ballpark | B2: =100%+'Weekly Tables'!I3 -> 0.94670671 | C2: =IFS(B2="", "", B2<90%,0, B2<95%,1, B2<=98%,2, B2<=101%,3, B2<=105%,4, TRUE,5) -> 1 | D2: =IF(C2="","",C2*5/100) -> 0.05 | E2: =100%+'Weekly Tables'!F3 -> 1.0965152 | F2: =IFS(E2="", "", E2<90%,0, E2<95%,1, E2<=98%,2, E2<=101%,3, E2<=105%,4, TRUE,5) -> 5 | G2: =IF(F2="","",F2*5/100) -> 0.25 | I2: =IFS(H2="", "", H2<75,0, H2<85,1, H2<95,2, H2<=100,3, H2<=105,4, TRUE,5) | J2: =IF(I2="","",I2*15/100) | K2: ='Weekly Tables'!L3*100 -> -2.7 | L2: =IFS(K2="", "", K2>=3,0, K2>=2,1, K2>=1,2, K2>=0,3, K2<=-1,5, K2<=-0.5,4, TRUE,3) -> 5 | M2: =IF(L2="","",L2*15/100) -> 0.75 | N2: ='Weekly Tables'!O3*100 -> -3.4 | O2: =IFS(N2="", "", N2>=3,0, N2>=2,1, N2>=1,2, N2>=0,3, N2<=-1,5, N2<=-0.5,4, TRUE,3) -> 5 | P2: =IF(O2="","",O2*15/100) -> 0.75 | Q2: ='Weekly Tables'!M12 -> NA | R2: =IFS(Q2="", "", Q2="NA","" ,Q2<3.8,0, Q2<4,1, Q2<4.3,2, Q2<4.5,3, Q2<4.7,4, TRUE,5) | S2: =IF(R2="","",R2*21/100) | T2: ='Weekly Tables'!K12 -> NA | U2: =IFS(T2="", "", T2="NA","" ,T2<3.8,0, T2<4,1, T2<4.3,2, T2<4.5,3, T2<4.7,4, TRUE,5) | V2: =IF(U2="","",U2*7.5/100) | W2: ='Weekly Tables'!N20 -> 0.0408 | X2: =IFS(W2="", "", W2>6%,0, W2>4%,1, W2>2%,2, W2>1.5%,3, W2>1%,4, TRUE,5) -> 1 | Y2: =IF(X2="","",X2*10/100) -> 0.1 | Z2: {=XLOOKUP(A2,'Weekly Tables'!$B$30:$B$34,'Weekly Tables'!$H$30:$H$34)} -> #N/A | AA2: =IFS(Z2="","", VALUE(Z2)>8,0, VALUE(Z2)>5,1, VALUE(Z2)>2,2, VALUE(Z2)>1.5,3, VALUE(Z2)>1,4, TRUE,5) -> #N/A | AB2: =IF(AA2="","",AA2*7.5/100) -> #N/A | AC2: ='Weekly Tables'!E20 -> 4.5 | AD2: =IFS(AC2="", "", AC2<3.8,0, AC2<4,1, AC2<4.3,2, AC2<4.5,3, AC2<4.7,4, TRUE,5) -> 4 | AE2: =IF(AD2="","",AD2*7.5/100) -> 0.3 | AF2: 86 | AG2: =IFS(AF2="", "", AF2<70,0, AF2<75,1, AF2<83,2, AF2<89,3, AF2<94,4, TRUE,5) -> 3 | AH2: =IF(AG2="","",AG2*12.5/100) -> 0.375 | AI2: 90 | AJ2: =IFS(AI2="", "", AI2<70,0, AI2<75,1, AI2<83,2, AI2<89,3, AI2<94,4, TRUE,5) -> 4 | AK2: =IF(AJ2="","",AJ2*6.25/100) -> 0.25 | AL2: 95 | AM2: =IFS(AL2="", "", AL2<70,0, AL2<75,1, AL2<83,2, AL2<89,3, AL2<94,4, TRUE,5) -> 5 | AN2: =IF(AM2="","",AM2*6.25/100) -> 0.3125 | AO2: 85 | AP2: =SUM(D2,G2,J2,M2,P2,S2,V2,Y2,AB2,AE2,AH2,AK2,AN2) -> #N/A
A3: Mosaic | B3: =100%+'Weekly Tables'!I4 -> 1.0190662 | C3: =IFS(B3="", "", B3<90%,0, B3<95%,1, B3<=98%,2, B3<=101%,3, B3<=105%,4, TRUE,5) -> 4 | D3: =IF(C3="","",C3*5/100) -> 0.2 | E3: =100%+'Weekly Tables'!F4 -> 1.3761061 | F3: =IFS(E3="", "", E3<90%,0, E3<95%,1, E3<=98%,2, E3<=101%,3, E3<=105%,4, TRUE,5) -> 5 | G3: =IF(F3="","",F3*5/100) -> 0.25 | I3: =IFS(H3="", "", H3<75,0, H3<85,1, H3<95,2, H3<=100,3, H3<=105,4, TRUE,5) | J3: =IF(I3="","",I3*15/100) | K3: ='Weekly Tables'!L4*100 -> 2.4 | L3: =IFS(K3="", "", K3>=3,0, K3>=2,1, K3>=1,2, K3>=0,3, K3<=-1,5, K3<=-0.5,4, TRUE,3) -> 1 | M3: =IF(L3="","",L3*15/100) -> 0.15 | N3: ='Weekly Tables'!O4*100 -> 1.1 | O3: =IFS(N3="", "", N3>=3,0, N3>=2,1, N3>=1,2, N3>=0,3, N3<=-1,5, N3<=-0.5,4, TRUE,3) -> 2 | P3: =IF(O3="","",O3*15/100) -> 0.3 | Q3: ='Weekly Tables'!M15 -> 5 | R3: =IFS(Q3="", "", Q3="NA","" ,Q3<3.8,0, Q3<4,1, Q3<4.3,2, Q3<4.5,3, Q3<4.7,4, TRUE,5) -> 5 | S3: =IF(R3="","",R3*21/100) -> 1.05 | T3: ='Weekly Tables'!K15 -> 2 | U3: =IFS(T3="", "", T3="NA","" ,T3<3.8,0, T3<4,1, T3<4.3,2, T3<4.5,3, T3<4.7,4, TRUE,5) -> 0 | V3: =IF(U3="","",U3*7.5/100) -> 0 | W3: ='Weekly Tables'!N23 -> 0.032075 | X3: =IFS(W3="", "", W3>6%,0, W3>4%,1, W3>2%,2, W3>1.5%,3, W3>1%,4, TRUE,5) -> 2 | Y3: =IF(X3="","",X3*10/100) -> 0.2 | Z3: {=XLOOKUP(A3,'Weekly Tables'!$B$30:$B$34,'Weekly Tables'!$H$30:$H$34)} -> 1.6 | AA3: =IFS(Z3="","", VALUE(Z3)>8,0, VALUE(Z3)>5,1, VALUE(Z3)>2,2, VALUE(Z3)>1.5,3, VALUE(Z3)>1,4, TRUE,5) -> 3 | AB3: =IF(AA3="","",AA3*7.5/100) -> 0.225 | AC3: ='Weekly Tables'!E23 -> 4.375 | AD3: =IFS(AC3="", "", AC3<3.8,0, AC3<4,1, AC3<4.3,2, AC3<4.5,3, AC3<4.7,4, TRUE,5) -> 3 | AE3: =IF(AD3="","",AD3*7.5/100) -> 0.225 | AF3: 67 | AG3: =IFS(AF3="", "", AF3<70,0, AF3<75,1, AF3<83,2, AF3<89,3, AF3<94,4, TRUE,5) -> 0 | AH3: =IF(AG3="","",AG3*12.5/100) -> 0 | AI3: 70 | AJ3: =IFS(AI3="", "", AI3<70,0, AI3<75,1, AI3<83,2, AI3<89,3, AI3<94,4, TRUE,5) -> 1 | AK3: =IF(AJ3="","",AJ3*6.25/100) -> 0.0625 | AL3: 76 | AM3: =IFS(AL3="", "", AL3<70,0, AL3<75,1, AL3<83,2, AL3<89,3, AL3<94,4, TRUE,5) -> 2 | AN3: =IF(AM3="","",AM3*6.25/100) -> 0.125 | AO3: 87 | AP3: =SUM(D3,G3,J3,M3,P3,S3,V3,Y3,AB3,AE3,AH3,AK3,AN3) -> 2.7875
A4: MVT | B4: =100%+'Weekly Tables'!I5 -> 1.2172449 | C4: =IFS(B4="", "", B4<90%,0, B4<95%,1, B4<=98%,2, B4<=101%,3, B4<=105%,4, TRUE,5) -> 5 | D4: =IF(C4="","",C4*5/100) -> 0.25 | E4: =100%+'Weekly Tables'!F5 -> 1.4285788 | F4: =IFS(E4="", "", E4<90%,0, E4<95%,1, E4<=98%,2, E4<=101%,3, E4<=105%,4, TRUE,5) -> 5 | G4: =IF(F4="","",F4*5/100) -> 0.25 | I4: =IFS(H4="", "", H4<75,0, H4<85,1, H4<95,2, H4<=100,3, H4<=105,4, TRUE,5) | J4: =IF(I4="","",I4*15/100) | K4: ='Weekly Tables'!L5*100 -> -4.1 | L4: =IFS(K4="", "", K4>=3,0, K4>=2,1, K4>=1,2, K4>=0,3, K4<=-1,5, K4<=-0.5,4, TRUE,3) -> 5 | M4: =IF(L4="","",L4*15/100) -> 0.75 | N4: ='Weekly Tables'!O5*100 -> 0.2 | O4: =IFS(N4="", "", N4>=3,0, N4>=2,1, N4>=1,2, N4>=0,3, N4<=-1,5, N4<=-0.5,4, TRUE,3) -> 3 | P4: =IF(O4="","",O4*15/100) -> 0.45 | Q4: ='Weekly Tables'!M13 -> 4 | R4: =IFS(Q4="", "", Q4="NA","" ,Q4<3.8,0, Q4<4,1, Q4<4.3,2, Q4<4.5,3, Q4<4.7,4, TRUE,5) -> 2 | S4: =IF(R4="","",R4*21/100) -> 0.42 | T4: ='Weekly Tables'!K13 -> NA | U4: =IFS(T4="", "", T4="NA","" ,T4<3.8,0, T4<4,1, T4<4.3,2, T4<4.5,3, T4<4.7,4, TRUE,5) | V4: =IF(U4="","",U4*7.5/100) | W4: ='Weekly Tables'!N21 -> 0.0372 | X4: =IFS(W4="", "", W4>6%,0, W4>4%,1, W4>2%,2, W4>1.5%,3, W4>1%,4, TRUE,5) -> 2 | Y4: =IF(X4="","",X4*10/100) -> 0.2 | Z4: {=XLOOKUP(A4,'Weekly Tables'!$B$30:$B$34,'Weekly Tables'!$H$30:$H$34)} -> 1.02 | AA4: =IFS(Z4="","", VALUE(Z4)>8,0, VALUE(Z4)>5,1, VALUE(Z4)>2,2, VALUE(Z4)>1.5,3, VALUE(Z4)>1,4, TRUE,5) -> 4 | AB4: =IF(AA4="","",AA4*7.5/100) -> 0.3 | AC4: ='Weekly Tables'!E21 -> 4.3 | AD4: =IFS(AC4="", "", AC4<3.8,0, AC4<4,1, AC4<4.3,2, AC4<4.5,3, AC4<4.7,4, TRUE,5) -> 3 | AE4: =IF(AD4="","",AD4*7.5/100) -> 0.225 | AF4: 72 | AG4: =IFS(AF4="", "", AF4<70,0, AF4<75,1, AF4<83,2, AF4<89,3, AF4<94,4, TRUE,5) -> 1 | AH4: =IF(AG4="","",AG4*12.5/100) -> 0.125 | AI4: 76 | AJ4: =IFS(AI4="", "", AI4<70,0, AI4<75,1, AI4<83,2, AI4<89,3, AI4<94,4, TRUE,5) -> 2 | AK4: =IF(AJ4="","",AJ4*6.25/100) -> 0.125 | AL4: 78 | AM4: =IFS(AL4="", "", AL4<70,0, AL4<75,1, AL4<83,2, AL4<89,3, AL4<94,4, TRUE,5) -> 2 | AN4: =IF(AM4="","",AM4*6.25/100) -> 0.125 | AO4: 93 | AP4: =SUM(D4,G4,J4,M4,P4,S4,V4,Y4,AB4,AE4,AH4,AK4,AN4) -> 3.22
A5: National Landing | B5: =100%+'Weekly Tables'!I6 -> 0.87077313 | C5: =IFS(B5="", "", B5<90%,0, B5<95%,1, B5<=98%,2, B5<=101%,3, B5<=105%,4, TRUE,5) -> 0 | D5: =IF(C5="","",C5*5/100) -> 0 | E5: =100%+'Weekly Tables'!F6 -> 1.0890977 | F5: =IFS(E5="", "", E5<90%,0, E5<95%,1, E5<=98%,2, E5<=101%,3, E5<=105%,4, TRUE,5) -> 5 | G5: =IF(F5="","",F5*5/100) -> 0.25 | I5: =IFS(H5="", "", H5<75,0, H5<85,1, H5<95,2, H5<=100,3, H5<=105,4, TRUE,5) | J5: =IF(I5="","",I5*15/100) | K5: ='Weekly Tables'!L6*100 -> -0.7 | L5: =IFS(K5="", "", K5>=3,0, K5>=2,1, K5>=1,2, K5>=0,3, K5<=-1,5, K5<=-0.5,4, TRUE,3) -> 4 | M5: =IF(L5="","",L5*15/100) -> 0.6 | N5: ='Weekly Tables'!O6*100 -> 3.3 | O5: =IFS(N5="", "", N5>=3,0, N5>=2,1, N5>=1,2, N5>=0,3, N5<=-1,5, N5<=-0.5,4, TRUE,3) -> 0 | P5: =IF(O5="","",O5*15/100) -> 0 | Q5: ='Weekly Tables'!M14 -> 3.33 | R5: =IFS(Q5="", "", Q5="NA","" ,Q5<3.8,0, Q5<4,1, Q5<4.3,2, Q5<4.5,3, Q5<4.7,4, TRUE,5) -> 0 | S5: =IF(R5="","",R5*21/100) -> 0 | T5: ='Weekly Tables'!K14 -> NA | U5: =IFS(T5="", "", T5="NA","" ,T5<3.8,0, T5<4,1, T5<4.3,2, T5<4.5,3, T5<4.7,4, TRUE,5) | V5: =IF(U5="","",U5*7.5/100) | W5: ='Weekly Tables'!N22 -> 0.0294 | X5: =IFS(W5="", "", W5>6%,0, W5>4%,1, W5>2%,2, W5>1.5%,3, W5>1%,4, TRUE,5) -> 2 | Y5: =IF(X5="","",X5*10/100) -> 0.2 | Z5: {=XLOOKUP(A5,'Weekly Tables'!$B$30:$B$34,'Weekly Tables'!$H$30:$H$34)} -> 1.05 | AA5: =IFS(Z5="","", VALUE(Z5)>8,0, VALUE(Z5)>5,1, VALUE(Z5)>2,2, VALUE(Z5)>1.5,3, VALUE(Z5)>1,4, TRUE,5) -> 4 | AB5: =IF(AA5="","",AA5*7.5/100) -> 0.3 | AC5: ='Weekly Tables'!E22 -> 4.2 | AD5: =IFS(AC5="", "", AC5<3.8,0, AC5<4,1, AC5<4.3,2, AC5<4.5,3, AC5<4.7,4, TRUE,5) -> 2 | AE5: =IF(AD5="","",AD5*7.5/100) -> 0.15 | AF5: 70 | AG5: =IFS(AF5="", "", AF5<70,0, AF5<75,1, AF5<83,2, AF5<89,3, AF5<94,4, TRUE,5) -> 1 | AH5: =IF(AG5="","",AG5*12.5/100) -> 0.125 | AI5: 75 | AJ5: =IFS(AI5="", "", AI5<70,0, AI5<75,1, AI5<83,2, AI5<89,3, AI5<94,4, TRUE,5) -> 2 | AK5: =IF(AJ5="","",AJ5*6.25/100) -> 0.125 | AL5: 71 | AM5: =IFS(AL5="", "", AL5<70,0, AL5<75,1, AL5<83,2, AL5<89,3, AL5<94,4, TRUE,5) -> 1 | AN5: =IF(AM5="","",AM5*6.25/100) -> 0.0625 | AO5: 80 | AP5: =SUM(D5,G5,J5,M5,P5,S5,V5,Y5,AB5,AE5,AH5,AK5,AN5) -> 1.8125
A6: Rockville | B6: =100%+'Weekly Tables'!I7 -> 0.85242532 | C6: =IFS(B6="", "", B6<90%,0, B6<95%,1, B6<=98%,2, B6<=101%,3, B6<=105%,4, TRUE,5) -> 0 | D6: =IF(C6="","",C6*5/100) -> 0 | E6: =100%+'Weekly Tables'!F7 -> 1.0642439 | F6: =IFS(E6="", "", E6<90%,0, E6<95%,1, E6<=98%,2, E6<=101%,3, E6<=105%,4, TRUE,5) -> 5 | G6: =IF(F6="","",F6*5/100) -> 0.25 | I6: =IFS(H6="", "", H6<75,0, H6<85,1, H6<95,2, H6<=100,3, H6<=105,4, TRUE,5) | J6: =IF(I6="","",I6*15/100) | K6: ='Weekly Tables'!L7*100 -> -1.9 | L6: =IFS(K6="", "", K6>=3,0, K6>=2,1, K6>=1,2, K6>=0,3, K6<=-1,5, K6<=-0.5,4, TRUE,3) -> 5 | M6: =IF(L6="","",L6*15/100) -> 0.75 | N6: ='Weekly Tables'!O7*100 -> -0.1 | O6: =IFS(N6="", "", N6>=3,0, N6>=2,1, N6>=1,2, N6>=0,3, N6<=-1,5, N6<=-0.5,4, TRUE,3) -> 3 | P6: =IF(O6="","",O6*15/100) -> 0.45 | Q6: ='Weekly Tables'!M16 -> 4.14 | R6: =IFS(Q6="", "", Q6="NA","" ,Q6<3.8,0, Q6<4,1, Q6<4.3,2, Q6<4.5,3, Q6<4.7,4, TRUE,5) -> 2 | S6: =IF(R6="","",R6*21/100) -> 0.42 | T6: ='Weekly Tables'!K16 -> 2 | U6: =IFS(T6="", "", T6="NA","" ,T6<3.8,0, T6<4,1, T6<4.3,2, T6<4.5,3, T6<4.7,4, TRUE,5) -> 0 | V6: =IF(U6="","",U6*7.5/100) -> 0 | W6: ='Weekly Tables'!N24 | X6: =IFS(W6="", "", W6>6%,0, W6>4%,1, W6>2%,2, W6>1.5%,3, W6>1%,4, TRUE,5) | Y6: =IF(X6="","",X6*10/100) | Z6: {=XLOOKUP(A6,'Weekly Tables'!$B$30:$B$34,'Weekly Tables'!$H$30:$H$34)} -> 1.43 | AA6: =IFS(Z6="","", VALUE(Z6)>8,0, VALUE(Z6)>5,1, VALUE(Z6)>2,2, VALUE(Z6)>1.5,3, VALUE(Z6)>1,4, TRUE,5) -> 4 | AB6: =IF(AA6="","",AA6*7.5/100) -> 0.3 | AC6: ='Weekly Tables'!E24 | AD6: =IFS(AC6="", "", AC6<3.8,0, AC6<4,1, AC6<4.3,2, AC6<4.5,3, AC6<4.7,4, TRUE,5) | AE6: =IF(AD6="","",AD6*7.5/100) | AF6: 56 | AG6: =IFS(AF6="", "", AF6<70,0, AF6<75,1, AF6<83,2, AF6<89,3, AF6<94,4, TRUE,5) -> 0 | AH6: =IF(AG6="","",AG6*12.5/100) -> 0 | AI6: 60 | AJ6: =IFS(AI6="", "", AI6<70,0, AI6<75,1, AI6<83,2, AI6<89,3, AI6<94,4, TRUE,5) -> 0 | AK6: =IF(AJ6="","",AJ6*6.25/100) -> 0 | AL6: 60 | AM6: =IFS(AL6="", "", AL6<70,0, AL6<75,1, AL6<83,2, AL6<89,3, AL6<94,4, TRUE,5) -> 0 | AN6: =IF(AM6="","",AM6*6.25/100) -> 0 | AO6: 78 | AP6: =SUM(D6,G6,J6,M6,P6,S6,V6,Y6,AB6,AE6,AH6,AK6,AN6) -> 2.17
C8: =IF(B2="","",ROUND(IF(B2>=105%,5,IF(B2>=102%,4+(B2-102%)/(105%-102%),IF(B2>=99%,3+(B2-99%)/(102%-99%),IF(B2>=95%,2+(B2-95%)/(99%-95%),IF(B2>=90%,1+(B2-90%)/(95%-90%),0))))),1)) -> 1.9 | F8: =IF(E2="","",ROUND(IF(E2>=105%,5,IF(E2>=102%,4+(E2-102%)/(105%-102%),IF(E2>=99%,3+(E2-99%)/(102%-99%),IF(E2>=95%,2+(E2-95%)/(99%-95%),IF(E2>=90%,1+(E2-90%)/(95%-90%),0))))),1)) -> 5
C9: =IF(B3="","",ROUND(IF(B3>=105%,5,IF(B3>=102%,4+(B3-102%)/(105%-102%),IF(B3>=99%,3+(B3-99%)/(102%-99%),IF(B3>=95%,2+(B3-95%)/(99%-95%),IF(B3>=90%,1+(B3-90%)/(95%-90%),0))))),1)) -> 4 | F9: =IF(E3="","",ROUND(IF(E3>=105%,5,IF(E3>=102%,4+(E3-102%)/(105%-102%),IF(E3>=99%,3+(E3-99%)/(102%-99%),IF(E3>=95%,2+(E3-95%)/(99%-95%),IF(E3>=90%,1+(E3-90%)/(95%-90%),0))))),1)) -> 5
C10: =IF(B4="","",ROUND(IF(B4>=105%,5,IF(B4>=102%,4+(B4-102%)/(105%-102%),IF(B4>=99%,3+(B4-99%)/(102%-99%),IF(B4>=95%,2+(B4-95%)/(99%-95%),IF(B4>=90%,1+(B4-90%)/(95%-90%),0))))),1)) -> 5 | F10: =IF(E4="","",ROUND(IF(E4>=105%,5,IF(E4>=102%,4+(E4-102%)/(105%-102%),IF(E4>=99%,3+(E4-99%)/(102%-99%),IF(E4>=95%,2+(E4-95%)/(99%-95%),IF(E4>=90%,1+(E4-90%)/(95%-90%),0))))),1)) -> 5
C11: =IF(B5="","",ROUND(IF(B5>=105%,5,IF(B5>=102%,4+(B5-102%)/(105%-102%),IF(B5>=99%,3+(B5-99%)/(102%-99%),IF(B5>=95%,2+(B5-95%)/(99%-95%),IF(B5>=90%,1+(B5-90%)/(95%-90%),0))))),1)) -> 0 | F11: =IF(E5="","",ROUND(IF(E5>=105%,5,IF(E5>=102%,4+(E5-102%)/(105%-102%),IF(E5>=99%,3+(E5-99%)/(102%-99%),IF(E5>=95%,2+(E5-95%)/(99%-95%),IF(E5>=90%,1+(E5-90%)/(95%-90%),0))))),1)) -> 5
C12: =IF(B6="","",ROUND(IF(B6>=105%,5,IF(B6>=102%,4+(B6-102%)/(105%-102%),IF(B6>=99%,3+(B6-99%)/(102%-99%),IF(B6>=95%,2+(B6-95%)/(99%-95%),IF(B6>=90%,1+(B6-90%)/(95%-90%),0))))),1)) -> 0 | F12: =IF(E6="","",ROUND(IF(E6>=105%,5,IF(E6>=102%,4+(E6-102%)/(105%-102%),IF(E6>=99%,3+(E6-99%)/(102%-99%),IF(E6>=95%,2+(E6-95%)/(99%-95%),IF(E6>=90%,1+(E6-90%)/(95%-90%),0))))),1)) -> 5

Sheet PERIODIC>>>

Sheet Period Store Scorecards 
A1: Location | B1: Sales vs Budget (%) | E1: Sales vs Prior Year (%) | H1: EBITDA vs Budget (%) | K1: Labor vs Budget Variance (pts) | N1: COGS vs Budget Variance (pts) | Q1: In-Store Rating | T1: 3P Error Rate (%) | W1: Avoidable Wait (mins) | Z1: 3P Rating | AC1: Full Audit Score | AF1: Culinary Audit Score | AI1: Training Completion % (Gate) | AJ1: Composite Score (0–5)
B2: Input | C2: Score | D2: Weighted | E2: Input | F2: Score | G2: Weighted | H2: Input | I2: Score | J2: Weighted | K2: Input | L2: Score | M2: Weighted | N2: Input | O2: Score | P2: Weighted | Q2: Input | R2: Score | S2: Weighted | T2: Input | U2: Score | V2: Weighted | W2: Input | X2: Score | Y2: Weighted | Z2: Input | AA2: Score | AB2: Weighted | AC2: Input | AD2: Score | AE2: Weighted | AF2: Input | AG2: Score | AH2: Weighted | AI2: Input
A3: Ballpark | B3: =100%+'Period Tables'!I3 -> 0.0005532557 | C3: =IFERROR(ROUND(ifs(B3="","",B3>=1.05,5,B3>=1.02,4+(B3-1.02)/0.03,B3>=0.99,3+(B3-0.99)/0.03,B3>=0.95,2+(B3-0.95)/0.04,B3>=0.9,1+(B3-0.9)/0.05,TRUE(),0),1),"") -> 0 | D3: =IF(C3="","",C3*C$9) -> 0 | E3: =100%+'Period Tables'!F3 -> 0.00070625625 | F3: =IFERROR(ROUND(ifs(E3="","",E3>=1.15,5,E3>=1.075,4+(E3-1.075)/0.075,E3>=1.05,3+(E3-1.05)/0.025,E3>=1,2+(E3-1)/0.05,E3>=0.95,1+(E3-0.95)/0.05,TRUE(),0),1),"") -> 0 | G3: =IF(F3="","",F3*F$9) -> 0 | H3: =100%+'Period Tables'!V3 -> #DIV/0! | I3: =IFERROR(ROUND(ifs(H3="","",H3>=1.05,5,H3>=1.01,4+(H3-1.01)/0.04,H3>=0.95,3+(H3-0.95)/0.06,H3>=0.85,2+(H3-0.85)/0.1,H3>=0.75,1+(H3-0.75)/0.1,TRUE(),0),1),"") | J3: =IF(I3="","",I3*I$9) | K3: ='Period Tables'!L3*100 -> -30.8 | L3: =IFERROR(ROUND(IFS(K3="","",K3>=3,0,K3>=2,1+(3-K3)/1,K3>=1,2+(2-K3)/1,K3>0,3+(1-K3)/1,K3>=-1,4+(0-K3)/1,TRUE,5),1),"") -> 5 | M3: =IF(L3="","",L3*L$9) -> 0.525 | N3: ='Period Tables'!O3*100 -> -26.4 | O3: =IFERROR(ROUND(IFS(N3="","",N3>=3,0,N3>=2,1+(3-N3)/1,N3>=1,2+(2-N3)/1,N3>0,3+(1-N3)/1,N3>=-1,4+(0-N3)/1,TRUE,5),1),"") -> 5 | P3: =IF(O3="","",O3*O$9) -> 0.525 | Q3: ='Period Tables'!E12 -> 5 | R3: =IF(OR(NOT(ISNUMBER(Q3)),Q3=0),"",IFERROR(ROUND(ifs(Q3>=4.7,5,Q3>=4.5,4+(Q3-4.5)/0.2,Q3>=4.3,3+(Q3-4.3)/0.2,Q3>=4,2+(Q3-4)/0.3,Q3>=3.8,1+(Q3-3.8)/0.2,TRUE(),0),1),"")) -> 5 | S3: =IF(R3="","",R3*R$9) -> 1.05 | T3: ='Period Tables'!I20 -> 0.0405 | U3: =IFERROR(ROUND(ifs(T3="","",T3<=0.01,5,T3<=0.015,4+(0.015-T3)/0.005,T3<=0.02,3+(0.02-T3)/0.005,T3<=0.04,2+(0.04-T3)/0.02,T3<=0.06,1+(0.06-T3)/0.02,TRUE(),0),1),"") -> 2 | V3: =IF(U3="","",U3*U$9) -> 0.17 | W3: ='Period Tables'!H31 -> 0.57 | X3: =IFERROR(ROUND(ifs(W3="","",W3<=1,5,W3<=1.5,4+(1.5-W3)/0.5,W3<=2,3+(2-W3)/0.5,W3<=5,2+(5-W3)/3,W3<=8,1+(8-W3)/3,TRUE(),0),1),"") -> 5 | Y3: =IF(X3="","",X3*X$9) -> 0.325 | Z3: ='Period Tables'!E20 -> 4 | AA3: =IF(OR(NOT(ISNUMBER(Z3)),Z3=0),"",IFERROR(ROUND(ifs(Z3>=4.7,5,Z3>=4.5,4+(Z3-4.5)/0.2,Z3>=4.3,3+(Z3-4.3)/0.2,Z3>=4,2+(Z3-4)/0.3,Z3>=3.8,1+(Z3-3.8)/0.2,TRUE(),0),1),"")) -> 2 | AB3: =IF(AA3="","",AA3*AA$9) -> 0.13 | AC3: 92 | AD3: =IFERROR(ROUND(ifs(AC3="","",AC3>=94,5,AC3>=89,4+(AC3-89)/5,AC3>=83,3+(AC3-83)/6,AC3>=75,2+(AC3-75)/8,AC3>=70,1+(AC3-70)/5,TRUE(),0),1),"") -> 4.6 | AE3: =IF(AD3="","",AD3*AD$9) -> 0.483 | AF3: 90 | AG3: =IFERROR(ROUND(ifs(AF3="","",AF3>=94,5,AF3>=89,4+(AF3-89)/5,AF3>=83,3+(AF3-83)/6,AF3>=75,2+(AF3-75)/8,AF3>=70,1+(AF3-70)/5,TRUE(),0),1),"") -> 4.2 | AH3: =IF(AG3="","",AG3*AG$9) -> 0.231 | AI3: 0.85 | AJ3: =SUM(D3,G3,J3,M3,P3,S3,V3,Y3,AB3,AE3,AH3) -> 3.439
A4: Mosaic | B4: =100%+'Period Tables'!I4 -> 0.94670671 | C4: =IFERROR(ROUND(ifs(B4="","",B4>=1.05,5,B4>=1.02,4+(B4-1.02)/0.03,B4>=0.99,3+(B4-0.99)/0.03,B4>=0.95,2+(B4-0.95)/0.04,B4>=0.9,1+(B4-0.9)/0.05,TRUE(),0),1),"") -> 1.9 | D4: =IF(C4="","",C4*C$9) -> 0.076 | E4: =100%+'Period Tables'!F4 -> 1.0965152 | F4: =IFERROR(ROUND(ifs(E4="","",E4>=1.15,5,E4>=1.075,4+(E4-1.075)/0.075,E4>=1.05,3+(E4-1.05)/0.025,E4>=1,2+(E4-1)/0.05,E4>=0.95,1+(E4-0.95)/0.05,TRUE(),0),1),"") -> 4.3 | G4: =IF(F4="","",F4*F$9) -> 0.172 | H4: =100%+'Period Tables'!V4 -> #DIV/0! | I4: =IFERROR(ROUND(ifs(H4="","",H4>=1.05,5,H4>=1.01,4+(H4-1.01)/0.04,H4>=0.95,3+(H4-0.95)/0.06,H4>=0.85,2+(H4-0.85)/0.1,H4>=0.75,1+(H4-0.75)/0.1,TRUE(),0),1),"") | J4: =IF(I4="","",I4*I$9) | K4: ='Period Tables'!L4*100 -> -2.7 | L4: =IFERROR(ROUND(IFS(K4="","",K4>=3,0,K4>=2,1+(3-K4)/1,K4>=1,2+(2-K4)/1,K4>0,3+(1-K4)/1,K4>=-1,4+(0-K4)/1,TRUE,5),1),"") -> 5 | M4: =IF(L4="","",L4*L$9) -> 0.525 | N4: ='Period Tables'!O4*100 -> -3.4 | O4: =IFERROR(ROUND(IFS(N4="","",N4>=3,0,N4>=2,1+(3-N4)/1,N4>=1,2+(2-N4)/1,N4>0,3+(1-N4)/1,N4>=-1,4+(0-N4)/1,TRUE,5),1),"") -> 5 | P4: =IF(O4="","",O4*O$9) -> 0.525 | Q4: ='Period Tables'!E15 -> 4.67 | R4: =IF(OR(NOT(ISNUMBER(Q4)),Q4=0),"",IFERROR(ROUND(ifs(Q4>=4.7,5,Q4>=4.5,4+(Q4-4.5)/0.2,Q4>=4.3,3+(Q4-4.3)/0.2,Q4>=4,2+(Q4-4)/0.3,Q4>=3.8,1+(Q4-3.8)/0.2,TRUE(),0),1),"")) -> 4.9 | S4: =IF(R4="","",R4*R$9) -> 1.029 | T4: ='Period Tables'!I23 -> 0.0315 | U4: =IFERROR(ROUND(ifs(T4="","",T4<=0.01,5,T4<=0.015,4+(0.015-T4)/0.005,T4<=0.02,3+(0.02-T4)/0.005,T4<=0.04,2+(0.04-T4)/0.02,T4<=0.06,1+(0.06-T4)/0.02,TRUE(),0),1),"") -> 2.4 | V4: =IF(U4="","",U4*U$9) -> 0.204 | W4: ='Period Tables'!H34 -> 1.48 | X4: =IFERROR(ROUND(ifs(W4="","",W4<=1,5,W4<=1.5,4+(1.5-W4)/0.5,W4<=2,3+(2-W4)/0.5,W4<=5,2+(5-W4)/3,W4<=8,1+(8-W4)/3,TRUE(),0),1),"") -> 4 | Y4: =IF(X4="","",X4*X$9) -> 0.26 | Z4: ='Period Tables'!E23 -> 4.4 | AA4: =IF(OR(NOT(ISNUMBER(Z4)),Z4=0),"",IFERROR(ROUND(ifs(Z4>=4.7,5,Z4>=4.5,4+(Z4-4.5)/0.2,Z4>=4.3,3+(Z4-4.3)/0.2,Z4>=4,2+(Z4-4)/0.3,Z4>=3.8,1+(Z4-3.8)/0.2,TRUE(),0),1),"")) -> 3.5 | AB4: =IF(AA4="","",AA4*AA$9) -> 0.2275 | AC4: 88 | AD4: =IFERROR(ROUND(ifs(AC4="","",AC4>=94,5,AC4>=89,4+(AC4-89)/5,AC4>=83,3+(AC4-83)/6,AC4>=75,2+(AC4-75)/8,AC4>=70,1+(AC4-70)/5,TRUE(),0),1),"") -> 3.8 | AE4: =IF(AD4="","",AD4*AD$9) -> 0.399 | AF4: 86 | AG4: =IFERROR(ROUND(ifs(AF4="","",AF4>=94,5,AF4>=89,4+(AF4-89)/5,AF4>=83,3+(AF4-83)/6,AF4>=75,2+(AF4-75)/8,AF4>=70,1+(AF4-70)/5,TRUE(),0),1),"") -> 3.5 | AH4: =IF(AG4="","",AG4*AG$9) -> 0.1925 | AI4: 0.87 | AJ4: =SUM(D4,G4,J4,M4,P4,S4,V4,Y4,AB4,AE4,AH4) -> 3.61
A5: MVT | B5: =100%+'Period Tables'!I5 -> 1.0190662 | C5: =IFERROR(ROUND(ifs(B5="","",B5>=1.05,5,B5>=1.02,4+(B5-1.02)/0.03,B5>=0.99,3+(B5-0.99)/0.03,B5>=0.95,2+(B5-0.95)/0.04,B5>=0.9,1+(B5-0.9)/0.05,TRUE(),0),1),"") -> 4 | D5: =IF(C5="","",C5*C$9) -> 0.16 | E5: =100%+'Period Tables'!F5 -> 1.3761061 | F5: =IFERROR(ROUND(ifs(E5="","",E5>=1.15,5,E5>=1.075,4+(E5-1.075)/0.075,E5>=1.05,3+(E5-1.05)/0.025,E5>=1,2+(E5-1)/0.05,E5>=0.95,1+(E5-0.95)/0.05,TRUE(),0),1),"") -> 5 | G5: =IF(F5="","",F5*F$9) -> 0.2 | H5: =100%+'Period Tables'!V5 -> #DIV/0! | I5: =IFERROR(ROUND(ifs(H5="","",H5>=1.05,5,H5>=1.01,4+(H5-1.01)/0.04,H5>=0.95,3+(H5-0.95)/0.06,H5>=0.85,2+(H5-0.85)/0.1,H5>=0.75,1+(H5-0.75)/0.1,TRUE(),0),1),"") | J5: =IF(I5="","",I5*I$9) | K5: ='Period Tables'!L5*100 -> 2.4 | L5: =IFERROR(ROUND(IFS(K5="","",K5>=3,0,K5>=2,1+(3-K5)/1,K5>=1,2+(2-K5)/1,K5>0,3+(1-K5)/1,K5>=-1,4+(0-K5)/1,TRUE,5),1),"") -> 1.6 | M5: =IF(L5="","",L5*L$9) -> 0.168 | N5: ='Period Tables'!O5*100 -> 1.1 | O5: =IFERROR(ROUND(IFS(N5="","",N5>=3,0,N5>=2,1+(3-N5)/1,N5>=1,2+(2-N5)/1,N5>0,3+(1-N5)/1,N5>=-1,4+(0-N5)/1,TRUE,5),1),"") -> 2.9 | P5: =IF(O5="","",O5*O$9) -> 0.3045 | Q5: ='Period Tables'!E13 -> 3 | R5: =IF(OR(NOT(ISNUMBER(Q5)),Q5=0),"",IFERROR(ROUND(ifs(Q5>=4.7,5,Q5>=4.5,4+(Q5-4.5)/0.2,Q5>=4.3,3+(Q5-4.3)/0.2,Q5>=4,2+(Q5-4)/0.3,Q5>=3.8,1+(Q5-3.8)/0.2,TRUE(),0),1),"")) -> 0 | S5: =IF(R5="","",R5*R$9) -> 0 | T5: ='Period Tables'!I21 -> 0.0264 | U5: =IFERROR(ROUND(ifs(T5="","",T5<=0.01,5,T5<=0.015,4+(0.015-T5)/0.005,T5<=0.02,3+(0.02-T5)/0.005,T5<=0.04,2+(0.04-T5)/0.02,T5<=0.06,1+(0.06-T5)/0.02,TRUE(),0),1),"") -> 2.7 | V5: =IF(U5="","",U5*U$9) -> 0.2295 | W5: ='Period Tables'!H32 -> 0.59 | X5: =IFERROR(ROUND(ifs(W5="","",W5<=1,5,W5<=1.5,4+(1.5-W5)/0.5,W5<=2,3+(2-W5)/0.5,W5<=5,2+(5-W5)/3,W5<=8,1+(8-W5)/3,TRUE(),0),1),"") -> 5 | Y5: =IF(X5="","",X5*X$9) -> 0.325 | Z5: ='Period Tables'!E21 -> 4.5 | AA5: =IF(OR(NOT(ISNUMBER(Z5)),Z5=0),"",IFERROR(ROUND(ifs(Z5>=4.7,5,Z5>=4.5,4+(Z5-4.5)/0.2,Z5>=4.3,3+(Z5-4.3)/0.2,Z5>=4,2+(Z5-4)/0.3,Z5>=3.8,1+(Z5-3.8)/0.2,TRUE(),0),1),"")) -> 4 | AB5: =IF(AA5="","",AA5*AA$9) -> 0.26 | AC5: 91 | AD5: =IFERROR(ROUND(ifs(AC5="","",AC5>=94,5,AC5>=89,4+(AC5-89)/5,AC5>=83,3+(AC5-83)/6,AC5>=75,2+(AC5-75)/8,AC5>=70,1+(AC5-70)/5,TRUE(),0),1),"") -> 4.4 | AE5: =IF(AD5="","",AD5*AD$9) -> 0.462 | AF5: 93 | AG5: =IFERROR(ROUND(ifs(AF5="","",AF5>=94,5,AF5>=89,4+(AF5-89)/5,AF5>=83,3+(AF5-83)/6,AF5>=75,2+(AF5-75)/8,AF5>=70,1+(AF5-70)/5,TRUE(),0),1),"") -> 4.8 | AH5: =IF(AG5="","",AG5*AG$9) -> 0.264 | AI5: 0.93 | AJ5: =SUM(D5,G5,J5,M5,P5,S5,V5,Y5,AB5,AE5,AH5) -> 2.373
A6: National Landing | B6: =100%+'Period Tables'!I6 -> 1.2172449 | C6: =IFERROR(ROUND(ifs(B6="","",B6>=1.05,5,B6>=1.02,4+(B6-1.02)/0.03,B6>=0.99,3+(B6-0.99)/0.03,B6>=0.95,2+(B6-0.95)/0.04,B6>=0.9,1+(B6-0.9)/0.05,TRUE(),0),1),"") -> 5 | D6: =IF(C6="","",C6*C$9) -> 0.2 | E6: =100%+'Period Tables'!F6 -> 1.4285788 | F6: =IFERROR(ROUND(ifs(E6="","",E6>=1.15,5,E6>=1.075,4+(E6-1.075)/0.075,E6>=1.05,3+(E6-1.05)/0.025,E6>=1,2+(E6-1)/0.05,E6>=0.95,1+(E6-0.95)/0.05,TRUE(),0),1),"") -> 5 | G6: =IF(F6="","",F6*F$9) -> 0.2 | H6: =100%+'Period Tables'!V6 -> #DIV/0! | I6: =IFERROR(ROUND(ifs(H6="","",H6>=1.05,5,H6>=1.01,4+(H6-1.01)/0.04,H6>=0.95,3+(H6-0.95)/0.06,H6>=0.85,2+(H6-0.85)/0.1,H6>=0.75,1+(H6-0.75)/0.1,TRUE(),0),1),"") | J6: =IF(I6="","",I6*I$9) | K6: ='Period Tables'!L6*100 -> -4.1 | L6: =IFERROR(ROUND(IFS(K6="","",K6>=3,0,K6>=2,1+(3-K6)/1,K6>=1,2+(2-K6)/1,K6>0,3+(1-K6)/1,K6>=-1,4+(0-K6)/1,TRUE,5),1),"") -> 5 | M6: =IF(L6="","",L6*L$9) -> 0.525 | N6: ='Period Tables'!O6*100 -> 0.2 | O6: =IFERROR(ROUND(IFS(N6="","",N6>=3,0,N6>=2,1+(3-N6)/1,N6>=1,2+(2-N6)/1,N6>0,3+(1-N6)/1,N6>=-1,4+(0-N6)/1,TRUE,5),1),"") -> 3.8 | P6: =IF(O6="","",O6*O$9) -> 0.399 | Q6: ='Period Tables'!E14 -> 4.33 | R6: =IF(OR(NOT(ISNUMBER(Q6)),Q6=0),"",IFERROR(ROUND(ifs(Q6>=4.7,5,Q6>=4.5,4+(Q6-4.5)/0.2,Q6>=4.3,3+(Q6-4.3)/0.2,Q6>=4,2+(Q6-4)/0.3,Q6>=3.8,1+(Q6-3.8)/0.2,TRUE(),0),1),"")) -> 3.2 | S6: =IF(R6="","",R6*R$9) -> 0.672 | T6: ='Period Tables'!I22 -> 0.0315 | U6: =IFERROR(ROUND(ifs(T6="","",T6<=0.01,5,T6<=0.015,4+(0.015-T6)/0.005,T6<=0.02,3+(0.02-T6)/0.005,T6<=0.04,2+(0.04-T6)/0.02,T6<=0.06,1+(0.06-T6)/0.02,TRUE(),0),1),"") -> 2.4 | V6: =IF(U6="","",U6*U$9) -> 0.204 | W6: ='Period Tables'!H33 -> 1.14 | X6: =IFERROR(ROUND(ifs(W6="","",W6<=1,5,W6<=1.5,4+(1.5-W6)/0.5,W6<=2,3+(2-W6)/0.5,W6<=5,2+(5-W6)/3,W6<=8,1+(8-W6)/3,TRUE(),0),1),"") -> 4.7 | Y6: =IF(X6="","",X6*X$9) -> 0.3055 | Z6: ='Period Tables'!E22 -> 4.3 | AA6: =IF(OR(NOT(ISNUMBER(Z6)),Z6=0),"",IFERROR(ROUND(ifs(Z6>=4.7,5,Z6>=4.5,4+(Z6-4.5)/0.2,Z6>=4.3,3+(Z6-4.3)/0.2,Z6>=4,2+(Z6-4)/0.3,Z6>=3.8,1+(Z6-3.8)/0.2,TRUE(),0),1),"")) -> 3 | AB6: =IF(AA6="","",AA6*AA$9) -> 0.195 | AC6: 78 | AD6: =IFERROR(ROUND(ifs(AC6="","",AC6>=94,5,AC6>=89,4+(AC6-89)/5,AC6>=83,3+(AC6-83)/6,AC6>=75,2+(AC6-75)/8,AC6>=70,1+(AC6-70)/5,TRUE(),0),1),"") -> 2.4 | AE6: =IF(AD6="","",AD6*AD$9) -> 0.252 | AF6: 75 | AG6: =IFERROR(ROUND(ifs(AF6="","",AF6>=94,5,AF6>=89,4+(AF6-89)/5,AF6>=83,3+(AF6-83)/6,AF6>=75,2+(AF6-75)/8,AF6>=70,1+(AF6-70)/5,TRUE(),0),1),"") -> 2 | AH6: =IF(AG6="","",AG6*AG$9) -> 0.11 | AI6: 0.8 | AJ6: =SUM(D6,G6,J6,M6,P6,S6,V6,Y6,AB6,AE6,AH6) -> 3.0625
A7: Rockville | B7: =100%+'Period Tables'!I7 -> 0.87077313 | C7: =IFERROR(ROUND(ifs(B7="","",B7>=1.05,5,B7>=1.02,4+(B7-1.02)/0.03,B7>=0.99,3+(B7-0.99)/0.03,B7>=0.95,2+(B7-0.95)/0.04,B7>=0.9,1+(B7-0.9)/0.05,TRUE(),0),1),"") -> 0 | D7: =IF(C7="","",C7*C$9) -> 0 | E7: =100%+'Period Tables'!F7 -> 1.0890977 | F7: =IFERROR(ROUND(ifs(E7="","",E7>=1.15,5,E7>=1.075,4+(E7-1.075)/0.075,E7>=1.05,3+(E7-1.05)/0.025,E7>=1,2+(E7-1)/0.05,E7>=0.95,1+(E7-0.95)/0.05,TRUE(),0),1),"") -> 4.2 | G7: =IF(F7="","",F7*F$9) -> 0.168 | H7: =100%+'Period Tables'!V7 -> #DIV/0! | I7: =IFERROR(ROUND(ifs(H7="","",H7>=1.05,5,H7>=1.01,4+(H7-1.01)/0.04,H7>=0.95,3+(H7-0.95)/0.06,H7>=0.85,2+(H7-0.85)/0.1,H7>=0.75,1+(H7-0.75)/0.1,TRUE(),0),1),"") | J7: =IF(I7="","",I7*I$9) | K7: ='Period Tables'!L7*100 -> -0.7 | L7: =IFERROR(ROUND(IFS(K7="","",K7>=3,0,K7>=2,1+(3-K7)/1,K7>=1,2+(2-K7)/1,K7>0,3+(1-K7)/1,K7>=-1,4+(0-K7)/1,TRUE,5),1),"") -> 4.7 | M7: =IF(L7="","",L7*L$9) -> 0.4935 | N7: ='Period Tables'!O7*100 -> 3.3 | O7: =IFERROR(ROUND(IFS(N7="","",N7>=3,0,N7>=2,1+(3-N7)/1,N7>=1,2+(2-N7)/1,N7>0,3+(1-N7)/1,N7>=-1,4+(0-N7)/1,TRUE,5),1),"") -> 0 | P7: =IF(O7="","",O7*O$9) -> 0 | Q7: ='Period Tables'!E16 -> 4.47 | R7: =IF(OR(NOT(ISNUMBER(Q7)),Q7=0),"",IFERROR(ROUND(ifs(Q7>=4.7,5,Q7>=4.5,4+(Q7-4.5)/0.2,Q7>=4.3,3+(Q7-4.3)/0.2,Q7>=4,2+(Q7-4)/0.3,Q7>=3.8,1+(Q7-3.8)/0.2,TRUE(),0),1),"")) -> 3.9 | S7: =IF(R7="","",R7*R$9) -> 0.819 | T7: ='Period Tables'!I24 -> 0.045 | U7: =IFERROR(ROUND(ifs(T7="","",T7<=0.01,5,T7<=0.015,4+(0.015-T7)/0.005,T7<=0.02,3+(0.02-T7)/0.005,T7<=0.04,2+(0.04-T7)/0.02,T7<=0.06,1+(0.06-T7)/0.02,TRUE(),0),1),"") -> 1.8 | V7: =IF(U7="","",U7*U$9) -> 0.153 | W7: ='Period Tables'!H30 -> 2.03 | X7: =IFERROR(ROUND(ifs(W7="","",W7<=1,5,W7<=1.5,4+(1.5-W7)/0.5,W7<=2,3+(2-W7)/0.5,W7<=5,2+(5-W7)/3,W7<=8,1+(8-W7)/3,TRUE(),0),1),"") -> 3 | Y7: =IF(X7="","",X7*X$9) -> 0.195 | Z7: ='Period Tables'!E24 -> 4.3 | AA7: =IF(OR(NOT(ISNUMBER(Z7)),Z7=0),"",IFERROR(ROUND(ifs(Z7>=4.7,5,Z7>=4.5,4+(Z7-4.5)/0.2,Z7>=4.3,3+(Z7-4.3)/0.2,Z7>=4,2+(Z7-4)/0.3,Z7>=3.8,1+(Z7-3.8)/0.2,TRUE(),0),1),"")) -> 3 | AB7: =IF(AA7="","",AA7*AA$9) -> 0.195 | AC7: 77 | AD7: =IFERROR(ROUND(ifs(AC7="","",AC7>=94,5,AC7>=89,4+(AC7-89)/5,AC7>=83,3+(AC7-83)/6,AC7>=75,2+(AC7-75)/8,AC7>=70,1+(AC7-70)/5,TRUE(),0),1),"") -> 2.3 | AE7: =IF(AD7="","",AD7*AD$9) -> 0.2415 | AF7: 74 | AG7: =IFERROR(ROUND(ifs(AF7="","",AF7>=94,5,AF7>=89,4+(AF7-89)/5,AF7>=83,3+(AF7-83)/6,AF7>=75,2+(AF7-75)/8,AF7>=70,1+(AF7-70)/5,TRUE(),0),1),"") -> 1.8 | AH7: =IF(AG7="","",AG7*AG$9) -> 0.099 | AI7: 0.78 | AJ7: =SUM(D7,G7,J7,M7,P7,S7,V7,Y7,AB7,AE7,AH7) -> 2.364
A8: All Stores | B8: =100%+'Period Tables'!I8 -> 0.85242532 | C8: =IFERROR(ROUND(ifs(B8="","",B8>=1.05,5,B8>=1.02,4+(B8-1.02)/0.03,B8>=0.99,3+(B8-0.99)/0.03,B8>=0.95,2+(B8-0.95)/0.04,B8>=0.9,1+(B8-0.9)/0.05,TRUE(),0),1),"") -> 0 | D8: =IF(C8="","",C8*C$9) -> 0 | E8: =100%+'Period Tables'!F8 -> 1.0642439 | F8: =IFERROR(ROUND(ifs(E8="","",E8>=1.15,5,E8>=1.075,4+(E8-1.075)/0.075,E8>=1.05,3+(E8-1.05)/0.025,E8>=1,2+(E8-1)/0.05,E8>=0.95,1+(E8-0.95)/0.05,TRUE(),0),1),"") -> 3.6 | G8: =IF(F8="","",F8*F$9) -> 0.144 | H8: =100%+'Period Tables'!V8 -> #DIV/0! | I8: =IFERROR(ROUND(ifs(H8="","",H8>=1.05,5,H8>=1.01,4+(H8-1.01)/0.04,H8>=0.95,3+(H8-0.95)/0.06,H8>=0.85,2+(H8-0.85)/0.1,H8>=0.75,1+(H8-0.75)/0.1,TRUE(),0),1),"") | J8: =IF(I8="","",I8*I$9) | K8: ='Period Tables'!L8*100 -> -1.9 | L8: =IFERROR(ROUND(IFS(K8="","",K8>=3,0,K8>=2,1+(3-K8)/1,K8>=1,2+(2-K8)/1,K8>0,3+(1-K8)/1,K8>=-1,4+(0-K8)/1,TRUE,5),1),"") -> 5 | M8: =IF(L8="","",L8*L$9) -> 0.525 | N8: ='Period Tables'!O8*100 -> -0.1 | O8: =IFERROR(ROUND(IFS(N8="","",N8>=3,0,N8>=2,1+(3-N8)/1,N8>=1,2+(2-N8)/1,N8>0,3+(1-N8)/1,N8>=-1,4+(0-N8)/1,TRUE,5),1),"") -> 4.1 | P8: =IF(O8="","",O8*O$9) -> 0.4305 | Q8: ='Period Tables'!E17 -> 4.294 | R8: =IF(OR(NOT(ISNUMBER(Q8)),Q8=0),"",IFERROR(ROUND(ifs(Q8>=4.7,5,Q8>=4.5,4+(Q8-4.5)/0.2,Q8>=4.3,3+(Q8-4.3)/0.2,Q8>=4,2+(Q8-4)/0.3,Q8>=3.8,1+(Q8-3.8)/0.2,TRUE(),0),1),"")) -> 3 | S8: =IF(R8="","",R8*R$9) -> 0.63 | T8: ='Period Tables'!I25 -> 0.03498 | U8: =IFERROR(ROUND(ifs(T8="","",T8<=0.01,5,T8<=0.015,4+(0.015-T8)/0.005,T8<=0.02,3+(0.02-T8)/0.005,T8<=0.04,2+(0.04-T8)/0.02,T8<=0.06,1+(0.06-T8)/0.02,TRUE(),0),1),"") -> 2.3 | V8: =IF(U8="","",U8*U$9) -> 0.1955 | W8: ='Period Tables'!H35 -> 1.19 | X8: =IFERROR(ROUND(ifs(W8="","",W8<=1,5,W8<=1.5,4+(1.5-W8)/0.5,W8<=2,3+(2-W8)/0.5,W8<=5,2+(5-W8)/3,W8<=8,1+(8-W8)/3,TRUE(),0),1),"") -> 4.6 | Y8: =IF(X8="","",X8*X$9) -> 0.299 | Z8: ='Period Tables'!E25 -> 4.3 | AA8: =IF(OR(NOT(ISNUMBER(Z8)),Z8=0),"",IFERROR(ROUND(ifs(Z8>=4.7,5,Z8>=4.5,4+(Z8-4.5)/0.2,Z8>=4.3,3+(Z8-4.3)/0.2,Z8>=4,2+(Z8-4)/0.3,Z8>=3.8,1+(Z8-3.8)/0.2,TRUE(),0),1),"")) -> 3 | AB8: =IF(AA8="","",AA8*AA$9) -> 0.195 | AC8: =AVERAGE(AC3:AC7) -> 85.2 | AD8: =IFERROR(ROUND(ifs(AC8="","",AC8>=94,5,AC8>=89,4+(AC8-89)/5,AC8>=83,3+(AC8-83)/6,AC8>=75,2+(AC8-75)/8,AC8>=70,1+(AC8-70)/5,TRUE(),0),1),"") -> 3.4 | AE8: =IF(AD8="","",AD8*AD$9) -> 0.357 | AF8: =AVERAGE(AF3:AF7) -> 83.6 | AG8: =IFERROR(ROUND(ifs(AF8="","",AF8>=94,5,AF8>=89,4+(AF8-89)/5,AF8>=83,3+(AF8-83)/6,AF8>=75,2+(AF8-75)/8,AF8>=70,1+(AF8-70)/5,TRUE(),0),1),"") -> 3.1 | AH8: =IF(AG8="","",AG8*AG$9) -> 0.1705 | AI8: =AVERAGE(AI3:AI7) -> 0.846 | AJ8: =SUM(D8,G8,J8,M8,P8,S8,V8,Y8,AB8,AE8,AH8) -> 2.9465
A9: Weight | C9: ='Scoring Matrix'!C42 -> 0.04 | F9: ='Scoring Matrix'!C44 -> 0.04 | I9: ='Scoring Matrix'!C46 -> 0.125 | L9: ='Scoring Matrix'!C48 -> 0.105 | O9: ='Scoring Matrix'!C50 -> 0.105 | R9: ='Scoring Matrix'!C52 -> 0.21 | U9: ='Scoring Matrix'!C54 -> 0.085 | X9: ='Scoring Matrix'!C56 -> 0.065 | AA9: ='Scoring Matrix'!C58 -> 0.065 | AD9: ='Scoring Matrix'!C60 -> 0.105 | AG9: ='Scoring Matrix'!C62 -> 0.055

Sheet Period Store Scorecards
A1: Restaurant | B1: Sales vs Budget (%) | C1: Score | D1: Weighted | E1: Sales vs Prior Year (%) | F1: Score | G1: Weighted | H1: EBITDA vs Budget (%) | I1: Score | J1: Weighted | K1: Labor Var (pts) | L1: Score | M1: Weighted | N1: COGS Var (pts) | O1: Score | P1: Weighted | Q1: Google Rating | R1: Score | S1: Weighted | T1: Yelp Rating | U1: Score | V1: Weighted | W1: 3P Error Rate (%) | X1: Score | Y1: Weighted | Z1: Avoidable Wait (mins) | AA1: Score | AB1: Weighted | AC1: 3P Rating | AD1: Score | AE1: Weighted | AF1: Full Audit Score | AG1: Score | AH1: Weighted | AI1: Culinary Audit Score | AJ1: Score | AK1: Weighted | AL1: Focus Audit Score | AM1: Score | AN1: Weighted | AO1: Training % (Gate) | AP1: Composite Score (0-5)
A2: Ballpark | B2: =100%+'Period Tables'!I3 -> 0.0005532557 | C2: =IFS(B2="", "", B2<90%,0, B2<95%,1, B2<=98%,2, B2<=101%,3, B2<=105%,4, TRUE,5) -> 0 | D2: =IF(C2="","",C2*5/100) -> 0 | E2: =100%+'Period Tables'!F3 -> 0.00070625625 | F2: =IFS(E2="", "", E2<90%,0, E2<95%,1, E2<=98%,2, E2<=101%,3, E2<=105%,4, TRUE,5) -> 0 | G2: =IF(F2="","",F2*5/100) -> 0 | H2: =100%+'Period Tables'!V3 -> #DIV/0! | I2: =IFS(H2="", "", H2<75%,0, H2<85%,1, H2<95%,2, H2<=100%,3, H2<=105%,4, TRUE,5) -> #DIV/0! | J2: =IF(I2="","",I2*15/100) -> #DIV/0! | K2: ='Period Tables'!L3*100 -> -30.8 | L2: =IFS(K2="", "", K2>=3,0, K2>=2,1, K2>=1,2, K2>=0,3, K2<=-1,5, K2<=-0.5,4, TRUE,3) -> 5 | M2: =IF(L2="","",L2*12.5/100) -> 0.625 | N2: ='Period Tables'!O3*100 -> -26.4 | O2: =IFS(N2="", "", N2>=3,0, N2>=2,1, N2>=1,2, N2>=0,3, N2<=-1,5, N2<=-0.5,4, TRUE,3) -> 5 | P2: =IF(O2="","",O2*12.5/100) -> 0.625 | Q2: ='Period Tables'!H12 -> 5 | R2: =IFS(Q2="", "", Q2="NA","" ,Q2<3.8,0, Q2<4,1, Q2<4.3,2, Q2<4.5,3, Q2<4.7,4, TRUE,5) -> 5 | S2: =IF(R2="","",R2*17.5/100) -> 0.875 | T2: ='Period Tables'!F12 -> NA | U2: =IFS(T2="", "", T2="NA","" ,T2<3.8,0, T2<4,1, T2<4.3,2, T2<4.5,3, T2<4.7,4, TRUE,5) | V2: =IF(U2="","",U2*7.5/100) | W2: ='Period Tables'!I20 -> 0.0405 | X2: =IFS(W2="", "", W2>6%,0, W2>4%,1, W2>2%,2, W2>1.5%,3, W2>1%,4, TRUE,5) -> 1 | Y2: =IF(X2="","",X2*10/100) -> 0.1 | Z2: ='Period Tables'!H31 -> 0.57 | AA2: =IFS(Z2="","", VALUE(Z2)>8,0, VALUE(Z2)>5,1, VALUE(Z2)>2,2, VALUE(Z2)>1.5,3, VALUE(Z2)>1,4, TRUE,5) -> 5 | AB2: =IF(AA2="","",AA2*7.5/100) -> 0.375 | AC2: ='Period Tables'!E20 -> 4 | AD2: =IFS(AC2="", "", AC2<3.8,0, AC2<4,1, AC2<4.3,2, AC2<4.5,3, AC2<4.7,4, TRUE,5) -> 2 | AE2: =IF(AD2="","",AD2*7.5/100) -> 0.15 | AF2: 86 | AG2: =IFS(AF2="", "", AF2<70,0, AF2<75,1, AF2<83,2, AF2<89,3, AF2<94,4, TRUE,5) -> 3 | AH2: =IF(AG2="","",AG2*12.5/100) -> 0.375 | AI2: 90 | AJ2: =IFS(AI2="", "", AI2<70,0, AI2<75,1, AI2<83,2, AI2<89,3, AI2<94,4, TRUE,5) -> 4 | AK2: =IF(AJ2="","",AJ2*6.25/100) -> 0.25 | AL2: 95 | AM2: =IFS(AL2="", "", AL2<70,0, AL2<75,1, AL2<83,2, AL2<89,3, AL2<94,4, TRUE,5) -> 5 | AN2: =IF(AM2="","",AM2*6.25/100) -> 0.3125 | AO2: 85 | AP2: =SUM(D2,G2,J2,M2,P2,S2,V2,Y2,AB2,AE2,AH2,AK2,AN2) -> #DIV/0!
A3: Mosaic | B3: =100%+'Period Tables'!I4 -> 0.94670671 | C3: =IFS(B3="", "", B3<90%,0, B3<95%,1, B3<=98%,2, B3<=101%,3, B3<=105%,4, TRUE,5) -> 1 | D3: =IF(C3="","",C3*5/100) -> 0.05 | E3: =100%+'Period Tables'!F4 -> 1.0965152 | F3: =IFS(E3="", "", E3<90%,0, E3<95%,1, E3<=98%,2, E3<=101%,3, E3<=105%,4, TRUE,5) -> 5 | G3: =IF(F3="","",F3*5/100) -> 0.25 | H3: =100%+'Period Tables'!V4 -> #DIV/0! | I3: =IFS(H3="", "", H3<75%,0, H3<85%,1, H3<95%,2, H3<=100%,3, H3<=105%,4, TRUE,5) -> #DIV/0! | J3: =IF(I3="","",I3*15/100) -> #DIV/0! | K3: ='Period Tables'!L4*100 -> -2.7 | L3: =IFS(K3="", "", K3>=3,0, K3>=2,1, K3>=1,2, K3>=0,3, K3<=-1,5, K3<=-0.5,4, TRUE,3) -> 5 | M3: =IF(L3="","",L3*12.5/100) -> 0.625 | N3: ='Period Tables'!O4*100 -> -3.4 | O3: =IFS(N3="", "", N3>=3,0, N3>=2,1, N3>=1,2, N3>=0,3, N3<=-1,5, N3<=-0.5,4, TRUE,3) -> 5 | P3: =IF(O3="","",O3*12.5/100) -> 0.625 | Q3: ='Period Tables'!H15 -> 4.75 | R3: =IFS(Q3="", "", Q3="NA","" ,Q3<3.8,0, Q3<4,1, Q3<4.3,2, Q3<4.5,3, Q3<4.7,4, TRUE,5) -> 5 | S3: =IF(R3="","",R3*17.5/100) -> 0.875 | T3: ='Period Tables'!F15 -> 4 | U3: =IFS(T3="", "", T3="NA","" ,T3<3.8,0, T3<4,1, T3<4.3,2, T3<4.5,3, T3<4.7,4, TRUE,5) -> 2 | V3: =IF(U3="","",U3*7.5/100) -> 0.15 | W3: ='Period Tables'!I23 -> 0.0315 | X3: =IFS(W3="", "", W3>6%,0, W3>4%,1, W3>2%,2, W3>1.5%,3, W3>1%,4, TRUE,5) -> 2 | Y3: =IF(X3="","",X3*10/100) -> 0.2 | Z3: ='Period Tables'!H34 -> 1.48 | AA3: =IFS(Z3="","", VALUE(Z3)>8,0, VALUE(Z3)>5,1, VALUE(Z3)>2,2, VALUE(Z3)>1.5,3, VALUE(Z3)>1,4, TRUE,5) -> 4 | AB3: =IF(AA3="","",AA3*7.5/100) -> 0.3 | AC3: ='Period Tables'!E23 -> 4.4 | AD3: =IFS(AC3="", "", AC3<3.8,0, AC3<4,1, AC3<4.3,2, AC3<4.5,3, AC3<4.7,4, TRUE,5) -> 3 | AE3: =IF(AD3="","",AD3*7.5/100) -> 0.225 | AF3: 67 | AG3: =IFS(AF3="", "", AF3<70,0, AF3<75,1, AF3<83,2, AF3<89,3, AF3<94,4, TRUE,5) -> 0 | AH3: =IF(AG3="","",AG3*12.5/100) -> 0 | AI3: 70 | AJ3: =IFS(AI3="", "", AI3<70,0, AI3<75,1, AI3<83,2, AI3<89,3, AI3<94,4, TRUE,5) -> 1 | AK3: =IF(AJ3="","",AJ3*6.25/100) -> 0.0625 | AL3: 76 | AM3: =IFS(AL3="", "", AL3<70,0, AL3<75,1, AL3<83,2, AL3<89,3, AL3<94,4, TRUE,5) -> 2 | AN3: =IF(AM3="","",AM3*6.25/100) -> 0.125 | AO3: 87 | AP3: =SUM(D3,G3,J3,M3,P3,S3,V3,Y3,AB3,AE3,AH3,AK3,AN3) -> #DIV/0!
A4: MVT | B4: =100%+'Period Tables'!I5 -> 1.0190662 | C4: =IFS(B4="", "", B4<90%,0, B4<95%,1, B4<=98%,2, B4<=101%,3, B4<=105%,4, TRUE,5) -> 4 | D4: =IF(C4="","",C4*5/100) -> 0.2 | E4: =100%+'Period Tables'!F5 -> 1.3761061 | F4: =IFS(E4="", "", E4<90%,0, E4<95%,1, E4<=98%,2, E4<=101%,3, E4<=105%,4, TRUE,5) -> 5 | G4: =IF(F4="","",F4*5/100) -> 0.25 | H4: =100%+'Period Tables'!V5 -> #DIV/0! | I4: =IFS(H4="", "", H4<75%,0, H4<85%,1, H4<95%,2, H4<=100%,3, H4<=105%,4, TRUE,5) -> #DIV/0! | J4: =IF(I4="","",I4*15/100) -> #DIV/0! | K4: ='Period Tables'!L5*100 -> 2.4 | L4: =IFS(K4="", "", K4>=3,0, K4>=2,1, K4>=1,2, K4>=0,3, K4<=-1,5, K4<=-0.5,4, TRUE,3) -> 1 | M4: =IF(L4="","",L4*12.5/100) -> 0.125 | N4: ='Period Tables'!O5*100 -> 1.1 | O4: =IFS(N4="", "", N4>=3,0, N4>=2,1, N4>=1,2, N4>=0,3, N4<=-1,5, N4<=-0.5,4, TRUE,3) -> 2 | P4: =IF(O4="","",O4*12.5/100) -> 0.25 | Q4: ='Period Tables'!H13 -> 3.67 | R4: =IFS(Q4="", "", Q4="NA","" ,Q4<3.8,0, Q4<4,1, Q4<4.3,2, Q4<4.5,3, Q4<4.7,4, TRUE,5) -> 0 | S4: =IF(R4="","",R4*17.5/100) -> 0 | T4: ='Period Tables'!F13 -> 1 | U4: =IFS(T4="", "", T4="NA","" ,T4<3.8,0, T4<4,1, T4<4.3,2, T4<4.5,3, T4<4.7,4, TRUE,5) -> 0 | V4: =IF(U4="","",U4*7.5/100) -> 0 | W4: ='Period Tables'!I21 -> 0.0264 | X4: =IFS(W4="", "", W4>6%,0, W4>4%,1, W4>2%,2, W4>1.5%,3, W4>1%,4, TRUE,5) -> 2 | Y4: =IF(X4="","",X4*10/100) -> 0.2 | Z4: ='Period Tables'!H32 -> 0.59 | AA4: =IFS(Z4="","", VALUE(Z4)>8,0, VALUE(Z4)>5,1, VALUE(Z4)>2,2, VALUE(Z4)>1.5,3, VALUE(Z4)>1,4, TRUE,5) -> 5 | AB4: =IF(AA4="","",AA4*7.5/100) -> 0.375 | AC4: ='Period Tables'!E21 -> 4.5 | AD4: =IFS(AC4="", "", AC4<3.8,0, AC4<4,1, AC4<4.3,2, AC4<4.5,3, AC4<4.7,4, TRUE,5) -> 4 | AE4: =IF(AD4="","",AD4*7.5/100) -> 0.3 | AF4: 72 | AG4: =IFS(AF4="", "", AF4<70,0, AF4<75,1, AF4<83,2, AF4<89,3, AF4<94,4, TRUE,5) -> 1 | AH4: =IF(AG4="","",AG4*12.5/100) -> 0.125 | AI4: 76 | AJ4: =IFS(AI4="", "", AI4<70,0, AI4<75,1, AI4<83,2, AI4<89,3, AI4<94,4, TRUE,5) -> 2 | AK4: =IF(AJ4="","",AJ4*6.25/100) -> 0.125 | AL4: 78 | AM4: =IFS(AL4="", "", AL4<70,0, AL4<75,1, AL4<83,2, AL4<89,3, AL4<94,4, TRUE,5) -> 2 | AN4: =IF(AM4="","",AM4*6.25/100) -> 0.125 | AO4: 93 | AP4: =SUM(D4,G4,J4,M4,P4,S4,V4,Y4,AB4,AE4,AH4,AK4,AN4) -> #DIV/0!
