Workbook

Sheet Sheet1

Sheet Sheet1 (1)

Sheet Summary
C1: =B2 -> Week Ending 01/25/2026 | D1: =C1 -> Week Ending 01/25/2026 | E1: =+D1 -> Week Ending 01/25/2026 | F1: =+E1 -> Week Ending 01/25/2026 | G1: Period To Date | H1: Period To Date | I1: Period To Date | J1: Period To Date | K1: Trailing 4 week | L1: Trailing 4 week | M1: Trailing 4 week | N1: Trailing 4 week | R1: Trailing 8 week | S1: Trailing 8 week | T1: Trailing 8 week | U1: Trailing 8 week
B2: Week Ending 01/25/2026 | G2: Current Period | K2: 4-Week Average | O2: 4-Week Average Comparison | R2: 8-Week Average | V2: 8-Week Average Comparison
B3: Location | C3: Sales | D3: COGS | E3: Labor | F3: Prime Margin | G3: Sales | H3: COGS | I3: Total Labor Cost | J3: Prime Margin | K3: Sales | L3: COGS | M3: Total Labor Cost | N3: Prime Margin | O3: Sales Current Week vs 4-week | P3: COGS Current Week vs 4-week | Q3: Labor Current Week vs 4-week | R3: Sales | S3: COGS | T3: Total Labor Cost | U3: Prime Margin | V3: Sales Current Week vs 8-week | W3: COGS Current Week vs 8-week | X3: Labor Current Week vs 8-week
B4: Location | C4: Total Sales | D4: Total Cost of Goods Sold | E4: Total Payroll Expenses | F4: Prime Profit | G4: Total Sales | H4: Total Cost of Goods Sold | I4: Total Payroll Expenses | J4: Prime Profit | K4: Total Sales | L4: Total Cost of Goods Sold | M4: Total Payroll Expenses | N4: Prime Profit | R4: Total Sales | S4: Total Cost of Goods Sold | T4: Total Payroll Expenses | U4: Prime Profit
A5: 2 - RASA - Ballpark | B5: =A5 -> 2 - RASA - Ballpark | C5: =INDEX(INDIRECT("'"&$A5&"'!$1:$1048576"),MATCH(C$4,INDIRECT("'"&$A5&"'!A:A"),0),MATCH(C$1,INDIRECT("'"&$A5&"'!$5:$5"),0)) -> 20034.79 | D5: {=INDEX(INDIRECT("'"&$A5&"'!$1:$1048576"),MATCH(D$4,INDIRECT("'"&$A5&"'!A:A"),0),MATCH(D$1,INDIRECT("'"&$A5&"'!$5:$5"),0)+1)} -> 0.27586613 | E5: {=INDEX(INDIRECT("'"&$A5&"'!$1:$1048576"),MATCH(E$4,INDIRECT("'"&$A5&"'!A:A"),0),MATCH(E$1,INDIRECT("'"&$A5&"'!$5:$5"),0)+1)} -> 0.30742973 | F5: {=INDEX(INDIRECT("'"&$A5&"'!$1:$1048576"),MATCH(F$4,INDIRECT("'"&$A5&"'!A:A"),0),MATCH(F$1,INDIRECT("'"&$A5&"'!$5:$5"),0)+1)} -> 0.41670414 | G5: =INDEX(INDIRECT("'"&$A5&"'!$1:$1048576"),MATCH(G$4,INDIRECT("'"&$A5&"'!A:A"),0),MATCH(G$1,INDIRECT("'"&$A5&"'!$5:$5"),0)) -> 67478.95 | H5: {=INDEX(INDIRECT("'"&$A5&"'!$1:$1048576"),MATCH(H$4,INDIRECT("'"&$A5&"'!A:A"),0),MATCH(H$1,INDIRECT("'"&$A5&"'!$5:$5"),0)+1)} -> 0.28315749 | I5: {=INDEX(INDIRECT("'"&$A5&"'!$1:$1048576"),MATCH(I$4,INDIRECT("'"&$A5&"'!A:A"),0),MATCH(I$1,INDIRECT("'"&$A5&"'!$5:$5"),0)+1)} -> 0.35384531 | J5: {=INDEX(INDIRECT("'"&$A5&"'!$1:$1048576"),MATCH(J$4,INDIRECT("'"&$A5&"'!A:A"),0),MATCH(J$1,INDIRECT("'"&$A5&"'!$5:$5"),0)+1)} -> 0.3629972 | K5: =INDEX(INDIRECT("'"&$A5&"'!$1:$1048576"),MATCH(K$4,INDIRECT("'"&$A5&"'!A:A"),0),MATCH(K$1,INDIRECT("'"&$A5&"'!$5:$5"),0)) -> 16869.737 | L5: {=INDEX(INDIRECT("'"&$A5&"'!$1:$1048576"),MATCH(L$4,INDIRECT("'"&$A5&"'!A:A"),0),MATCH(L$1,INDIRECT("'"&$A5&"'!$5:$5"),0)+1)} -> 0.28315749 | M5: {=INDEX(INDIRECT("'"&$A5&"'!$1:$1048576"),MATCH(M$4,INDIRECT("'"&$A5&"'!A:A"),0),MATCH(M$1,INDIRECT("'"&$A5&"'!$5:$5"),0)+1)} -> 0.35384531 | N5: {=INDEX(INDIRECT("'"&$A5&"'!$1:$1048576"),MATCH(N$4,INDIRECT("'"&$A5&"'!A:A"),0),MATCH(N$1,INDIRECT("'"&$A5&"'!$5:$5"),0)+1)} -> 0.3629972 | O5: =+(C5-K5)/K5 -> 0.18761718 | P5: =+D5-L5 -> -0.0072913575 | Q5: =+E5-M5 -> -0.046415584 | R5: =INDEX(INDIRECT("'"&$A5&"'!$1:$1048576"),MATCH(R$4,INDIRECT("'"&$A5&"'!A:A"),0),MATCH(R$1,INDIRECT("'"&$A5&"'!$5:$5"),0)) -> 17353.603 | S5: {=INDEX(INDIRECT("'"&$A5&"'!$1:$1048576"),MATCH(S$4,INDIRECT("'"&$A5&"'!A:A"),0),MATCH(S$1,INDIRECT("'"&$A5&"'!$5:$5"),0)+1)} -> 0.27992084 | T5: {=INDEX(INDIRECT("'"&$A5&"'!$1:$1048576"),MATCH(T$4,INDIRECT("'"&$A5&"'!A:A"),0),MATCH(T$1,INDIRECT("'"&$A5&"'!$5:$5"),0)+1)} -> 0.35029492 | U5: {=INDEX(INDIRECT("'"&$A5&"'!$1:$1048576"),MATCH(U$4,INDIRECT("'"&$A5&"'!A:A"),0),MATCH(U$1,INDIRECT("'"&$A5&"'!$5:$5"),0)+1)} -> 0.36978424 | V5: =+(C5-R5)/R5 -> 0.15450322 | W5: =+D5-S5 -> -0.0040547098 | X5: =+E5-T5 -> -0.042865191 | AK5: Week 1 | AL5: 46026 | AM5: =YEAR(AL5) -> 2026 | AN5: =AK5&", "&AM5 -> Week 1, 2026 | AO5: ="Week Ending "&TEXT(AL5,"mm/dd/yyyy") -> Week Ending 01/04/2026
A6: 4 - RASA - MVT | B6: =A6 -> 4 - RASA - MVT | C6: =INDEX(INDIRECT("'"&$A6&"'!$1:$1048576"),MATCH(C$4,INDIRECT("'"&$A6&"'!A:A"),0),MATCH(C$1,INDIRECT("'"&$A6&"'!$5:$5"),0)) -> 39699.41 | D6: {=INDEX(INDIRECT("'"&$A6&"'!$1:$1048576"),MATCH(D$4,INDIRECT("'"&$A6&"'!A:A"),0),MATCH(D$1,INDIRECT("'"&$A6&"'!$5:$5"),0)+1)} -> 0.24622608 | E6: {=INDEX(INDIRECT("'"&$A6&"'!$1:$1048576"),MATCH(E$4,INDIRECT("'"&$A6&"'!A:A"),0),MATCH(E$1,INDIRECT("'"&$A6&"'!$5:$5"),0)+1)} -> 0.26941332 | F6: {=INDEX(INDIRECT("'"&$A6&"'!$1:$1048576"),MATCH(F$4,INDIRECT("'"&$A6&"'!A:A"),0),MATCH(F$1,INDIRECT("'"&$A6&"'!$5:$5"),0)+1)} -> 0.4843606 | G6: =INDEX(INDIRECT("'"&$A6&"'!$1:$1048576"),MATCH(G$4,INDIRECT("'"&$A6&"'!A:A"),0),MATCH(G$1,INDIRECT("'"&$A6&"'!$5:$5"),0)) -> 130404.64 | H6: {=INDEX(INDIRECT("'"&$A6&"'!$1:$1048576"),MATCH(H$4,INDIRECT("'"&$A6&"'!A:A"),0),MATCH(H$1,INDIRECT("'"&$A6&"'!$5:$5"),0)+1)} -> 0.27629584 | I6: {=INDEX(INDIRECT("'"&$A6&"'!$1:$1048576"),MATCH(I$4,INDIRECT("'"&$A6&"'!A:A"),0),MATCH(I$1,INDIRECT("'"&$A6&"'!$5:$5"),0)+1)} -> 0.28441695 | J6: {=INDEX(INDIRECT("'"&$A6&"'!$1:$1048576"),MATCH(J$4,INDIRECT("'"&$A6&"'!A:A"),0),MATCH(J$1,INDIRECT("'"&$A6&"'!$5:$5"),0)+1)} -> 0.43928721 | K6: =INDEX(INDIRECT("'"&$A6&"'!$1:$1048576"),MATCH(K$4,INDIRECT("'"&$A6&"'!A:A"),0),MATCH(K$1,INDIRECT("'"&$A6&"'!$5:$5"),0)) -> 32601.16 | L6: {=INDEX(INDIRECT("'"&$A6&"'!$1:$1048576"),MATCH(L$4,INDIRECT("'"&$A6&"'!A:A"),0),MATCH(L$1,INDIRECT("'"&$A6&"'!$5:$5"),0)+1)} -> 0.27629584 | M6: {=INDEX(INDIRECT("'"&$A6&"'!$1:$1048576"),MATCH(M$4,INDIRECT("'"&$A6&"'!A:A"),0),MATCH(M$1,INDIRECT("'"&$A6&"'!$5:$5"),0)+1)} -> 0.28441695 | N6: {=INDEX(INDIRECT("'"&$A6&"'!$1:$1048576"),MATCH(N$4,INDIRECT("'"&$A6&"'!A:A"),0),MATCH(N$1,INDIRECT("'"&$A6&"'!$5:$5"),0)+1)} -> 0.43928721 | O6: =+(C6-K6)/K6 -> 0.21772998 | P6: =+D6-L6 -> -0.030069766 | Q6: =+E6-M6 -> -0.015003626 | R6: =INDEX(INDIRECT("'"&$A6&"'!$1:$1048576"),MATCH(R$4,INDIRECT("'"&$A6&"'!A:A"),0),MATCH(R$1,INDIRECT("'"&$A6&"'!$5:$5"),0)) -> 33185.844 | S6: {=INDEX(INDIRECT("'"&$A6&"'!$1:$1048576"),MATCH(S$4,INDIRECT("'"&$A6&"'!A:A"),0),MATCH(S$1,INDIRECT("'"&$A6&"'!$5:$5"),0)+1)} -> 0.27627454 | T6: {=INDEX(INDIRECT("'"&$A6&"'!$1:$1048576"),MATCH(T$4,INDIRECT("'"&$A6&"'!A:A"),0),MATCH(T$1,INDIRECT("'"&$A6&"'!$5:$5"),0)+1)} -> 0.27740209 | U6: {=INDEX(INDIRECT("'"&$A6&"'!$1:$1048576"),MATCH(U$4,INDIRECT("'"&$A6&"'!A:A"),0),MATCH(U$1,INDIRECT("'"&$A6&"'!$5:$5"),0)+1)} -> 0.44632337 | V6: =+(C6-R6)/R6 -> 0.19627544 | W6: =+D6-S6 -> -0.030048464 | X6: =+E6-T6 -> -0.0079887688 | AK6: Week 2 | AL6: 46033 | AM6: =YEAR(AL6) -> 2026 | AN6: =AK6&", "&AM6 -> Week 2, 2026 | AO6: ="Week Ending "&TEXT(AL6,"mm/dd/yyyy") -> Week Ending 01/11/2026
A7: 5 - RASA - National Landin | B7: =A7 -> 5 - RASA - National Landin | C7: =INDEX(INDIRECT("'"&$A7&"'!$1:$1048576"),MATCH(C$4,INDIRECT("'"&$A7&"'!A:A"),0),MATCH(C$1,INDIRECT("'"&$A7&"'!$5:$5"),0)) -> 16370.43 | D7: {=INDEX(INDIRECT("'"&$A7&"'!$1:$1048576"),MATCH(D$4,INDIRECT("'"&$A7&"'!A:A"),0),MATCH(D$1,INDIRECT("'"&$A7&"'!$5:$5"),0)+1)} -> 0.25379663 | E7: {=INDEX(INDIRECT("'"&$A7&"'!$1:$1048576"),MATCH(E$4,INDIRECT("'"&$A7&"'!A:A"),0),MATCH(E$1,INDIRECT("'"&$A7&"'!$5:$5"),0)+1)} -> 0.33503213 | F7: {=INDEX(INDIRECT("'"&$A7&"'!$1:$1048576"),MATCH(F$4,INDIRECT("'"&$A7&"'!A:A"),0),MATCH(F$1,INDIRECT("'"&$A7&"'!$5:$5"),0)+1)} -> 0.41117124 | G7: =INDEX(INDIRECT("'"&$A7&"'!$1:$1048576"),MATCH(G$4,INDIRECT("'"&$A7&"'!A:A"),0),MATCH(G$1,INDIRECT("'"&$A7&"'!$5:$5"),0)) -> 71792.78 | H7: {=INDEX(INDIRECT("'"&$A7&"'!$1:$1048576"),MATCH(H$4,INDIRECT("'"&$A7&"'!A:A"),0),MATCH(H$1,INDIRECT("'"&$A7&"'!$5:$5"),0)+1)} -> 0.26518321 | I7: {=INDEX(INDIRECT("'"&$A7&"'!$1:$1048576"),MATCH(I$4,INDIRECT("'"&$A7&"'!A:A"),0),MATCH(I$1,INDIRECT("'"&$A7&"'!$5:$5"),0)+1)} -> 0.30130272 | J7: {=INDEX(INDIRECT("'"&$A7&"'!$1:$1048576"),MATCH(J$4,INDIRECT("'"&$A7&"'!A:A"),0),MATCH(J$1,INDIRECT("'"&$A7&"'!$5:$5"),0)+1)} -> 0.43351407 | K7: =INDEX(INDIRECT("'"&$A7&"'!$1:$1048576"),MATCH(K$4,INDIRECT("'"&$A7&"'!A:A"),0),MATCH(K$1,INDIRECT("'"&$A7&"'!$5:$5"),0)) -> 17948.195 | L7: {=INDEX(INDIRECT("'"&$A7&"'!$1:$1048576"),MATCH(L$4,INDIRECT("'"&$A7&"'!A:A"),0),MATCH(L$1,INDIRECT("'"&$A7&"'!$5:$5"),0)+1)} -> 0.26518321 | M7: {=INDEX(INDIRECT("'"&$A7&"'!$1:$1048576"),MATCH(M$4,INDIRECT("'"&$A7&"'!A:A"),0),MATCH(M$1,INDIRECT("'"&$A7&"'!$5:$5"),0)+1)} -> 0.30130272 | N7: {=INDEX(INDIRECT("'"&$A7&"'!$1:$1048576"),MATCH(N$4,INDIRECT("'"&$A7&"'!A:A"),0),MATCH(N$1,INDIRECT("'"&$A7&"'!$5:$5"),0)+1)} -> 0.43351407 | O7: =+(C7-K7)/K7 -> -0.087906611 | P7: =+D7-L7 -> -0.01138658 | Q7: =+E7-M7 -> 0.033729407 | R7: =INDEX(INDIRECT("'"&$A7&"'!$1:$1048576"),MATCH(R$4,INDIRECT("'"&$A7&"'!A:A"),0),MATCH(R$1,INDIRECT("'"&$A7&"'!$5:$5"),0)) -> 18114.14 | S7: {=INDEX(INDIRECT("'"&$A7&"'!$1:$1048576"),MATCH(S$4,INDIRECT("'"&$A7&"'!A:A"),0),MATCH(S$1,INDIRECT("'"&$A7&"'!$5:$5"),0)+1)} -> 0.27066031 | T7: {=INDEX(INDIRECT("'"&$A7&"'!$1:$1048576"),MATCH(T$4,INDIRECT("'"&$A7&"'!A:A"),0),MATCH(T$1,INDIRECT("'"&$A7&"'!$5:$5"),0)+1)} -> 0.31367256 | U7: {=INDEX(INDIRECT("'"&$A7&"'!$1:$1048576"),MATCH(U$4,INDIRECT("'"&$A7&"'!A:A"),0),MATCH(U$1,INDIRECT("'"&$A7&"'!$5:$5"),0)+1)} -> 0.41566713 | V7: =+(C7-R7)/R7 -> -0.096262367 | W7: =+D7-S7 -> -0.016863678 | X7: =+E7-T7 -> 0.021359563 | AK7: Week 3 | AL7: 46040 | AM7: =YEAR(AL7) -> 2026 | AN7: =AK7&", "&AM7 -> Week 3, 2026 | AO7: ="Week Ending "&TEXT(AL7,"mm/dd/yyyy") -> Week Ending 01/18/2026
A8: 6 - RASA - Mosaic | B8: =A8 -> 6 - RASA - Mosaic | C8: =INDEX(INDIRECT("'"&$A8&"'!$1:$1048576"),MATCH(C$4,INDIRECT("'"&$A8&"'!A:A"),0),MATCH(C$1,INDIRECT("'"&$A8&"'!$5:$5"),0)) -> 17376.74 | D8: {=INDEX(INDIRECT("'"&$A8&"'!$1:$1048576"),MATCH(D$4,INDIRECT("'"&$A8&"'!A:A"),0),MATCH(D$1,INDIRECT("'"&$A8&"'!$5:$5"),0)+1)} -> 0.27953402 | E8: {=INDEX(INDIRECT("'"&$A8&"'!$1:$1048576"),MATCH(E$4,INDIRECT("'"&$A8&"'!A:A"),0),MATCH(E$1,INDIRECT("'"&$A8&"'!$5:$5"),0)+1)} -> 0.30349191 | F8: {=INDEX(INDIRECT("'"&$A8&"'!$1:$1048576"),MATCH(F$4,INDIRECT("'"&$A8&"'!A:A"),0),MATCH(F$1,INDIRECT("'"&$A8&"'!$5:$5"),0)+1)} -> 0.41697407 | G8: =INDEX(INDIRECT("'"&$A8&"'!$1:$1048576"),MATCH(G$4,INDIRECT("'"&$A8&"'!A:A"),0),MATCH(G$1,INDIRECT("'"&$A8&"'!$5:$5"),0)) -> 72028.36 | H8: {=INDEX(INDIRECT("'"&$A8&"'!$1:$1048576"),MATCH(H$4,INDIRECT("'"&$A8&"'!A:A"),0),MATCH(H$1,INDIRECT("'"&$A8&"'!$5:$5"),0)+1)} -> 0.28608995 | I8: {=INDEX(INDIRECT("'"&$A8&"'!$1:$1048576"),MATCH(I$4,INDIRECT("'"&$A8&"'!A:A"),0),MATCH(I$1,INDIRECT("'"&$A8&"'!$5:$5"),0)+1)} -> 0.33807878 | J8: {=INDEX(INDIRECT("'"&$A8&"'!$1:$1048576"),MATCH(J$4,INDIRECT("'"&$A8&"'!A:A"),0),MATCH(J$1,INDIRECT("'"&$A8&"'!$5:$5"),0)+1)} -> 0.37583127 | K8: =INDEX(INDIRECT("'"&$A8&"'!$1:$1048576"),MATCH(K$4,INDIRECT("'"&$A8&"'!A:A"),0),MATCH(K$1,INDIRECT("'"&$A8&"'!$5:$5"),0)) -> 18007.09 | L8: {=INDEX(INDIRECT("'"&$A8&"'!$1:$1048576"),MATCH(L$4,INDIRECT("'"&$A8&"'!A:A"),0),MATCH(L$1,INDIRECT("'"&$A8&"'!$5:$5"),0)+1)} -> 0.28608995 | M8: {=INDEX(INDIRECT("'"&$A8&"'!$1:$1048576"),MATCH(M$4,INDIRECT("'"&$A8&"'!A:A"),0),MATCH(M$1,INDIRECT("'"&$A8&"'!$5:$5"),0)+1)} -> 0.33807878 | N8: {=INDEX(INDIRECT("'"&$A8&"'!$1:$1048576"),MATCH(N$4,INDIRECT("'"&$A8&"'!A:A"),0),MATCH(N$1,INDIRECT("'"&$A8&"'!$5:$5"),0)+1)} -> 0.37583127 | O8: =+(C8-K8)/K8 -> -0.035005656 | P8: =+D8-L8 -> -0.0065559305 | Q8: =+E8-M8 -> -0.03458687 | R8: =INDEX(INDIRECT("'"&$A8&"'!$1:$1048576"),MATCH(R$4,INDIRECT("'"&$A8&"'!A:A"),0),MATCH(R$1,INDIRECT("'"&$A8&"'!$5:$5"),0)) -> 20085.236 | S8: {=INDEX(INDIRECT("'"&$A8&"'!$1:$1048576"),MATCH(S$4,INDIRECT("'"&$A8&"'!A:A"),0),MATCH(S$1,INDIRECT("'"&$A8&"'!$5:$5"),0)+1)} -> 0.28645002 | T8: {=INDEX(INDIRECT("'"&$A8&"'!$1:$1048576"),MATCH(T$4,INDIRECT("'"&$A8&"'!A:A"),0),MATCH(T$1,INDIRECT("'"&$A8&"'!$5:$5"),0)+1)} -> 0.33482317 | U8: {=INDEX(INDIRECT("'"&$A8&"'!$1:$1048576"),MATCH(U$4,INDIRECT("'"&$A8&"'!A:A"),0),MATCH(U$1,INDIRECT("'"&$A8&"'!$5:$5"),0)+1)} -> 0.37872681 | V8: =+(C8-R8)/R8 -> -0.13485011 | W8: =+D8-S8 -> -0.0069159955 | X8: =+E8-T8 -> -0.031331262 | AK8: Week 4 | AL8: 46047 | AM8: =YEAR(AL8) -> 2026 | AN8: =AK8&", "&AM8 -> Week 4, 2026 | AO8: ="Week Ending "&TEXT(AL8,"mm/dd/yyyy") -> Week Ending 01/25/2026
A9: 7 - RASA - Rockville | B9: =A9 -> 7 - RASA - Rockville | C9: =INDEX(INDIRECT("'"&$A9&"'!$1:$1048576"),MATCH(C$4,INDIRECT("'"&$A9&"'!A:A"),0),MATCH(C$1,INDIRECT("'"&$A9&"'!$5:$5"),0)) -> 22461.46 | D9: {=INDEX(INDIRECT("'"&$A9&"'!$1:$1048576"),MATCH(D$4,INDIRECT("'"&$A9&"'!A:A"),0),MATCH(D$1,INDIRECT("'"&$A9&"'!$5:$5"),0)+1)} -> 0.31231496 | E9: {=INDEX(INDIRECT("'"&$A9&"'!$1:$1048576"),MATCH(E$4,INDIRECT("'"&$A9&"'!A:A"),0),MATCH(E$1,INDIRECT("'"&$A9&"'!$5:$5"),0)+1)} -> 0.30120437 | F9: {=INDEX(INDIRECT("'"&$A9&"'!$1:$1048576"),MATCH(F$4,INDIRECT("'"&$A9&"'!A:A"),0),MATCH(F$1,INDIRECT("'"&$A9&"'!$5:$5"),0)+1)} -> 0.38648067 | G9: =INDEX(INDIRECT("'"&$A9&"'!$1:$1048576"),MATCH(G$4,INDIRECT("'"&$A9&"'!A:A"),0),MATCH(G$1,INDIRECT("'"&$A9&"'!$5:$5"),0)) -> 89282.66 | H9: {=INDEX(INDIRECT("'"&$A9&"'!$1:$1048576"),MATCH(H$4,INDIRECT("'"&$A9&"'!A:A"),0),MATCH(H$1,INDIRECT("'"&$A9&"'!$5:$5"),0)+1)} -> 0.30209237 | I9: {=INDEX(INDIRECT("'"&$A9&"'!$1:$1048576"),MATCH(I$4,INDIRECT("'"&$A9&"'!A:A"),0),MATCH(I$1,INDIRECT("'"&$A9&"'!$5:$5"),0)+1)} -> 0.3205282 | J9: {=INDEX(INDIRECT("'"&$A9&"'!$1:$1048576"),MATCH(J$4,INDIRECT("'"&$A9&"'!A:A"),0),MATCH(J$1,INDIRECT("'"&$A9&"'!$5:$5"),0)+1)} -> 0.37737944 | K9: =INDEX(INDIRECT("'"&$A9&"'!$1:$1048576"),MATCH(K$4,INDIRECT("'"&$A9&"'!A:A"),0),MATCH(K$1,INDIRECT("'"&$A9&"'!$5:$5"),0)) -> 22320.665 | L9: {=INDEX(INDIRECT("'"&$A9&"'!$1:$1048576"),MATCH(L$4,INDIRECT("'"&$A9&"'!A:A"),0),MATCH(L$1,INDIRECT("'"&$A9&"'!$5:$5"),0)+1)} -> 0.30209237 | M9: {=INDEX(INDIRECT("'"&$A9&"'!$1:$1048576"),MATCH(M$4,INDIRECT("'"&$A9&"'!A:A"),0),MATCH(M$1,INDIRECT("'"&$A9&"'!$5:$5"),0)+1)} -> 0.3205282 | N9: {=INDEX(INDIRECT("'"&$A9&"'!$1:$1048576"),MATCH(N$4,INDIRECT("'"&$A9&"'!A:A"),0),MATCH(N$1,INDIRECT("'"&$A9&"'!$5:$5"),0)+1)} -> 0.37737944 | O9: =+(C9-K9)/K9 -> 0.0063078318 | P9: =+D9-L9 -> 0.010222595 | Q9: =+E9-M9 -> -0.019323823 | R9: =INDEX(INDIRECT("'"&$A9&"'!$1:$1048576"),MATCH(R$4,INDIRECT("'"&$A9&"'!A:A"),0),MATCH(R$1,INDIRECT("'"&$A9&"'!$5:$5"),0)) -> 22103.178 | S9: {=INDEX(INDIRECT("'"&$A9&"'!$1:$1048576"),MATCH(S$4,INDIRECT("'"&$A9&"'!A:A"),0),MATCH(S$1,INDIRECT("'"&$A9&"'!$5:$5"),0)+1)} -> 0.29579638 | T9: {=INDEX(INDIRECT("'"&$A9&"'!$1:$1048576"),MATCH(T$4,INDIRECT("'"&$A9&"'!A:A"),0),MATCH(T$1,INDIRECT("'"&$A9&"'!$5:$5"),0)+1)} -> 0.31621234 | U9: {=INDEX(INDIRECT("'"&$A9&"'!$1:$1048576"),MATCH(U$4,INDIRECT("'"&$A9&"'!A:A"),0),MATCH(U$1,INDIRECT("'"&$A9&"'!$5:$5"),0)+1)} -> 0.38799127 | V9: =+(C9-R9)/R9 -> 0.016209547 | W9: =+D9-S9 -> 0.016518576 | X9: =+E9-T9 -> -0.015007967 | AK9: Week 5 | AL9: 46054 | AM9: =YEAR(AL9) -> 2026 | AN9: =AK9&", "&AM9 -> Week 5, 2026 | AO9: ="Week Ending "&TEXT(AL9,"mm/dd/yyyy") -> Week Ending 02/01/2026
A10: Consolidated | B10: All | C10: =INDEX(INDIRECT("'"&$A10&"'!$1:$1048576"),MATCH(C$4,INDIRECT("'"&$A10&"'!A:A"),0),MATCH(C$1,INDIRECT("'"&$A10&"'!$5:$5"),0)) -> 115942.83 | D10: {=INDEX(INDIRECT("'"&$A10&"'!$1:$1048576"),MATCH(D$4,INDIRECT("'"&$A10&"'!A:A"),0),MATCH(D$1,INDIRECT("'"&$A10&"'!$5:$5"),0)+1)} -> 0.27021205 | E10: {=INDEX(INDIRECT("'"&$A10&"'!$1:$1048576"),MATCH(E$4,INDIRECT("'"&$A10&"'!A:A"),0),MATCH(E$1,INDIRECT("'"&$A10&"'!$5:$5"),0)+1)} -> 0.29651381 | F10: {=INDEX(INDIRECT("'"&$A10&"'!$1:$1048576"),MATCH(F$4,INDIRECT("'"&$A10&"'!A:A"),0),MATCH(F$1,INDIRECT("'"&$A10&"'!$5:$5"),0)+1)} -> 0.43327414 | G10: =INDEX(INDIRECT("'"&$A10&"'!$1:$1048576"),MATCH(G$4,INDIRECT("'"&$A10&"'!A:A"),0),MATCH(G$1,INDIRECT("'"&$A10&"'!$5:$5"),0)) -> 430987.39 | H10: {=INDEX(INDIRECT("'"&$A10&"'!$1:$1048576"),MATCH(H$4,INDIRECT("'"&$A10&"'!A:A"),0),MATCH(H$1,INDIRECT("'"&$A10&"'!$5:$5"),0)+1)} -> 0.28249984 | I10: {=INDEX(INDIRECT("'"&$A10&"'!$1:$1048576"),MATCH(I$4,INDIRECT("'"&$A10&"'!A:A"),0),MATCH(I$1,INDIRECT("'"&$A10&"'!$5:$5"),0)+1)} -> 0.31454895 | J10: {=INDEX(INDIRECT("'"&$A10&"'!$1:$1048576"),MATCH(J$4,INDIRECT("'"&$A10&"'!A:A"),0),MATCH(J$1,INDIRECT("'"&$A10&"'!$5:$5"),0)+1)} -> 0.40295121 | K10: =INDEX(INDIRECT("'"&$A10&"'!$1:$1048576"),MATCH(K$4,INDIRECT("'"&$A10&"'!A:A"),0),MATCH(K$1,INDIRECT("'"&$A10&"'!$5:$5"),0)) -> 107746.85 | L10: {=INDEX(INDIRECT("'"&$A10&"'!$1:$1048576"),MATCH(L$4,INDIRECT("'"&$A10&"'!A:A"),0),MATCH(L$1,INDIRECT("'"&$A10&"'!$5:$5"),0)+1)} -> 0.28249984 | M10: {=INDEX(INDIRECT("'"&$A10&"'!$1:$1048576"),MATCH(M$4,INDIRECT("'"&$A10&"'!A:A"),0),MATCH(M$1,INDIRECT("'"&$A10&"'!$5:$5"),0)+1)} -> 0.31454895 | N10: {=INDEX(INDIRECT("'"&$A10&"'!$1:$1048576"),MATCH(N$4,INDIRECT("'"&$A10&"'!A:A"),0),MATCH(N$1,INDIRECT("'"&$A10&"'!$5:$5"),0)+1)} -> 0.40295121 | O10: =+(C10-K10)/K10 -> 0.076067028 | P10: =+D10-L10 -> -0.012287791 | Q10: =+E10-M10 -> -0.01803514 | R10: =INDEX(INDIRECT("'"&$A10&"'!$1:$1048576"),MATCH(R$4,INDIRECT("'"&$A10&"'!A:A"),0),MATCH(R$1,INDIRECT("'"&$A10&"'!$5:$5"),0)) -> 110842 | S10: {=INDEX(INDIRECT("'"&$A10&"'!$1:$1048576"),MATCH(S$4,INDIRECT("'"&$A10&"'!A:A"),0),MATCH(S$1,INDIRECT("'"&$A10&"'!$5:$5"),0)+1)} -> 0.28166466 | T10: {=INDEX(INDIRECT("'"&$A10&"'!$1:$1048576"),MATCH(T$4,INDIRECT("'"&$A10&"'!A:A"),0),MATCH(T$1,INDIRECT("'"&$A10&"'!$5:$5"),0)+1)} -> 0.312886 | U10: {=INDEX(INDIRECT("'"&$A10&"'!$1:$1048576"),MATCH(U$4,INDIRECT("'"&$A10&"'!A:A"),0),MATCH(U$1,INDIRECT("'"&$A10&"'!$5:$5"),0)+1)} -> 0.40544934 | V10: =+(C10-R10)/R10 -> 0.046018928 | W10: =+D10-S10 -> -0.011452604 | X10: =+E10-T10 -> -0.016372192 | AK10: Week 6 | AL10: 46061 | AM10: =YEAR(AL10) -> 2026 | AN10: =AK10&", "&AM10 -> Week 6, 2026 | AO10: ="Week Ending "&TEXT(AL10,"mm/dd/yyyy") -> Week Ending 02/08/2026
AK11: Week 7 | AL11: 46068 | AM11: =YEAR(AL11) -> 2026 | AN11: =AK11&", "&AM11 -> Week 7, 2026 | AO11: ="Week Ending "&TEXT(AL11,"mm/dd/yyyy") -> Week Ending 02/15/2026
AK12: Week 8 | AL12: 46075 | AM12: =YEAR(AL12) -> 2026 | AN12: =AK12&", "&AM12 -> Week 8, 2026 | AO12: ="Week Ending "&TEXT(AL12,"mm/dd/yyyy") -> Week Ending 02/22/2026
B13: Notes: | AK13: Week 9 | AL13: 46082 | AM13: =YEAR(AL13) -> 2026 | AN13: =AK13&", "&AM13 -> Week 9, 2026 | AO13: ="Week Ending "&TEXT(AL13,"mm/dd/yyyy") -> Week Ending 03/01/2026
AK14: Week 10 | AL14: 46089 | AM14: =YEAR(AL14) -> 2026 | AN14: =AK14&", "&AM14 -> Week 10, 2026 | AO14: ="Week Ending "&TEXT(AL14,"mm/dd/yyyy") -> Week Ending 03/08/2026
B15: RASA - Ballpark | AK15: Week 11 | AL15: 46096 | AM15: =YEAR(AL15) -> 2026 | AN15: =AK15&", "&AM15 -> Week 11, 2026 | AO15: ="Week Ending "&TEXT(AL15,"mm/dd/yyyy") -> Week Ending 03/15/2026
B16: COGS - | C16: No notes | AK16: Week 12 | AL16: 46103 | AM16: =YEAR(AL16) -> 2026 | AN16: =AK16&", "&AM16 -> Week 12, 2026 | AO16: ="Week Ending "&TEXT(AL16,"mm/dd/yyyy") -> Week Ending 03/22/2026
B17: Labor - | C17: Sales up 17% vs 4-8 week comp but total labor $s are only up 2.3% as a % of sales vs same comp. | AK17: Week 13 | AL17: 46110 | AM17: =YEAR(AL17) -> 2026 | AN17: =AK17&", "&AM17 -> Week 13, 2026 | AO17: ="Week Ending "&TEXT(AL17,"mm/dd/yyyy") -> Week Ending 03/29/2026
AK18: Week 14 | AL18: 46117 | AM18: =YEAR(AL18) -> 2026 | AN18: =AK18&", "&AM18 -> Week 14, 2026 | AO18: ="Week Ending "&TEXT(AL18,"mm/dd/yyyy") -> Week Ending 04/05/2026
B19: RASA - MVT | AK19: Week 15 | AL19: 46124 | AM19: =YEAR(AL19) -> 2026 | AN19: =AK19&", "&AM19 -> Week 15, 2026 | AO19: ="Week Ending "&TEXT(AL19,"mm/dd/yyyy") -> Week Ending 04/12/2026
B20: COGS - | C20: Prepped food - 5.8% vs 7.0% 4-8 week comp. However, PTD is comparable at 7.0%. | AK20: Week 16 | AL20: 46131 | AM20: =YEAR(AL20) -> 2026 | AN20: =AK20&", "&AM20 -> Week 16, 2026 | AO20: ="Week Ending "&TEXT(AL20,"mm/dd/yyyy") -> Week Ending 04/19/2026
B21: Labor - | C21: No notes | AK21: Week 17 | AL21: 46138 | AM21: =YEAR(AL21) -> 2026 | AN21: =AK21&", "&AM21 -> Week 17, 2026 | AO21: ="Week Ending "&TEXT(AL21,"mm/dd/yyyy") -> Week Ending 04/26/2026
AK22: Week 18 | AL22: 46145 | AM22: =YEAR(AL22) -> 2026 | AN22: =AK22&", "&AM22 -> Week 18, 2026 | AO22: ="Week Ending "&TEXT(AL22,"mm/dd/yyyy") -> Week Ending 05/03/2026
B23: RASA - National Landing | AK23: Week 19 | AL23: 46152 | AM23: =YEAR(AL23) -> 2026 | AN23: =AK23&", "&AM23 -> Week 19, 2026 | AO23: ="Week Ending "&TEXT(AL23,"mm/dd/yyyy") -> Week Ending 05/10/2026
B24: COGS - | C24: No notes | AK24: Week 20 | AL24: 46159 | AM24: =YEAR(AL24) -> 2026 | AN24: =AK24&", "&AM24 -> Week 20, 2026 | AO24: ="Week Ending "&TEXT(AL24,"mm/dd/yyyy") -> Week Ending 05/17/2026
B25: Labor - | C25: Sales down 9% vs 4-8 week comp but total labor $s are only down 1.0% as a % of sales vs same comp. P1 bonus expense was posted this week. | AK25: Week 21 | AL25: 46166 | AM25: =YEAR(AL25) -> 2026 | AN25: =AK25&", "&AM25 -> Week 21, 2026 | AO25: ="Week Ending "&TEXT(AL25,"mm/dd/yyyy") -> Week Ending 05/24/2026
AK26: Week 22 | AL26: 46173 | AM26: =YEAR(AL26) -> 2026 | AN26: =AK26&", "&AM26 -> Week 22, 2026 | AO26: ="Week Ending "&TEXT(AL26,"mm/dd/yyyy") -> Week Ending 05/31/2026
B27: RASA - Mosaic | AK27: Week 23 | AL27: 46180 | AM27: =YEAR(AL27) -> 2026 | AN27: =AK27&", "&AM27 -> Week 23, 2026 | AO27: ="Week Ending "&TEXT(AL27,"mm/dd/yyyy") -> Week Ending 06/07/2026
B28: COGS - | C28: No notes | AK28: Week 24 | AL28: 46187 | AM28: =YEAR(AL28) -> 2026 | AN28: =AK28&", "&AM28 -> Week 24, 2026 | AO28: ="Week Ending "&TEXT(AL28,"mm/dd/yyyy") -> Week Ending 06/14/2026
B29: Labor - | C29: Sales down 8% vs 4-8 week comp but total labor $s are down 17.5% as a % of sales vs same comp. | AK29: Week 25 | AL29: 46194 | AM29: =YEAR(AL29) -> 2026 | AN29: =AK29&", "&AM29 -> Week 25, 2026 | AO29: ="Week Ending "&TEXT(AL29,"mm/dd/yyyy") -> Week Ending 06/21/2026
AK30: Week 26 | AL30: 46201 | AM30: =YEAR(AL30) -> 2026 | AN30: =AK30&", "&AM30 -> Week 26, 2026 | AO30: ="Week Ending "&TEXT(AL30,"mm/dd/yyyy") -> Week Ending 06/28/2026
B31: RASA - Rockville | AK31: Week 27 | AL31: 46208 | AM31: =YEAR(AL31) -> 2026 | AN31: =AK31&", "&AM31 -> Week 27, 2026 | AO31: ="Week Ending "&TEXT(AL31,"mm/dd/yyyy") -> Week Ending 07/05/2026
B32: COGS - | C32: No notes | AK32: Week 28 | AL32: 46215 | AM32: =YEAR(AL32) -> 2026 | AN32: =AK32&", "&AM32 -> Week 28, 2026 | AO32: ="Week Ending "&TEXT(AL32,"mm/dd/yyyy") -> Week Ending 07/12/2026
B33: Labor - | C33: No notes | AK33: Week 29 | AL33: 46222 | AM33: =YEAR(AL33) -> 2026 | AN33: =AK33&", "&AM33 -> Week 29, 2026 | AO33: ="Week Ending "&TEXT(AL33,"mm/dd/yyyy") -> Week Ending 07/19/2026
AK34: Week 30 | AL34: 46229 | AM34: =YEAR(AL34) -> 2026 | AN34: =AK34&", "&AM34 -> Week 30, 2026 | AO34: ="Week Ending "&TEXT(AL34,"mm/dd/yyyy") -> Week Ending 07/26/2026
AK35: Week 31 | AL35: 46236 | AM35: =YEAR(AL35) -> 2026 | AN35: =AK35&", "&AM35 -> Week 31, 2026 | AO35: ="Week Ending "&TEXT(AL35,"mm/dd/yyyy") -> Week Ending 08/02/2026
AK36: Week 32 | AL36: 46243 | AM36: =YEAR(AL36) -> 2026 | AN36: =AK36&", "&AM36 -> Week 32, 2026 | AO36: ="Week Ending "&TEXT(AL36,"mm/dd/yyyy") -> Week Ending 08/09/2026
AK37: Week 33 | AL37: 46250 | AM37: =YEAR(AL37) -> 2026 | AN37: =AK37&", "&AM37 -> Week 33, 2026 | AO37: ="Week Ending "&TEXT(AL37,"mm/dd/yyyy") -> Week Ending 08/16/2026
AK38: Week 34 | AL38: 46257 | AM38: =YEAR(AL38) -> 2026 | AN38: =AK38&", "&AM38 -> Week 34, 2026 | AO38: ="Week Ending "&TEXT(AL38,"mm/dd/yyyy") -> Week Ending 08/23/2026
AK39: Week 35 | AL39: 46264 | AM39: =YEAR(AL39) -> 2026 | AN39: =AK39&", "&AM39 -> Week 35, 2026 | AO39: ="Week Ending "&TEXT(AL39,"mm/dd/yyyy") -> Week Ending 08/30/2026
AK40: Week 36 | AL40: 46271 | AM40: =YEAR(AL40) -> 2026 | AN40: =AK40&", "&AM40 -> Week 36, 2026 | AO40: ="Week Ending "&TEXT(AL40,"mm/dd/yyyy") -> Week Ending 09/06/2026
...

Sheet Comparison by Store
A1: Prime Margin - Trailing 12 Week
A2: =+Summary!B2 -> Week Ending 01/25/2026
A3: 7 - RASA - Rockville
B4: 2 - Rasa - Ballpark | D4: 4 - Rasa - MVT | F4: 5 - Rasa - National Landin | H4: 6 - Rasa - Mosaic | J4: 7 - RASA - Rockville | L4: Total
A5: Sales
A6: Single Plate In-House Sales | B6: =INDEX(INDIRECT("'"&B$4&"'!$1:$1048576"),MATCH($A6,INDIRECT("'"&B$4&"'!$A:$A"),0),MATCH($A$2,INDIRECT("'"&B$4&"'!$5:$5"),0)) -> #N/A | C6: =IFERROR(B6/B16, "NA") -> NA | D6: =INDEX(INDIRECT("'"&D$4&"'!$1:$1048576"),MATCH($A6,INDIRECT("'"&D$4&"'!$A:$A"),0),MATCH($A$2,INDIRECT("'"&D$4&"'!$5:$5"),0)) -> #N/A | E6: =IFERROR(D6/D16, "NA") -> NA | F6: =INDEX(INDIRECT("'"&F$4&"'!$1:$1048576"),MATCH($A6,INDIRECT("'"&F$4&"'!$A:$A"),0),MATCH($A$2,INDIRECT("'"&F$4&"'!$5:$5"),0)) -> #N/A | G6: =IFERROR(F6/F16, "NA") -> NA | H6: =INDEX(INDIRECT("'"&H$4&"'!$1:$1048576"),MATCH($A6,INDIRECT("'"&H$4&"'!$A:$A"),0),MATCH($A$2,INDIRECT("'"&H$4&"'!$5:$5"),0)) -> #N/A | I6: =IFERROR(H6/H16, "NA") -> NA | J6: =INDEX(INDIRECT("'"&J$4&"'!$1:$1048576"),MATCH($A6,INDIRECT("'"&J$4&"'!$A:$A"),0),MATCH($A$2,INDIRECT("'"&J$4&"'!$5:$5"),0)) -> #N/A | K6: =IFERROR(J6/J16, "NA") -> NA | L6: =+J6+H6+F6+D6+B6 -> #N/A | M6: =IFERROR(L6/L16, "NA") -> NA
A7: Digital Sales | B7: =INDEX(INDIRECT("'"&B$4&"'!$1:$1048576"),MATCH($A7,INDIRECT("'"&B$4&"'!$A:$A"),0),MATCH($A$2,INDIRECT("'"&B$4&"'!$5:$5"),0)) -> #N/A | C7: =IFERROR(B7/B16, "NA") -> NA | D7: =INDEX(INDIRECT("'"&D$4&"'!$1:$1048576"),MATCH($A7,INDIRECT("'"&D$4&"'!$A:$A"),0),MATCH($A$2,INDIRECT("'"&D$4&"'!$5:$5"),0)) -> #N/A | E7: =IFERROR(D7/D16, "NA") -> NA | F7: =INDEX(INDIRECT("'"&F$4&"'!$1:$1048576"),MATCH($A7,INDIRECT("'"&F$4&"'!$A:$A"),0),MATCH($A$2,INDIRECT("'"&F$4&"'!$5:$5"),0)) -> #N/A | G7: =IFERROR(F7/F16, "NA") -> NA | H7: =INDEX(INDIRECT("'"&H$4&"'!$1:$1048576"),MATCH($A7,INDIRECT("'"&H$4&"'!$A:$A"),0),MATCH($A$2,INDIRECT("'"&H$4&"'!$5:$5"),0)) -> #N/A | I7: =IFERROR(H7/H16, "NA") -> NA | J7: =INDEX(INDIRECT("'"&J$4&"'!$1:$1048576"),MATCH($A7,INDIRECT("'"&J$4&"'!$A:$A"),0),MATCH($A$2,INDIRECT("'"&J$4&"'!$5:$5"),0)) -> #N/A | K7: =IFERROR(J7/J16, "NA") -> NA | L7: =+J7+H7+F7+D7+B7 -> #N/A | M7: =IFERROR(L7/L16, "NA") -> NA
A8: Catering Sales | B8: =INDEX(INDIRECT("'"&B$4&"'!$1:$1048576"),MATCH($A8,INDIRECT("'"&B$4&"'!$A:$A"),0),MATCH($A$2,INDIRECT("'"&B$4&"'!$5:$5"),0)) -> #N/A | C8: =IFERROR(B8/B16, "NA") -> NA | D8: =INDEX(INDIRECT("'"&D$4&"'!$1:$1048576"),MATCH($A8,INDIRECT("'"&D$4&"'!$A:$A"),0),MATCH($A$2,INDIRECT("'"&D$4&"'!$5:$5"),0)) -> #N/A | E8: =IFERROR(D8/D16, "NA") -> NA | F8: =INDEX(INDIRECT("'"&F$4&"'!$1:$1048576"),MATCH($A8,INDIRECT("'"&F$4&"'!$A:$A"),0),MATCH($A$2,INDIRECT("'"&F$4&"'!$5:$5"),0)) -> #N/A | G8: =IFERROR(F8/F16, "NA") -> NA | H8: =INDEX(INDIRECT("'"&H$4&"'!$1:$1048576"),MATCH($A8,INDIRECT("'"&H$4&"'!$A:$A"),0),MATCH($A$2,INDIRECT("'"&H$4&"'!$5:$5"),0)) -> #N/A | I8: =IFERROR(H8/H16, "NA") -> NA | J8: =INDEX(INDIRECT("'"&J$4&"'!$1:$1048576"),MATCH($A8,INDIRECT("'"&J$4&"'!$A:$A"),0),MATCH($A$2,INDIRECT("'"&J$4&"'!$5:$5"),0)) -> #N/A | K8: =IFERROR(J8/J16, "NA") -> NA | L8: =+J8+H8+F8+D8+B8 -> #N/A | M8: =IFERROR(L8/L16, "NA") -> NA
A9: 43000 - Delivery Sales - Rasa Website | B9: =INDEX(INDIRECT("'"&B$4&"'!$1:$1048576"),MATCH($A9,INDIRECT("'"&B$4&"'!$A:$A"),0),MATCH($A$2,INDIRECT("'"&B$4&"'!$5:$5"),0)) -> #N/A | C9: =IFERROR(B9/B16, "NA") -> NA | D9: =INDEX(INDIRECT("'"&D$4&"'!$1:$1048576"),MATCH($A9,INDIRECT("'"&D$4&"'!$A:$A"),0),MATCH($A$2,INDIRECT("'"&D$4&"'!$5:$5"),0)) -> #N/A | E9: =IFERROR(D9/D16, "NA") -> NA | F9: =INDEX(INDIRECT("'"&F$4&"'!$1:$1048576"),MATCH($A9,INDIRECT("'"&F$4&"'!$A:$A"),0),MATCH($A$2,INDIRECT("'"&F$4&"'!$5:$5"),0)) -> #N/A | G9: =IFERROR(F9/F16, "NA") -> NA | H9: =INDEX(INDIRECT("'"&H$4&"'!$1:$1048576"),MATCH($A9,INDIRECT("'"&H$4&"'!$A:$A"),0),MATCH($A$2,INDIRECT("'"&H$4&"'!$5:$5"),0)) -> #N/A | I9: =IFERROR(H9/H16, "NA") -> NA | J9: =INDEX(INDIRECT("'"&J$4&"'!$1:$1048576"),MATCH($A9,INDIRECT("'"&J$4&"'!$A:$A"),0),MATCH($A$2,INDIRECT("'"&J$4&"'!$5:$5"),0)) -> #N/A | K9: =IFERROR(J9/J16, "NA") -> NA | L9: =+J9+H9+F9+D9+B9 -> #N/A | M9: =IFERROR(L9/L16, "NA") -> NA
A10: Delivery Fee Income | B10: =INDEX(INDIRECT("'"&B$4&"'!$1:$1048576"),MATCH($A10,INDIRECT("'"&B$4&"'!$A:$A"),0),MATCH($A$2,INDIRECT("'"&B$4&"'!$5:$5"),0)) -> #N/A | C10: =IFERROR(B10/B16, "NA") -> NA | D10: =INDEX(INDIRECT("'"&D$4&"'!$1:$1048576"),MATCH($A10,INDIRECT("'"&D$4&"'!$A:$A"),0),MATCH($A$2,INDIRECT("'"&D$4&"'!$5:$5"),0)) -> #N/A | E10: =IFERROR(D10/D16, "NA") -> NA | F10: =INDEX(INDIRECT("'"&F$4&"'!$1:$1048576"),MATCH($A10,INDIRECT("'"&F$4&"'!$A:$A"),0),MATCH($A$2,INDIRECT("'"&F$4&"'!$5:$5"),0)) -> #N/A | G10: =IFERROR(F10/F16, "NA") -> NA | H10: =INDEX(INDIRECT("'"&H$4&"'!$1:$1048576"),MATCH($A10,INDIRECT("'"&H$4&"'!$A:$A"),0),MATCH($A$2,INDIRECT("'"&H$4&"'!$5:$5"),0)) -> #N/A | I10: =IFERROR(H10/H16, "NA") -> NA | J10: =INDEX(INDIRECT("'"&J$4&"'!$1:$1048576"),MATCH($A10,INDIRECT("'"&J$4&"'!$A:$A"),0),MATCH($A$2,INDIRECT("'"&J$4&"'!$5:$5"),0)) -> #N/A | K10: =IFERROR(J10/J16, "NA") -> NA | L10: =+J10+H10+F10+D10+B10 -> #N/A | M10: =IFERROR(L10/L16, "NA") -> NA
A11: 45000 - Sales Adjustments | B11: =INDEX(INDIRECT("'"&B$4&"'!$1:$1048576"),MATCH($A11,INDIRECT("'"&B$4&"'!$A:$A"),0),MATCH($A$2,INDIRECT("'"&B$4&"'!$5:$5"),0)) -> #N/A | C11: =IFERROR(B11/B16, "NA") -> NA | D11: =INDEX(INDIRECT("'"&D$4&"'!$1:$1048576"),MATCH($A11,INDIRECT("'"&D$4&"'!$A:$A"),0),MATCH($A$2,INDIRECT("'"&D$4&"'!$5:$5"),0)) -> #N/A | E11: =IFERROR(D11/D16, "NA") -> NA | F11: =INDEX(INDIRECT("'"&F$4&"'!$1:$1048576"),MATCH($A11,INDIRECT("'"&F$4&"'!$A:$A"),0),MATCH($A$2,INDIRECT("'"&F$4&"'!$5:$5"),0)) -> #N/A | G11: =IFERROR(F11/F16, "NA") -> NA | H11: =INDEX(INDIRECT("'"&H$4&"'!$1:$1048576"),MATCH($A11,INDIRECT("'"&H$4&"'!$A:$A"),0),MATCH($A$2,INDIRECT("'"&H$4&"'!$5:$5"),0)) -> #N/A | I11: =IFERROR(H11/H16, "NA") -> NA | J11: =INDEX(INDIRECT("'"&J$4&"'!$1:$1048576"),MATCH($A11,INDIRECT("'"&J$4&"'!$A:$A"),0),MATCH($A$2,INDIRECT("'"&J$4&"'!$5:$5"),0)) -> #N/A | K11: =IFERROR(J11/J16, "NA") -> NA | L11: =+J11+H11+F11+D11+B11 -> #N/A | M11: =IFERROR(L11/L16, "NA") -> NA
A12: Discounts / Refunds | B12: =INDEX(INDIRECT("'"&B$4&"'!$1:$1048576"),MATCH($A12,INDIRECT("'"&B$4&"'!$A:$A"),0),MATCH($A$2,INDIRECT("'"&B$4&"'!$5:$5"),0)) -> #N/A | C12: =IFERROR(B12/B16, "NA") -> NA | D12: =INDEX(INDIRECT("'"&D$4&"'!$1:$1048576"),MATCH($A12,INDIRECT("'"&D$4&"'!$A:$A"),0),MATCH($A$2,INDIRECT("'"&D$4&"'!$5:$5"),0)) -> #N/A | E12: =IFERROR(D12/D16, "NA") -> NA | F12: =INDEX(INDIRECT("'"&F$4&"'!$1:$1048576"),MATCH($A12,INDIRECT("'"&F$4&"'!$A:$A"),0),MATCH($A$2,INDIRECT("'"&F$4&"'!$5:$5"),0)) -> #N/A | G12: =IFERROR(F12/F16, "NA") -> NA | H12: =INDEX(INDIRECT("'"&H$4&"'!$1:$1048576"),MATCH($A12,INDIRECT("'"&H$4&"'!$A:$A"),0),MATCH($A$2,INDIRECT("'"&H$4&"'!$5:$5"),0)) -> #N/A | I12: =IFERROR(H12/H16, "NA") -> NA | J12: =INDEX(INDIRECT("'"&J$4&"'!$1:$1048576"),MATCH($A12,INDIRECT("'"&J$4&"'!$A:$A"),0),MATCH($A$2,INDIRECT("'"&J$4&"'!$5:$5"),0)) -> #N/A | K12: =IFERROR(J12/J16, "NA") -> NA | L12: =+J12+H12+F12+D12+B12 -> #N/A | M12: =IFERROR(L12/L16, "NA") -> NA
A13: 82602 - Other Income_WCK | B13: =INDEX(INDIRECT("'"&B$4&"'!$1:$1048576"),MATCH($A13,INDIRECT("'"&B$4&"'!$A:$A"),0),MATCH($A$2,INDIRECT("'"&B$4&"'!$5:$5"),0)) -> #N/A | C13: =IFERROR(B13/B16, "NA") -> NA | D13: =INDEX(INDIRECT("'"&D$4&"'!$1:$1048576"),MATCH($A13,INDIRECT("'"&D$4&"'!$A:$A"),0),MATCH($A$2,INDIRECT("'"&D$4&"'!$5:$5"),0)) -> #N/A | E13: =IFERROR(D13/D16, "NA") -> NA | F13: =INDEX(INDIRECT("'"&F$4&"'!$1:$1048576"),MATCH($A13,INDIRECT("'"&F$4&"'!$A:$A"),0),MATCH($A$2,INDIRECT("'"&F$4&"'!$5:$5"),0)) -> #N/A | G13: =IFERROR(F13/F16, "NA") -> NA | H13: =INDEX(INDIRECT("'"&H$4&"'!$1:$1048576"),MATCH($A13,INDIRECT("'"&H$4&"'!$A:$A"),0),MATCH($A$2,INDIRECT("'"&H$4&"'!$5:$5"),0)) -> #N/A | I13: =IFERROR(H13/H16, "NA") -> NA | J13: =INDEX(INDIRECT("'"&J$4&"'!$1:$1048576"),MATCH($A13,INDIRECT("'"&J$4&"'!$A:$A"),0),MATCH($A$2,INDIRECT("'"&J$4&"'!$5:$5"),0)) -> #N/A | K13: =IFERROR(J13/J16, "NA") -> NA | L13: =+J13+H13+F13+D13+B13 -> #N/A | M13: =IFERROR(L13/L16, "NA") -> NA
A14: 82604 - Other Income_OTP | B14: =INDEX(INDIRECT("'"&B$4&"'!$1:$1048576"),MATCH($A14,INDIRECT("'"&B$4&"'!$A:$A"),0),MATCH($A$2,INDIRECT("'"&B$4&"'!$5:$5"),0)) -> #N/A | C14: =IFERROR(B14/B16, "NA") -> NA | D14: =INDEX(INDIRECT("'"&D$4&"'!$1:$1048576"),MATCH($A14,INDIRECT("'"&D$4&"'!$A:$A"),0),MATCH($A$2,INDIRECT("'"&D$4&"'!$5:$5"),0)) -> #N/A | E14: =IFERROR(D14/D16, "NA") -> NA | F14: =INDEX(INDIRECT("'"&F$4&"'!$1:$1048576"),MATCH($A14,INDIRECT("'"&F$4&"'!$A:$A"),0),MATCH($A$2,INDIRECT("'"&F$4&"'!$5:$5"),0)) -> #N/A | G14: =IFERROR(F14/F16, "NA") -> NA | H14: =INDEX(INDIRECT("'"&H$4&"'!$1:$1048576"),MATCH($A14,INDIRECT("'"&H$4&"'!$A:$A"),0),MATCH($A$2,INDIRECT("'"&H$4&"'!$5:$5"),0)) -> #N/A | I14: =IFERROR(H14/H16, "NA") -> NA | J14: =INDEX(INDIRECT("'"&J$4&"'!$1:$1048576"),MATCH($A14,INDIRECT("'"&J$4&"'!$A:$A"),0),MATCH($A$2,INDIRECT("'"&J$4&"'!$5:$5"),0)) -> #N/A | K14: =IFERROR(J14/J16, "NA") -> NA | L14: =+J14+H14+F14+D14+B14 -> #N/A | M14: =IFERROR(L14/L16, "NA") -> NA
A15: 82605 - Other Income_To Good To Go | B15: =INDEX(INDIRECT("'"&B$4&"'!$1:$1048576"),MATCH($A15,INDIRECT("'"&B$4&"'!$A:$A"),0),MATCH($A$2,INDIRECT("'"&B$4&"'!$5:$5"),0)) -> #N/A | C15: =IFERROR(B15/B16, "NA") -> NA | D15: =INDEX(INDIRECT("'"&D$4&"'!$1:$1048576"),MATCH($A15,INDIRECT("'"&D$4&"'!$A:$A"),0),MATCH($A$2,INDIRECT("'"&D$4&"'!$5:$5"),0)) -> #N/A | E15: =IFERROR(D15/D16, "NA") -> NA | F15: =INDEX(INDIRECT("'"&F$4&"'!$1:$1048576"),MATCH($A15,INDIRECT("'"&F$4&"'!$A:$A"),0),MATCH($A$2,INDIRECT("'"&F$4&"'!$5:$5"),0)) -> #N/A | G15: =IFERROR(F15/F16, "NA") -> NA | H15: =INDEX(INDIRECT("'"&H$4&"'!$1:$1048576"),MATCH($A15,INDIRECT("'"&H$4&"'!$A:$A"),0),MATCH($A$2,INDIRECT("'"&H$4&"'!$5:$5"),0)) -> #N/A | I15: =IFERROR(H15/H16, "NA") -> NA | J15: =INDEX(INDIRECT("'"&J$4&"'!$1:$1048576"),MATCH($A15,INDIRECT("'"&J$4&"'!$A:$A"),0),MATCH($A$2,INDIRECT("'"&J$4&"'!$5:$5"),0)) -> #N/A | K15: =IFERROR(J15/J16, "NA") -> NA | L15: =+J15+H15+F15+D15+B15 -> #N/A | M15: =IFERROR(L15/L16, "NA") -> NA
A16: Total Sales | B16: =INDEX(INDIRECT("'"&B$4&"'!$1:$1048576"),MATCH($A16,INDIRECT("'"&B$4&"'!$A:$A"),0),MATCH($A$2,INDIRECT("'"&B$4&"'!$5:$5"),0)) -> 20034.79 | C16: =IFERROR(B16/B16, "NA") -> 1 | D16: =INDEX(INDIRECT("'"&D$4&"'!$1:$1048576"),MATCH($A16,INDIRECT("'"&D$4&"'!$A:$A"),0),MATCH($A$2,INDIRECT("'"&D$4&"'!$5:$5"),0)) -> 39699.41 | E16: =IFERROR(D16/D16, "NA") -> 1 | F16: =INDEX(INDIRECT("'"&F$4&"'!$1:$1048576"),MATCH($A16,INDIRECT("'"&F$4&"'!$A:$A"),0),MATCH($A$2,INDIRECT("'"&F$4&"'!$5:$5"),0)) -> 16370.43 | G16: =IFERROR(F16/F16, "NA") -> 1 | H16: =INDEX(INDIRECT("'"&H$4&"'!$1:$1048576"),MATCH($A16,INDIRECT("'"&H$4&"'!$A:$A"),0),MATCH($A$2,INDIRECT("'"&H$4&"'!$5:$5"),0)) -> 17376.74 | I16: =IFERROR(H16/H16, "NA") -> 1 | J16: =INDEX(INDIRECT("'"&J$4&"'!$1:$1048576"),MATCH($A16,INDIRECT("'"&J$4&"'!$A:$A"),0),MATCH($A$2,INDIRECT("'"&J$4&"'!$5:$5"),0)) -> 22461.46 | K16: =IFERROR(J16/J16, "NA") -> 1 | L16: =+J16+H16+F16+D16+B16 -> 115942.83 | M16: =IFERROR(L16/L16, "NA") -> 1
A18: Cost of Goods Sold
A19: Food & Beverage Costs
A20: 50000 - Food & Beverage Costs
A21: Food Costs
A22: 50100 - Food Costs | B22: =INDEX(INDIRECT("'"&B$4&"'!$1:$1048576"),MATCH($A22,INDIRECT("'"&B$4&"'!$A:$A"),0),MATCH($A$2,INDIRECT("'"&B$4&"'!$5:$5"),0)) -> 0 | C22: =IFERROR(B22/B16, "NA") -> 0 | D22: =INDEX(INDIRECT("'"&D$4&"'!$1:$1048576"),MATCH($A22,INDIRECT("'"&D$4&"'!$A:$A"),0),MATCH($A$2,INDIRECT("'"&D$4&"'!$5:$5"),0)) -> 0 | E22: =IFERROR(D22/D16, "NA") -> 0 | F22: =INDEX(INDIRECT("'"&F$4&"'!$1:$1048576"),MATCH($A22,INDIRECT("'"&F$4&"'!$A:$A"),0),MATCH($A$2,INDIRECT("'"&F$4&"'!$5:$5"),0)) -> 0 | G22: =IFERROR(F22/F16, "NA") -> 0 | H22: =INDEX(INDIRECT("'"&H$4&"'!$1:$1048576"),MATCH($A22,INDIRECT("'"&H$4&"'!$A:$A"),0),MATCH($A$2,INDIRECT("'"&H$4&"'!$5:$5"),0)) -> 0 | I22: =IFERROR(H22/H16, "NA") -> 0 | J22: =INDEX(INDIRECT("'"&J$4&"'!$1:$1048576"),MATCH($A22,INDIRECT("'"&J$4&"'!$A:$A"),0),MATCH($A$2,INDIRECT("'"&J$4&"'!$5:$5"),0)) -> 0 | K22: =IFERROR(J22/J16, "NA") -> 0 | M22: =IFERROR(L22/L16, "NA") -> 0
A23: 50110 - COGS - Produce | B23: =INDEX(INDIRECT("'"&B$4&"'!$1:$1048576"),MATCH($A23,INDIRECT("'"&B$4&"'!$A:$A"),0),MATCH($A$2,INDIRECT("'"&B$4&"'!$5:$5"),0)) -> 1038.36 | C23: =IFERROR(B23/B16, "NA") -> 0.051827845 | D23: =INDEX(INDIRECT("'"&D$4&"'!$1:$1048576"),MATCH($A23,INDIRECT("'"&D$4&"'!$A:$A"),0),MATCH($A$2,INDIRECT("'"&D$4&"'!$5:$5"),0)) -> 1910.6 | E23: =IFERROR(D23/D16, "NA") -> 0.04812666 | F23: =INDEX(INDIRECT("'"&F$4&"'!$1:$1048576"),MATCH($A23,INDIRECT("'"&F$4&"'!$A:$A"),0),MATCH($A$2,INDIRECT("'"&F$4&"'!$5:$5"),0)) -> 816.91 | G23: =IFERROR(F23/F16, "NA") -> 0.04990156 | H23: =INDEX(INDIRECT("'"&H$4&"'!$1:$1048576"),MATCH($A23,INDIRECT("'"&H$4&"'!$A:$A"),0),MATCH($A$2,INDIRECT("'"&H$4&"'!$5:$5"),0)) -> 691.24 | I23: =IFERROR(H23/H16, "NA") -> 0.039779613 | J23: =INDEX(INDIRECT("'"&J$4&"'!$1:$1048576"),MATCH($A23,INDIRECT("'"&J$4&"'!$A:$A"),0),MATCH($A$2,INDIRECT("'"&J$4&"'!$5:$5"),0)) -> 1249.54 | K23: =IFERROR(J23/J16, "NA") -> 0.0556304 | L23: =+J23+H23+F23+D23+B23 -> 5706.65 | M23: =IFERROR(L23/L16, "NA") -> 0.049219516
A24: 50120 - COGS - Grocery Dry & Canned | B24: =INDEX(INDIRECT("'"&B$4&"'!$1:$1048576"),MATCH($A24,INDIRECT("'"&B$4&"'!$A:$A"),0),MATCH($A$2,INDIRECT("'"&B$4&"'!$5:$5"),0)) -> 579.79 | C24: =IFERROR(B24/B16, "NA") -> 0.02893916 | D24: =INDEX(INDIRECT("'"&D$4&"'!$1:$1048576"),MATCH($A24,INDIRECT("'"&D$4&"'!$A:$A"),0),MATCH($A$2,INDIRECT("'"&D$4&"'!$5:$5"),0)) -> 1091.48 | E24: =IFERROR(D24/D16, "NA") -> 0.027493608 | F24: =INDEX(INDIRECT("'"&F$4&"'!$1:$1048576"),MATCH($A24,INDIRECT("'"&F$4&"'!$A:$A"),0),MATCH($A$2,INDIRECT("'"&F$4&"'!$5:$5"),0)) -> 377.75 | G24: =IFERROR(F24/F16, "NA") -> 0.023075142 | H24: =INDEX(INDIRECT("'"&H$4&"'!$1:$1048576"),MATCH($A24,INDIRECT("'"&H$4&"'!$A:$A"),0),MATCH($A$2,INDIRECT("'"&H$4&"'!$5:$5"),0)) -> 519.04 | I24: =IFERROR(H24/H16, "NA") -> 0.029869814 | J24: =INDEX(INDIRECT("'"&J$4&"'!$1:$1048576"),MATCH($A24,INDIRECT("'"&J$4&"'!$A:$A"),0),MATCH($A$2,INDIRECT("'"&J$4&"'!$5:$5"),0)) -> 765.99 | K24: =IFERROR(J24/J16, "NA") -> 0.034102414 | L24: =+J24+H24+F24+D24+B24 -> 3334.05 | M24: =IFERROR(L24/L16, "NA") -> 0.028755983
A25: 50130 - COGS - Poultry | B25: =INDEX(INDIRECT("'"&B$4&"'!$1:$1048576"),MATCH($A25,INDIRECT("'"&B$4&"'!$A:$A"),0),MATCH($A$2,INDIRECT("'"&B$4&"'!$5:$5"),0)) -> 618.5 | C25: =IFERROR(B25/B16, "NA") -> 0.030871299 | D25: =INDEX(INDIRECT("'"&D$4&"'!$1:$1048576"),MATCH($A25,INDIRECT("'"&D$4&"'!$A:$A"),0),MATCH($A$2,INDIRECT("'"&D$4&"'!$5:$5"),0)) -> 1062.92 | E25: =IFERROR(D25/D16, "NA") -> 0.026774201 | F25: =INDEX(INDIRECT("'"&F$4&"'!$1:$1048576"),MATCH($A25,INDIRECT("'"&F$4&"'!$A:$A"),0),MATCH($A$2,INDIRECT("'"&F$4&"'!$5:$5"),0)) -> 358.18 | G25: =IFERROR(F25/F16, "NA") -> 0.021879694 | H25: =INDEX(INDIRECT("'"&H$4&"'!$1:$1048576"),MATCH($A25,INDIRECT("'"&H$4&"'!$A:$A"),0),MATCH($A$2,INDIRECT("'"&H$4&"'!$5:$5"),0)) -> 451.53 | I25: =IFERROR(H25/H16, "NA") -> 0.025984736 | J25: =INDEX(INDIRECT("'"&J$4&"'!$1:$1048576"),MATCH($A25,INDIRECT("'"&J$4&"'!$A:$A"),0),MATCH($A$2,INDIRECT("'"&J$4&"'!$5:$5"),0)) -> 752.13 | K25: =IFERROR(J25/J16, "NA") -> 0.033485357 | L25: =+J25+H25+F25+D25+B25 -> 3243.26 | M25: =IFERROR(L25/L16, "NA") -> 0.027972924
A26: 50140 - COGS - Dairy | B26: =INDEX(INDIRECT("'"&B$4&"'!$1:$1048576"),MATCH($A26,INDIRECT("'"&B$4&"'!$A:$A"),0),MATCH($A$2,INDIRECT("'"&B$4&"'!$5:$5"),0)) -> 409.97 | C26: =IFERROR(B26/B16, "NA") -> 0.020462905 | D26: =INDEX(INDIRECT("'"&D$4&"'!$1:$1048576"),MATCH($A26,INDIRECT("'"&D$4&"'!$A:$A"),0),MATCH($A$2,INDIRECT("'"&D$4&"'!$5:$5"),0)) -> 573.87 | E26: =IFERROR(D26/D16, "NA") -> 0.014455379 | F26: =INDEX(INDIRECT("'"&F$4&"'!$1:$1048576"),MATCH($A26,INDIRECT("'"&F$4&"'!$A:$A"),0),MATCH($A$2,INDIRECT("'"&F$4&"'!$5:$5"),0)) -> 387.48 | G26: =IFERROR(F26/F16, "NA") -> 0.023669507 | H26: =INDEX(INDIRECT("'"&H$4&"'!$1:$1048576"),MATCH($A26,INDIRECT("'"&H$4&"'!$A:$A"),0),MATCH($A$2,INDIRECT("'"&H$4&"'!$5:$5"),0)) -> 435.55 | I26: =IFERROR(H26/H16, "NA") -> 0.025065116 | J26: =INDEX(INDIRECT("'"&J$4&"'!$1:$1048576"),MATCH($A26,INDIRECT("'"&J$4&"'!$A:$A"),0),MATCH($A$2,INDIRECT("'"&J$4&"'!$5:$5"),0)) -> 601.5 | K26: =IFERROR(J26/J16, "NA") -> 0.026779203 | L26: =+J26+H26+F26+D26+B26 -> 2408.37 | M26: =IFERROR(L26/L16, "NA") -> 0.020772048
A27: 50150 - COGS - Frozen | B27: =INDEX(INDIRECT("'"&B$4&"'!$1:$1048576"),MATCH($A27,INDIRECT("'"&B$4&"'!$A:$A"),0),MATCH($A$2,INDIRECT("'"&B$4&"'!$5:$5"),0)) -> 231.81 | C27: =IFERROR(B27/B16, "NA") -> 0.011570373 | D27: =INDEX(INDIRECT("'"&D$4&"'!$1:$1048576"),MATCH($A27,INDIRECT("'"&D$4&"'!$A:$A"),0),MATCH($A$2,INDIRECT("'"&D$4&"'!$5:$5"),0)) -> 331.07 | E27: =IFERROR(D27/D16, "NA") -> 0.0083394186 | F27: =INDEX(INDIRECT("'"&F$4&"'!$1:$1048576"),MATCH($A27,INDIRECT("'"&F$4&"'!$A:$A"),0),MATCH($A$2,INDIRECT("'"&F$4&"'!$5:$5"),0)) -> 228.25 | G27: =IFERROR(F27/F16, "NA") -> 0.013942823 | H27: =INDEX(INDIRECT("'"&H$4&"'!$1:$1048576"),MATCH($A27,INDIRECT("'"&H$4&"'!$A:$A"),0),MATCH($A$2,INDIRECT("'"&H$4&"'!$5:$5"),0)) -> 202.79 | I27: =IFERROR(H27/H16, "NA") -> 0.011670198 | J27: =INDEX(INDIRECT("'"&J$4&"'!$1:$1048576"),MATCH($A27,INDIRECT("'"&J$4&"'!$A:$A"),0),MATCH($A$2,INDIRECT("'"&J$4&"'!$5:$5"),0)) -> 304.34 | K27: =IFERROR(J27/J16, "NA") -> 0.013549431 | L27: =+J27+H27+F27+D27+B27 -> 1298.26 | M27: =IFERROR(L27/L16, "NA") -> 0.011197415
A28: 50160 - COGS - Meat | B28: =INDEX(INDIRECT("'"&B$4&"'!$1:$1048576"),MATCH($A28,INDIRECT("'"&B$4&"'!$A:$A"),0),MATCH($A$2,INDIRECT("'"&B$4&"'!$5:$5"),0)) -> 199.82 | C28: =IFERROR(B28/B16, "NA") -> 0.0099736508 | D28: =INDEX(INDIRECT("'"&D$4&"'!$1:$1048576"),MATCH($A28,INDIRECT("'"&D$4&"'!$A:$A"),0),MATCH($A$2,INDIRECT("'"&D$4&"'!$5:$5"),0)) -> 488.88 | E28: =IFERROR(D28/D16, "NA") -> 0.012314541 | F28: =INDEX(INDIRECT("'"&F$4&"'!$1:$1048576"),MATCH($A28,INDIRECT("'"&F$4&"'!$A:$A"),0),MATCH($A$2,INDIRECT("'"&F$4&"'!$5:$5"),0)) -> 130.39 | G28: =IFERROR(F28/F16, "NA") -> 0.007964971 | H28: =INDEX(INDIRECT("'"&H$4&"'!$1:$1048576"),MATCH($A28,INDIRECT("'"&H$4&"'!$A:$A"),0),MATCH($A$2,INDIRECT("'"&H$4&"'!$5:$5"),0)) -> 153.94 | I28: =IFERROR(H28/H16, "NA") -> 0.0088589689 | J28: =INDEX(INDIRECT("'"&J$4&"'!$1:$1048576"),MATCH($A28,INDIRECT("'"&J$4&"'!$A:$A"),0),MATCH($A$2,INDIRECT("'"&J$4&"'!$5:$5"),0)) -> 195.91 | K28: =IFERROR(J28/J16, "NA") -> 0.008722051 | L28: =+J28+H28+F28+D28+B28 -> 1168.94 | M28: =IFERROR(L28/L16, "NA") -> 0.010082038
A29: 50170 - COGS - Seafood | B29: =INDEX(INDIRECT("'"&B$4&"'!$1:$1048576"),MATCH($A29,INDIRECT("'"&B$4&"'!$A:$A"),0),MATCH($A$2,INDIRECT("'"&B$4&"'!$5:$5"),0)) -> 0 | C29: =IFERROR(B29/B16, "NA") -> 0 | D29: =INDEX(INDIRECT("'"&D$4&"'!$1:$1048576"),MATCH($A29,INDIRECT("'"&D$4&"'!$A:$A"),0),MATCH($A$2,INDIRECT("'"&D$4&"'!$5:$5"),0)) -> 0 | E29: =IFERROR(D29/D16, "NA") -> 0 | F29: =INDEX(INDIRECT("'"&F$4&"'!$1:$1048576"),MATCH($A29,INDIRECT("'"&F$4&"'!$A:$A"),0),MATCH($A$2,INDIRECT("'"&F$4&"'!$5:$5"),0)) -> 0 | G29: =IFERROR(F29/F16, "NA") -> 0 | H29: =INDEX(INDIRECT("'"&H$4&"'!$1:$1048576"),MATCH($A29,INDIRECT("'"&H$4&"'!$A:$A"),0),MATCH($A$2,INDIRECT("'"&H$4&"'!$5:$5"),0)) -> 0 | I29: =IFERROR(H29/H16, "NA") -> 0 | J29: =INDEX(INDIRECT("'"&J$4&"'!$1:$1048576"),MATCH($A29,INDIRECT("'"&J$4&"'!$A:$A"),0),MATCH($A$2,INDIRECT("'"&J$4&"'!$5:$5"),0)) -> 0 | K29: =IFERROR(J29/J16, "NA") -> 0 | L29: =+J29+H29+F29+D29+B29 -> 0 | M29: =IFERROR(L29/L16, "NA") -> 0
A30: 50180 - COGS - Spices | B30: =INDEX(INDIRECT("'"&B$4&"'!$1:$1048576"),MATCH($A30,INDIRECT("'"&B$4&"'!$A:$A"),0),MATCH($A$2,INDIRECT("'"&B$4&"'!$5:$5"),0)) -> 107.93 | C30: =IFERROR(B30/B16, "NA") -> 0.0053871291 | D30: =INDEX(INDIRECT("'"&D$4&"'!$1:$1048576"),MATCH($A30,INDIRECT("'"&D$4&"'!$A:$A"),0),MATCH($A$2,INDIRECT("'"&D$4&"'!$5:$5"),0)) -> 46.78 | E30: =IFERROR(D30/D16, "NA") -> 0.001178355 | F30: =INDEX(INDIRECT("'"&F$4&"'!$1:$1048576"),MATCH($A30,INDIRECT("'"&F$4&"'!$A:$A"),0),MATCH($A$2,INDIRECT("'"&F$4&"'!$5:$5"),0)) -> 110.85 | G30: =IFERROR(F30/F16, "NA") -> 0.0067713554 | H30: =INDEX(INDIRECT("'"&H$4&"'!$1:$1048576"),MATCH($A30,INDIRECT("'"&H$4&"'!$A:$A"),0),MATCH($A$2,INDIRECT("'"&H$4&"'!$5:$5"),0)) -> 71.56 | I30: =IFERROR(H30/H16, "NA") -> 0.0041181487 | J30: =INDEX(INDIRECT("'"&J$4&"'!$1:$1048576"),MATCH($A30,INDIRECT("'"&J$4&"'!$A:$A"),0),MATCH($A$2,INDIRECT("'"&J$4&"'!$5:$5"),0)) -> 205.02 | K30: =IFERROR(J30/J16, "NA") -> 0.0091276346 | L30: =+J30+H30+F30+D30+B30 -> 542.14 | M30: =IFERROR(L30/L16, "NA") -> 0.0046759252
A31: 50190 - COGS - Prepped Food | B31: =INDEX(INDIRECT("'"&B$4&"'!$1:$1048576"),MATCH($A31,INDIRECT("'"&B$4&"'!$A:$A"),0),MATCH($A$2,INDIRECT("'"&B$4&"'!$5:$5"),0)) -> 1150.01 | C31: =IFERROR(B31/B16, "NA") -> 0.057400652 | D31: =INDEX(INDIRECT("'"&D$4&"'!$1:$1048576"),MATCH($A31,INDIRECT("'"&D$4&"'!$A:$A"),0),MATCH($A$2,INDIRECT("'"&D$4&"'!$5:$5"),0)) -> 2283.11 | E31: =IFERROR(D31/D16, "NA") -> 0.057509923 | F31: =INDEX(INDIRECT("'"&F$4&"'!$1:$1048576"),MATCH($A31,INDIRECT("'"&F$4&"'!$A:$A"),0),MATCH($A$2,INDIRECT("'"&F$4&"'!$5:$5"),0)) -> 1048.29 | G31: =IFERROR(F31/F16, "NA") -> 0.064035581 | H31: =INDEX(INDIRECT("'"&H$4&"'!$1:$1048576"),MATCH($A31,INDIRECT("'"&H$4&"'!$A:$A"),0),MATCH($A$2,INDIRECT("'"&H$4&"'!$5:$5"),0)) -> 1228.48 | I31: =IFERROR(H31/H16, "NA") -> 0.070696805 | J31: =INDEX(INDIRECT("'"&J$4&"'!$1:$1048576"),MATCH($A31,INDIRECT("'"&J$4&"'!$A:$A"),0),MATCH($A$2,INDIRECT("'"&J$4&"'!$5:$5"),0)) -> 1833.13 | K31: =IFERROR(J31/J16, "NA") -> 0.081612237 | L31: =+J31+H31+F31+D31+B31 -> 7543.02 | M31: =IFERROR(L31/L16, "NA") -> 0.065058098
A32: 50191 - COGS - Wow Bao | B32: =INDEX(INDIRECT("'"&B$4&"'!$1:$1048576"),MATCH($A32,INDIRECT("'"&B$4&"'!$A:$A"),0),MATCH($A$2,INDIRECT("'"&B$4&"'!$5:$5"),0)) -> 0 | C32: =IFERROR(B32/B16, "NA") -> 0 | D32: =INDEX(INDIRECT("'"&D$4&"'!$1:$1048576"),MATCH($A32,INDIRECT("'"&D$4&"'!$A:$A"),0),MATCH($A$2,INDIRECT("'"&D$4&"'!$5:$5"),0)) -> 0 | E32: =IFERROR(D32/D16, "NA") -> 0 | F32: =INDEX(INDIRECT("'"&F$4&"'!$1:$1048576"),MATCH($A32,INDIRECT("'"&F$4&"'!$A:$A"),0),MATCH($A$2,INDIRECT("'"&F$4&"'!$5:$5"),0)) -> 0 | G32: =IFERROR(F32/F16, "NA") -> 0 | H32: =INDEX(INDIRECT("'"&H$4&"'!$1:$1048576"),MATCH($A32,INDIRECT("'"&H$4&"'!$A:$A"),0),MATCH($A$2,INDIRECT("'"&H$4&"'!$5:$5"),0)) -> 0 | I32: =IFERROR(H32/H16, "NA") -> 0 | J32: =INDEX(INDIRECT("'"&J$4&"'!$1:$1048576"),MATCH($A32,INDIRECT("'"&J$4&"'!$A:$A"),0),MATCH($A$2,INDIRECT("'"&J$4&"'!$5:$5"),0)) -> 0 | K32: =IFERROR(J32/J16, "NA") -> 0 | L32: =+J32+H32+F32+D32+B32 -> 0 | M32: =IFERROR(L32/L16, "NA") -> 0
A33: 50195 - COGS - Distribution | B33: =INDEX(INDIRECT("'"&B$4&"'!$1:$1048576"),MATCH($A33,INDIRECT("'"&B$4&"'!$A:$A"),0),MATCH($A$2,INDIRECT("'"&B$4&"'!$5:$5"),0)) -> 0 | C33: =IFERROR(B33/B16, "NA") -> 0 | D33: =INDEX(INDIRECT("'"&D$4&"'!$1:$1048576"),MATCH($A33,INDIRECT("'"&D$4&"'!$A:$A"),0),MATCH($A$2,INDIRECT("'"&D$4&"'!$5:$5"),0)) -> 0 | E33: =IFERROR(D33/D16, "NA") -> 0 | F33: =INDEX(INDIRECT("'"&F$4&"'!$1:$1048576"),MATCH($A33,INDIRECT("'"&F$4&"'!$A:$A"),0),MATCH($A$2,INDIRECT("'"&F$4&"'!$5:$5"),0)) -> 0 | G33: =IFERROR(F33/F16, "NA") -> 0 | H33: =INDEX(INDIRECT("'"&H$4&"'!$1:$1048576"),MATCH($A33,INDIRECT("'"&H$4&"'!$A:$A"),0),MATCH($A$2,INDIRECT("'"&H$4&"'!$5:$5"),0)) -> 0 | I33: =IFERROR(H33/H16, "NA") -> 0 | J33: =INDEX(INDIRECT("'"&J$4&"'!$1:$1048576"),MATCH($A33,INDIRECT("'"&J$4&"'!$A:$A"),0),MATCH($A$2,INDIRECT("'"&J$4&"'!$5:$5"),0)) -> 0 | K33: =IFERROR(J33/J16, "NA") -> 0 | L33: =+J33+H33+F33+D33+B33 -> 0 | M33: =IFERROR(L33/L16, "NA") -> 0
A34: Total Food Costs | B34: =INDEX(INDIRECT("'"&B$4&"'!$1:$1048576"),MATCH($A34,INDIRECT("'"&B$4&"'!$A:$A"),0),MATCH($A$2,INDIRECT("'"&B$4&"'!$5:$5"),0)) -> 4336.19 | C34: =IFERROR(B34/B16, "NA") -> 0.21643301 | D34: =INDEX(INDIRECT("'"&D$4&"'!$1:$1048576"),MATCH($A34,INDIRECT("'"&D$4&"'!$A:$A"),0),MATCH($A$2,INDIRECT("'"&D$4&"'!$5:$5"),0)) -> 7788.71 | E34: =IFERROR(D34/D16, "NA") -> 0.19619208 | F34: =INDEX(INDIRECT("'"&F$4&"'!$1:$1048576"),MATCH($A34,INDIRECT("'"&F$4&"'!$A:$A"),0),MATCH($A$2,INDIRECT("'"&F$4&"'!$5:$5"),0)) -> 3458.1 | G34: =IFERROR(F34/F16, "NA") -> 0.21124063 | H34: =INDEX(INDIRECT("'"&H$4&"'!$1:$1048576"),MATCH($A34,INDIRECT("'"&H$4&"'!$A:$A"),0),MATCH($A$2,INDIRECT("'"&H$4&"'!$5:$5"),0)) -> 3754.13 | I34: =IFERROR(H34/H16, "NA") -> 0.2160434 | J34: =INDEX(INDIRECT("'"&J$4&"'!$1:$1048576"),MATCH($A34,INDIRECT("'"&J$4&"'!$A:$A"),0),MATCH($A$2,INDIRECT("'"&J$4&"'!$5:$5"),0)) -> 5907.56 | K34: =IFERROR(J34/J16, "NA") -> 0.26300873 | L34: =+J34+H34+F34+D34+B34 -> 25244.69 | M34: =IFERROR(L34/L16, "NA") -> 0.21773395
A35: Beverage Costs
A36: 50101 - Beverage Costs | B36: =INDEX(INDIRECT("'"&B$4&"'!$1:$1048576"),MATCH($A36,INDIRECT("'"&B$4&"'!$A:$A"),0),MATCH($A$2,INDIRECT("'"&B$4&"'!$5:$5"),0)) -> 0 | C36: =IFERROR(B36/B16, "NA") -> 0 | D36: =INDEX(INDIRECT("'"&D$4&"'!$1:$1048576"),MATCH($A36,INDIRECT("'"&D$4&"'!$A:$A"),0),MATCH($A$2,INDIRECT("'"&D$4&"'!$5:$5"),0)) -> 0 | E36: =IFERROR(D36/D16, "NA") -> 0 | F36: =INDEX(INDIRECT("'"&F$4&"'!$1:$1048576"),MATCH($A36,INDIRECT("'"&F$4&"'!$A:$A"),0),MATCH($A$2,INDIRECT("'"&F$4&"'!$5:$5"),0)) -> 0 | G36: =IFERROR(F36/F16, "NA") -> 0 | H36: =INDEX(INDIRECT("'"&H$4&"'!$1:$1048576"),MATCH($A36,INDIRECT("'"&H$4&"'!$A:$A"),0),MATCH($A$2,INDIRECT("'"&H$4&"'!$5:$5"),0)) -> 0 | I36: =IFERROR(H36/H16, "NA") -> 0 | J36: =INDEX(INDIRECT("'"&J$4&"'!$1:$1048576"),MATCH($A36,INDIRECT("'"&J$4&"'!$A:$A"),0),MATCH($A$2,INDIRECT("'"&J$4&"'!$5:$5"),0)) -> 0 | K36: =IFERROR(J36/J16, "NA") -> 0 | M36: =IFERROR(L36/L16, "NA") -> 0
A37: 50200 - COGS - N/A Beverage | B37: =INDEX(INDIRECT("'"&B$4&"'!$1:$1048576"),MATCH($A37,INDIRECT("'"&B$4&"'!$A:$A"),0),MATCH($A$2,INDIRECT("'"&B$4&"'!$5:$5"),0)) -> 278.64 | C37: =IFERROR(B37/B16, "NA") -> 0.013907807 | D37: =INDEX(INDIRECT("'"&D$4&"'!$1:$1048576"),MATCH($A37,INDIRECT("'"&D$4&"'!$A:$A"),0),MATCH($A$2,INDIRECT("'"&D$4&"'!$5:$5"),0)) -> 450.47 | E37: =IFERROR(D37/D16, "NA") -> 0.01134702 | F37: =INDEX(INDIRECT("'"&F$4&"'!$1:$1048576"),MATCH($A37,INDIRECT("'"&F$4&"'!$A:$A"),0),MATCH($A$2,INDIRECT("'"&F$4&"'!$5:$5"),0)) -> 58.22 | G37: =IFERROR(F37/F16, "NA") -> 0.0035564124 | H37: =INDEX(INDIRECT("'"&H$4&"'!$1:$1048576"),MATCH($A37,INDIRECT("'"&H$4&"'!$A:$A"),0),MATCH($A$2,INDIRECT("'"&H$4&"'!$5:$5"),0)) -> 337.44 | I37: =IFERROR(H37/H16, "NA") -> 0.019419062 | J37: =INDEX(INDIRECT("'"&J$4&"'!$1:$1048576"),MATCH($A37,INDIRECT("'"&J$4&"'!$A:$A"),0),MATCH($A$2,INDIRECT("'"&J$4&"'!$5:$5"),0)) -> 309.21 | K37: =IFERROR(J37/J16, "NA") -> 0.013766247 | L37: =+J37+H37+F37+D37+B37 -> 1433.98 | M37: =IFERROR(L37/L16, "NA") -> 0.012367992
A38: 50300 - COGS - Beer | B38: =INDEX(INDIRECT("'"&B$4&"'!$1:$1048576"),MATCH($A38,INDIRECT("'"&B$4&"'!$A:$A"),0),MATCH($A$2,INDIRECT("'"&B$4&"'!$5:$5"),0)) -> 19.39 | C38: =IFERROR(B38/B16, "NA") -> 0.00096781648 | D38: =INDEX(INDIRECT("'"&D$4&"'!$1:$1048576"),MATCH($A38,INDIRECT("'"&D$4&"'!$A:$A"),0),MATCH($A$2,INDIRECT("'"&D$4&"'!$5:$5"),0)) -> 13.77 | E38: =IFERROR(D38/D16, "NA") -> 0.00034685654 | F38: =INDEX(INDIRECT("'"&F$4&"'!$1:$1048576"),MATCH($A38,INDIRECT("'"&F$4&"'!$A:$A"),0),MATCH($A$2,INDIRECT("'"&F$4&"'!$5:$5"),0)) -> 5.64 | G38: =IFERROR(F38/F16, "NA") -> 0.00034452363 | H38: =INDEX(INDIRECT("'"&H$4&"'!$1:$1048576"),MATCH($A38,INDIRECT("'"&H$4&"'!$A:$A"),0),MATCH($A$2,INDIRECT("'"&H$4&"'!$5:$5"),0)) -> 12.18 | I38: =IFERROR(H38/H16, "NA") -> 0.000700937 | J38: =INDEX(INDIRECT("'"&J$4&"'!$1:$1048576"),MATCH($A38,INDIRECT("'"&J$4&"'!$A:$A"),0),MATCH($A$2,INDIRECT("'"&J$4&"'!$5:$5"),0)) -> 8.3 | K38: =IFERROR(J38/J16, "NA") -> 0.00036952184 | L38: =+J38+H38+F38+D38+B38 -> 59.28 | M38: =IFERROR(L38/L16, "NA") -> 0.00051128647
A39: 50400 - COGS - Liquor | B39: =INDEX(INDIRECT("'"&B$4&"'!$1:$1048576"),MATCH($A39,INDIRECT("'"&B$4&"'!$A:$A"),0),MATCH($A$2,INDIRECT("'"&B$4&"'!$5:$5"),0)) -> 0 | C39: =IFERROR(B39/B16, "NA") -> 0 | D39: =INDEX(INDIRECT("'"&D$4&"'!$1:$1048576"),MATCH($A39,INDIRECT("'"&D$4&"'!$A:$A"),0),MATCH($A$2,INDIRECT("'"&D$4&"'!$5:$5"),0)) -> 0.8 | E39: =IFERROR(D39/D16, "NA") -> 2.0151433e-05 | F39: =INDEX(INDIRECT("'"&F$4&"'!$1:$1048576"),MATCH($A39,INDIRECT("'"&F$4&"'!$A:$A"),0),MATCH($A$2,INDIRECT("'"&F$4&"'!$5:$5"),0)) -> 0 | G39: =IFERROR(F39/F16, "NA") -> 0 | H39: =INDEX(INDIRECT("'"&H$4&"'!$1:$1048576"),MATCH($A39,INDIRECT("'"&H$4&"'!$A:$A"),0),MATCH($A$2,INDIRECT("'"&H$4&"'!$5:$5"),0)) -> 29.9 | I39: =IFERROR(H39/H16, "NA") -> 0.001720691 | J39: =INDEX(INDIRECT("'"&J$4&"'!$1:$1048576"),MATCH($A39,INDIRECT("'"&J$4&"'!$A:$A"),0),MATCH($A$2,INDIRECT("'"&J$4&"'!$5:$5"),0)) -> 0 | K39: =IFERROR(J39/J16, "NA") -> 0 | L39: =+J39+H39+F39+D39+B39 -> 30.7 | M39: =IFERROR(L39/L16, "NA") -> 0.00026478567
A40: 50500 - COGS - Wine | B40: =INDEX(INDIRECT("'"&B$4&"'!$1:$1048576"),MATCH($A40,INDIRECT("'"&B$4&"'!$A:$A"),0),MATCH($A$2,INDIRECT("'"&B$4&"'!$5:$5"),0)) -> 24.71 | C40: =IFERROR(B40/B16, "NA") -> 0.0012333546 | D40: =INDEX(INDIRECT("'"&D$4&"'!$1:$1048576"),MATCH($A40,INDIRECT("'"&D$4&"'!$A:$A"),0),MATCH($A$2,INDIRECT("'"&D$4&"'!$5:$5"),0)) -> -11.7 | E40: =IFERROR(D40/D16, "NA") -> -0.00029471471 | F40: =INDEX(INDIRECT("'"&F$4&"'!$1:$1048576"),MATCH($A40,INDIRECT("'"&F$4&"'!$A:$A"),0),MATCH($A$2,INDIRECT("'"&F$4&"'!$5:$5"),0)) -> 6.99 | G40: =IFERROR(F40/F16, "NA") -> 0.00042698939 | H40: =INDEX(INDIRECT("'"&H$4&"'!$1:$1048576"),MATCH($A40,INDIRECT("'"&H$4&"'!$A:$A"),0),MATCH($A$2,INDIRECT("'"&H$4&"'!$5:$5"),0)) -> 14.36 | I40: =IFERROR(H40/H16, "NA") -> 0.00082639206 | J40: =INDEX(INDIRECT("'"&J$4&"'!$1:$1048576"),MATCH($A40,INDIRECT("'"&J$4&"'!$A:$A"),0),MATCH($A$2,INDIRECT("'"&J$4&"'!$5:$5"),0)) -> 5.92 | K40: =IFERROR(J40/J16, "NA") -> 0.00026356256 | L40: =+J40+H40+F40+D40+B40 -> 40.28 | M40: =IFERROR(L40/L16, "NA") -> 0.0003474126
A41: Total Beverage Costs | B41: =INDEX(INDIRECT("'"&B$4&"'!$1:$1048576"),MATCH($A41,INDIRECT("'"&B$4&"'!$A:$A"),0),MATCH($A$2,INDIRECT("'"&B$4&"'!$5:$5"),0)) -> 322.74 | C41: =IFERROR(B41/B16, "NA") -> 0.016108978 | D41: =INDEX(INDIRECT("'"&D$4&"'!$1:$1048576"),MATCH($A41,INDIRECT("'"&D$4&"'!$A:$A"),0),MATCH($A$2,INDIRECT("'"&D$4&"'!$5:$5"),0)) -> 453.34 | E41: =IFERROR(D41/D16, "NA") -> 0.011419313 | F41: =INDEX(INDIRECT("'"&F$4&"'!$1:$1048576"),MATCH($A41,INDIRECT("'"&F$4&"'!$A:$A"),0),MATCH($A$2,INDIRECT("'"&F$4&"'!$5:$5"),0)) -> 70.85 | G41: =IFERROR(F41/F16, "NA") -> 0.0043279254 | H41: =INDEX(INDIRECT("'"&H$4&"'!$1:$1048576"),MATCH($A41,INDIRECT("'"&H$4&"'!$A:$A"),0),MATCH($A$2,INDIRECT("'"&H$4&"'!$5:$5"),0)) -> 393.88 | I41: =IFERROR(H41/H16, "NA") -> 0.022667083 | J41: =INDEX(INDIRECT("'"&J$4&"'!$1:$1048576"),MATCH($A41,INDIRECT("'"&J$4&"'!$A:$A"),0),MATCH($A$2,INDIRECT("'"&J$4&"'!$5:$5"),0)) -> 323.43 | K41: =IFERROR(J41/J16, "NA") -> 0.014399331 | L41: =+J41+H41+F41+D41+B41 -> 1564.24 | M41: =IFERROR(L41/L16, "NA") -> 0.013491477
...

Sheet Consolidated
A1: Prime Margin - Trailing 12 Week
A2: 01/25/2026
A3: Consolidated
B5: Week Ending 11/09/2025 | D5: Week Ending 11/16/2025 | F5: Week Ending 11/23/2025 | H5: Week Ending 11/30/2025 | J5: Week Ending 12/07/2025 | L5: Week Ending 12/14/2025 | N5: Week Ending 12/21/2025 | P5: Week Ending 12/28/2025 | R5: Week Ending 01/04/2026 | T5: Week Ending 01/11/2026 | V5: Week Ending 01/18/2026 | X5: Week Ending 01/25/2026 | Z5: Period to Date | AB5: Trailing 4 Week | AD5: $ vs. 4 Week | AF5: % vs. 4 Week | AG5: Trailing 8 Week | AI5: $ vs. 8 Week | AK5: % vs. 8 Week
A6: Sales
A7: Sales | B7: 203694.32 | C7: =IFERROR(B7/B148, "NA") -> 1 | D7: 185604.19 | E7: =IFERROR(D7/D148, "NA") -> 1 | F7: 141258.89 | G7: =IFERROR(F7/F148, "NA") -> 1 | H7: 74664.32 | I7: =IFERROR(H7/H148, "NA") -> 1 | J7: 142398.2 | K7: =IFERROR(J7/J148, "NA") -> 1 | L7: 135140.37 | M7: =IFERROR(L7/L148, "NA") -> 1 | N7: 121597.41 | O7: =IFERROR(N7/N148, "NA") -> 1 | P7: 56612.63 | Q7: =IFERROR(P7/P148, "NA") -> 1 | R7: 69486.64 | S7: =IFERROR(R7/R148, "NA") -> 1 | T7: 110506.18 | U7: =IFERROR(T7/T148, "NA") -> 1 | V7: 135051.74 | W7: =IFERROR(V7/V148, "NA") -> 1 | X7: 115942.83 | Y7: =IFERROR(X7/X148, "NA") -> 1 | Z7: 430987.39 | AA7: =IFERROR(Z7/Z148, "NA") -> 1 | AB7: =IFERROR((R7+T7+V7+X7)/4, "NA") -> 107746.85 | AC7: =IFERROR(AB7/AB148, "NA") -> 1 | AD7: =IFERROR(X7-AB7, "NA") -> 8195.9825 | AE7: =IFERROR(AD7/AD148, "NA") -> 1 | AF7: =IFERROR((X7-AB7)/AB7, "NA") -> 0.076067028 | AG7: =IFERROR((J7+L7+N7+P7+R7+T7+V7+X7)/8, "NA") -> 110842 | AH7: =IFERROR(AG7/AG148, "NA") -> 1 | AI7: =IFERROR(X7-AG7, "NA") -> 5100.83 | AJ7: =IFERROR(AI7/AI148, "NA") -> 1 | AK7: =IFERROR((X7-AG7)/AG7, "NA") -> 0.046018928 | AL7: =IFERROR(AK7/AK148, "NA") -> 1
A8: 49600 - Toast Order Processing Fee Pass-Through | B8: 0 | C8: =IFERROR(B8/B148, "NA") -> 0 | D8: 0 | E8: =IFERROR(D8/D148, "NA") -> 0 | F8: 0 | G8: =IFERROR(F8/F148, "NA") -> 0 | H8: 0 | I8: =IFERROR(H8/H148, "NA") -> 0 | J8: 0 | K8: =IFERROR(J8/J148, "NA") -> 0 | L8: 0 | M8: =IFERROR(L8/L148, "NA") -> 0 | N8: 0 | O8: =IFERROR(N8/N148, "NA") -> 0 | P8: 0 | Q8: =IFERROR(P8/P148, "NA") -> 0 | R8: 0 | S8: =IFERROR(R8/R148, "NA") -> 0 | T8: 0 | U8: =IFERROR(T8/T148, "NA") -> 0 | V8: 0 | W8: =IFERROR(V8/V148, "NA") -> 0 | X8: 0 | Y8: =IFERROR(X8/X148, "NA") -> 0 | Z8: 0 | AA8: =IFERROR(Z8/Z148, "NA") -> 0 | AB8: =IFERROR((R8+T8+V8+X8)/4, "NA") -> 0 | AC8: =IFERROR(AB8/AB148, "NA") -> 0 | AD8: =IFERROR(X8-AB8, "NA") -> 0 | AE8: =IFERROR(AD8/AD148, "NA") -> 0 | AF8: =IFERROR((X8-AB8)/AB8, "NA") -> NA | AG8: =IFERROR((J8+L8+N8+P8+R8+T8+V8+X8)/8, "NA") -> 0 | AH8: =IFERROR(AG8/AG148, "NA") -> 0 | AI8: =IFERROR(X8-AG8, "NA") -> 0 | AJ8: =IFERROR(AI8/AI148, "NA") -> 0 | AK8: =IFERROR((X8-AG8)/AG8, "NA") -> NA | AL8: =IFERROR(AK8/AK148, "NA") -> NA
A9: Total Sales | B9: =IFERROR(B7+B8, "NA") -> 203694.32 | C9: =IFERROR(B9/B148, "NA") -> 1 | D9: =IFERROR(D7+D8, "NA") -> 185604.19 | E9: =IFERROR(D9/D148, "NA") -> 1 | F9: =IFERROR(F7+F8, "NA") -> 141258.89 | G9: =IFERROR(F9/F148, "NA") -> 1 | H9: =IFERROR(H7+H8, "NA") -> 74664.32 | I9: =IFERROR(H9/H148, "NA") -> 1 | J9: =IFERROR(J7+J8, "NA") -> 142398.2 | K9: =IFERROR(J9/J148, "NA") -> 1 | L9: =IFERROR(L7+L8, "NA") -> 135140.37 | M9: =IFERROR(L9/L148, "NA") -> 1 | N9: =IFERROR(N7+N8, "NA") -> 121597.41 | O9: =IFERROR(N9/N148, "NA") -> 1 | P9: =IFERROR(P7+P8, "NA") -> 56612.63 | Q9: =IFERROR(P9/P148, "NA") -> 1 | R9: =IFERROR(R7+R8, "NA") -> 69486.64 | S9: =IFERROR(R9/R148, "NA") -> 1 | T9: =IFERROR(T7+T8, "NA") -> 110506.18 | U9: =IFERROR(T9/T148, "NA") -> 1 | V9: =IFERROR(V7+V8, "NA") -> 135051.74 | W9: =IFERROR(V9/V148, "NA") -> 1 | X9: =IFERROR(X7+X8, "NA") -> 115942.83 | Y9: =IFERROR(X9/X148, "NA") -> 1 | Z9: =IFERROR(Z7+Z8, "NA") -> 430987.39 | AA9: =IFERROR(Z9/Z148, "NA") -> 1 | AB9: =IFERROR((R9+T9+V9+X9)/4, "NA") -> 107746.85 | AC9: =IFERROR(AB9/AB148, "NA") -> 1 | AD9: =IFERROR(X9-AB9, "NA") -> 8195.9825 | AE9: =IFERROR(AD9/AD148, "NA") -> 1 | AF9: =IFERROR((X9-AB9)/AB9, "NA") -> 0.076067028 | AG9: =IFERROR((J9+L9+N9+P9+R9+T9+V9+X9)/8, "NA") -> 110842 | AH9: =IFERROR(AG9/AG148, "NA") -> 1 | AI9: =IFERROR(X9-AG9, "NA") -> 5100.83 | AJ9: =IFERROR(AI9/AI148, "NA") -> 1 | AK9: =IFERROR((X9-AG9)/AG9, "NA") -> 0.046018928 | AL9: =IFERROR(AK9/AK148, "NA") -> 1
A11: Cost of Goods Sold
A12: Food & Beverage Costs
